2019-05-18 15:40:03,122 - util.py[DEBUG]: Cloud-init v. 18.3-9-g2e62cb8a-0ubuntu1~16.04.2 running 'init-local' at Sat, 18 May 2019 15:40:03 +0000. Up 6.39 seconds.
2019-05-18 15:40:03,122 - main.py[DEBUG]: No kernel command line url found.
2019-05-18 15:40:03,122 - main.py[DEBUG]: Closing stdin.
2019-05-18 15:40:03,125 - util.py[DEBUG]: Writing to /var/log/cloud-init.log - ab: [644] 0 bytes
2019-05-18 15:40:03,125 - util.py[DEBUG]: Changing the ownership of /var/log/cloud-init.log to 104:4
2019-05-18 15:40:03,126 - util.py[DEBUG]: Attempting to remove /var/lib/cloud/instance/boot-finished
2019-05-18 15:40:03,126 - util.py[DEBUG]: Attempting to remove /var/lib/cloud/data/no-net
2019-05-18 15:40:03,126 - handlers.py[DEBUG]: start: init-local/check-cache: attempting to read from cache [check]
2019-05-18 15:40:03,126 - util.py[DEBUG]: Reading from /var/lib/cloud/instance/obj.pkl (quiet=False)
2019-05-18 15:40:03,126 - stages.py[DEBUG]: no cache found
2019-05-18 15:40:03,126 - handlers.py[DEBUG]: finish: init-local/check-cache: SUCCESS: no cache found
2019-05-18 15:40:03,126 - util.py[DEBUG]: Attempting to remove /var/lib/cloud/instance
2019-05-18 15:40:03,129 - stages.py[DEBUG]: Using distro class <class 'cloudinit.distros.ubuntu.Distro'>
2019-05-18 15:40:03,129 - __init__.py[DEBUG]: Looking for data source in: ['NoCloud', 'ConfigDrive', 'OpenNebula', 'DigitalOcean', 'Azure', 'AltCloud', 'OVF', 'MAAS', 'GCE', 'OpenStack', 'CloudSigma', 'SmartOS', 'Bigstep', 'Scaleway', 'AliYun', 'Ec2', 'CloudStack', 'None'], via packages ['', 'cloudinit.sources'] that matches dependencies ['FILESYSTEM']
2019-05-18 15:40:03,155 - util.py[DEBUG]: Reading from /etc/os-release (quiet=False)
2019-05-18 15:40:03,155 - util.py[DEBUG]: Read 298 bytes from /etc/os-release
2019-05-18 15:40:03,189 - __init__.py[DEBUG]: Searching for local data source in: ['DataSourceNoCloud', 'DataSourceConfigDrive', 'DataSourceOpenNebula', 'DataSourceDigitalOcean', 'DataSourceAzure', 'DataSourceOVF', 'DataSourceOpenStackLocal', 'DataSourceCloudSigma', 'DataSourceSmartOS', 'DataSourceEc2Local']
2019-05-18 15:40:03,189 - handlers.py[DEBUG]: start: init-local/search-NoCloud: searching for local data from DataSourceNoCloud
2019-05-18 15:40:03,189 - __init__.py[DEBUG]: Seeing if we can get any data from <class 'cloudinit.sources.DataSourceNoCloud.DataSourceNoCloud'>
2019-05-18 15:40:03,189 - __init__.py[DEBUG]: Update datasource metadata and network config due to events: New instance first boot
2019-05-18 15:40:03,189 - util.py[DEBUG]: Running command ['systemd-detect-virt', '--quiet', '--container'] with allowed return codes [0] (shell=False, capture=True)
2019-05-18 15:40:03,191 - util.py[DEBUG]: Running command ['running-in-container'] with allowed return codes [0] (shell=False, capture=True)
2019-05-18 15:40:03,192 - util.py[DEBUG]: Running command ['lxc-is-container'] with allowed return codes [0] (shell=False, capture=True)
2019-05-18 15:40:03,193 - util.py[DEBUG]: Reading from /proc/1/environ (quiet=False)
2019-05-18 15:40:03,194 - util.py[DEBUG]: Read 150 bytes from /proc/1/environ
2019-05-18 15:40:03,194 - util.py[DEBUG]: Reading from /proc/self/status (quiet=False)
2019-05-18 15:40:03,194 - util.py[DEBUG]: Read 966 bytes from /proc/self/status
2019-05-18 15:40:03,194 - util.py[DEBUG]: querying dmi data /sys/class/dmi/id/product_serial
2019-05-18 15:40:03,194 - util.py[DEBUG]: Reading from /sys/class/dmi/id/product_serial (quiet=False)
2019-05-18 15:40:03,194 - util.py[DEBUG]: Read 37 bytes from /sys/class/dmi/id/product_serial
2019-05-18 15:40:03,194 - util.py[DEBUG]: dmi data /sys/class/dmi/id/product_serial returned ec2f6825-b517-d5ec-4cc5-718ff4d628c0
2019-05-18 15:40:03,194 - util.py[DEBUG]: Reading from /var/lib/cloud/seed/nocloud/user-data (quiet=False)
2019-05-18 15:40:03,194 - util.py[DEBUG]: Reading from /var/lib/cloud/seed/nocloud/meta-data (quiet=False)
2019-05-18 15:40:03,194 - util.py[DEBUG]: Reading from /var/lib/cloud/seed/nocloud/vendor-data (quiet=False)
2019-05-18 15:40:03,194 - util.py[DEBUG]: Reading from /var/lib/cloud/seed/nocloud/network-config (quiet=False)
2019-05-18 15:40:03,194 - util.py[DEBUG]: Reading from /var/lib/cloud/seed/nocloud-net/user-data (quiet=False)
2019-05-18 15:40:03,194 - util.py[DEBUG]: Reading from /var/lib/cloud/seed/nocloud-net/meta-data (quiet=False)
2019-05-18 15:40:03,194 - util.py[DEBUG]: Reading from /var/lib/cloud/seed/nocloud-net/vendor-data (quiet=False)
2019-05-18 15:40:03,195 - util.py[DEBUG]: Reading from /var/lib/cloud/seed/nocloud-net/network-config (quiet=False)
2019-05-18 15:40:03,195 - util.py[DEBUG]: Running command ['blkid', '-odevice', '/dev/sr0'] with allowed return codes [0, 2] (shell=False, capture=True)
2019-05-18 15:40:03,196 - util.py[DEBUG]: Running command ['blkid', '-odevice', '/dev/sr1'] with allowed return codes [0, 2] (shell=False, capture=True)
2019-05-18 15:40:03,198 - util.py[DEBUG]: Running command ['blkid', '-tTYPE=vfat', '-odevice'] with allowed return codes [0, 2] (shell=False, capture=True)
2019-05-18 15:40:03,211 - util.py[DEBUG]: Running command ['blkid', '-tTYPE=iso9660', '-odevice'] with allowed return codes [0, 2] (shell=False, capture=True)
2019-05-18 15:40:03,223 - util.py[DEBUG]: Running command ['blkid', '-tLABEL=cidata', '-odevice'] with allowed return codes [0, 2] (shell=False, capture=True)
2019-05-18 15:40:03,235 - handlers.py[DEBUG]: finish: init-local/search-NoCloud: SUCCESS: no local data found from DataSourceNoCloud
2019-05-18 15:40:03,235 - handlers.py[DEBUG]: start: init-local/search-ConfigDrive: searching for local data from DataSourceConfigDrive
2019-05-18 15:40:03,235 - __init__.py[DEBUG]: Seeing if we can get any data from <class 'cloudinit.sources.DataSourceConfigDrive.DataSourceConfigDrive'>
2019-05-18 15:40:03,235 - __init__.py[DEBUG]: Update datasource metadata and network config due to events: New instance first boot
2019-05-18 15:40:03,235 - util.py[DEBUG]: Running command ['blkid', '-odevice', '/dev/sr0'] with allowed return codes [0, 2] (shell=False, capture=True)
2019-05-18 15:40:03,236 - util.py[DEBUG]: Running command ['blkid', '-odevice', '/dev/sr1'] with allowed return codes [0, 2] (shell=False, capture=True)
2019-05-18 15:40:03,238 - util.py[DEBUG]: Running command ['blkid', '-odevice', '/dev/cd0'] with allowed return codes [0, 2] (shell=False, capture=True)
2019-05-18 15:40:03,239 - util.py[DEBUG]: Running command ['blkid', '-odevice', '/dev/cd1'] with allowed return codes [0, 2] (shell=False, capture=True)
2019-05-18 15:40:03,241 - util.py[DEBUG]: Running command ['blkid', '-tTYPE=vfat', '-odevice'] with allowed return codes [0, 2] (shell=False, capture=True)
2019-05-18 15:40:03,253 - util.py[DEBUG]: Running command ['blkid', '-tTYPE=iso9660', '-odevice'] with allowed return codes [0, 2] (shell=False, capture=True)
2019-05-18 15:40:03,264 - util.py[DEBUG]: Running command ['blkid', '-tLABEL=config-2', '-odevice'] with allowed return codes [0, 2] (shell=False, capture=True)
2019-05-18 15:40:03,276 - util.py[DEBUG]: Running command ['blkid', '-tLABEL=CONFIG-2', '-odevice'] with allowed return codes [0, 2] (shell=False, capture=True)
2019-05-18 15:40:03,287 - DataSourceConfigDrive.py[DEBUG]: devices=[] dslist=['NoCloud', 'ConfigDrive', 'OpenNebula', 'DigitalOcean', 'Azure', 'AltCloud', 'OVF', 'MAAS', 'GCE', 'OpenStack', 'CloudSigma', 'SmartOS', 'Bigstep', 'Scaleway', 'AliYun', 'Ec2', 'CloudStack', 'None']
2019-05-18 15:40:03,288 - handlers.py[DEBUG]: finish: init-local/search-ConfigDrive: SUCCESS: no local data found from DataSourceConfigDrive
2019-05-18 15:40:03,288 - handlers.py[DEBUG]: start: init-local/search-OpenNebula: searching for local data from DataSourceOpenNebula
2019-05-18 15:40:03,288 - __init__.py[DEBUG]: Seeing if we can get any data from <class 'cloudinit.sources.DataSourceOpenNebula.DataSourceOpenNebula'>
2019-05-18 15:40:03,288 - __init__.py[DEBUG]: Update datasource metadata and network config due to events: New instance first boot
2019-05-18 15:40:03,288 - util.py[DEBUG]: Running command ['blkid', '-tLABEL=CONTEXT', '-odevice'] with allowed return codes [0, 2] (shell=False, capture=True)
2019-05-18 15:40:03,300 - util.py[DEBUG]: Running command ['blkid', '-tLABEL=CDROM', '-odevice'] with allowed return codes [0, 2] (shell=False, capture=True)
2019-05-18 15:40:03,312 - util.py[DEBUG]: Running command ['blkid', '-tTYPE=iso9660', '-odevice'] with allowed return codes [0, 2] (shell=False, capture=True)
2019-05-18 15:40:03,324 - handlers.py[DEBUG]: finish: init-local/search-OpenNebula: SUCCESS: no local data found from DataSourceOpenNebula
2019-05-18 15:40:03,324 - handlers.py[DEBUG]: start: init-local/search-DigitalOcean: searching for local data from DataSourceDigitalOcean
2019-05-18 15:40:03,324 - __init__.py[DEBUG]: Seeing if we can get any data from <class 'cloudinit.sources.DataSourceDigitalOcean.DataSourceDigitalOcean'>
2019-05-18 15:40:03,324 - __init__.py[DEBUG]: Update datasource metadata and network config due to events: New instance first boot
2019-05-18 15:40:03,325 - util.py[DEBUG]: Running command ['systemd-detect-virt', '--quiet', '--container'] with allowed return codes [0] (shell=False, capture=True)
2019-05-18 15:40:03,326 - util.py[DEBUG]: Running command ['running-in-container'] with allowed return codes [0] (shell=False, capture=True)
2019-05-18 15:40:03,328 - util.py[DEBUG]: Running command ['lxc-is-container'] with allowed return codes [0] (shell=False, capture=True)
2019-05-18 15:40:03,329 - util.py[DEBUG]: Reading from /proc/1/environ (quiet=False)
2019-05-18 15:40:03,330 - util.py[DEBUG]: Read 150 bytes from /proc/1/environ
2019-05-18 15:40:03,330 - util.py[DEBUG]: Reading from /proc/self/status (quiet=False)
2019-05-18 15:40:03,330 - util.py[DEBUG]: Read 966 bytes from /proc/self/status
2019-05-18 15:40:03,330 - util.py[DEBUG]: querying dmi data /sys/class/dmi/id/sys_vendor
2019-05-18 15:40:03,330 - util.py[DEBUG]: Reading from /sys/class/dmi/id/sys_vendor (quiet=False)
2019-05-18 15:40:03,330 - util.py[DEBUG]: Read 4 bytes from /sys/class/dmi/id/sys_vendor
2019-05-18 15:40:03,330 - util.py[DEBUG]: dmi data /sys/class/dmi/id/sys_vendor returned Xen
2019-05-18 15:40:03,330 - handlers.py[DEBUG]: finish: init-local/search-DigitalOcean: SUCCESS: no local data found from DataSourceDigitalOcean
2019-05-18 15:40:03,330 - handlers.py[DEBUG]: start: init-local/search-Azure: searching for local data from DataSourceAzure
2019-05-18 15:40:03,330 - __init__.py[DEBUG]: Seeing if we can get any data from <class 'cloudinit.sources.DataSourceAzure.DataSourceAzure'>
2019-05-18 15:40:03,330 - __init__.py[DEBUG]: Update datasource metadata and network config due to events: New instance first boot
2019-05-18 15:40:03,331 - util.py[DEBUG]: Running command ['systemd-detect-virt', '--quiet', '--container'] with allowed return codes [0] (shell=False, capture=True)
2019-05-18 15:40:03,332 - util.py[DEBUG]: Running command ['running-in-container'] with allowed return codes [0] (shell=False, capture=True)
2019-05-18 15:40:03,334 - util.py[DEBUG]: Running command ['lxc-is-container'] with allowed return codes [0] (shell=False, capture=True)
2019-05-18 15:40:03,335 - util.py[DEBUG]: Reading from /proc/1/environ (quiet=False)
2019-05-18 15:40:03,336 - util.py[DEBUG]: Read 150 bytes from /proc/1/environ
2019-05-18 15:40:03,336 - util.py[DEBUG]: Reading from /proc/self/status (quiet=False)
2019-05-18 15:40:03,336 - util.py[DEBUG]: Read 966 bytes from /proc/self/status
2019-05-18 15:40:03,336 - util.py[DEBUG]: querying dmi data /sys/class/dmi/id/chassis_asset_tag
2019-05-18 15:40:03,336 - util.py[DEBUG]: Reading from /sys/class/dmi/id/chassis_asset_tag (quiet=False)
2019-05-18 15:40:03,336 - util.py[DEBUG]: Read 1 bytes from /sys/class/dmi/id/chassis_asset_tag
2019-05-18 15:40:03,336 - util.py[DEBUG]: dmi data /sys/class/dmi/id/chassis_asset_tag returned 
2019-05-18 15:40:03,336 - DataSourceAzure.py[DEBUG]: Non-Azure DMI asset tag '' discovered.
2019-05-18 15:40:03,336 - handlers.py[DEBUG]: finish: init-local/search-Azure: SUCCESS: no local data found from DataSourceAzure
2019-05-18 15:40:03,336 - handlers.py[DEBUG]: start: init-local/search-OVF: searching for local data from DataSourceOVF
2019-05-18 15:40:03,336 - __init__.py[DEBUG]: Seeing if we can get any data from <class 'cloudinit.sources.DataSourceOVF.DataSourceOVF'>
2019-05-18 15:40:03,336 - __init__.py[DEBUG]: Update datasource metadata and network config due to events: New instance first boot
2019-05-18 15:40:03,337 - util.py[DEBUG]: Running command ['systemd-detect-virt', '--quiet', '--container'] with allowed return codes [0] (shell=False, capture=True)
2019-05-18 15:40:03,338 - util.py[DEBUG]: Running command ['running-in-container'] with allowed return codes [0] (shell=False, capture=True)
2019-05-18 15:40:03,340 - util.py[DEBUG]: Running command ['lxc-is-container'] with allowed return codes [0] (shell=False, capture=True)
2019-05-18 15:40:03,342 - util.py[DEBUG]: Reading from /proc/1/environ (quiet=False)
2019-05-18 15:40:03,342 - util.py[DEBUG]: Read 150 bytes from /proc/1/environ
2019-05-18 15:40:03,342 - util.py[DEBUG]: Reading from /proc/self/status (quiet=False)
2019-05-18 15:40:03,342 - util.py[DEBUG]: Read 966 bytes from /proc/self/status
2019-05-18 15:40:03,342 - util.py[DEBUG]: querying dmi data /sys/class/dmi/id/product_name
2019-05-18 15:40:03,342 - util.py[DEBUG]: Reading from /sys/class/dmi/id/product_name (quiet=False)
2019-05-18 15:40:03,342 - util.py[DEBUG]: Read 9 bytes from /sys/class/dmi/id/product_name
2019-05-18 15:40:03,342 - util.py[DEBUG]: dmi data /sys/class/dmi/id/product_name returned HVM domU
2019-05-18 15:40:03,342 - util.py[DEBUG]: Reading from /proc/mounts (quiet=False)
2019-05-18 15:40:03,342 - util.py[DEBUG]: Read 1991 bytes from /proc/mounts
2019-05-18 15:40:03,342 - util.py[DEBUG]: Fetched {'cgroup': {'mountpoint': '/sys/fs/cgroup/cpuset', 'fstype': 'cgroup', 'opts': 'rw,nosuid,nodev,noexec,relatime,cpuset'}, 'udev': {'mountpoint': '/dev', 'fstype': 'devtmpfs', 'opts': 'rw,nosuid,relatime,size=30907648k,nr_inodes=7726912,mode=755'}, '/dev/xvda1': {'mountpoint': '/', 'fstype': 'ext4', 'opts': 'rw,relatime,discard,data=ordered'}, 'devpts': {'mountpoint': '/dev/pts', 'fstype': 'devpts', 'opts': 'rw,nosuid,noexec,relatime,gid=5,mode=620,ptmxmode=000'}, 'hugetlbfs': {'mountpoint': '/dev/hugepages', 'fstype': 'hugetlbfs', 'opts': 'rw,relatime'}, 'securityfs': {'mountpoint': '/sys/kernel/security', 'fstype': 'securityfs', 'opts': 'rw,nosuid,nodev,noexec,relatime'}, 'debugfs': {'mountpoint': '/sys/kernel/debug', 'fstype': 'debugfs', 'opts': 'rw,relatime'}, 'pstore': {'mountpoint': '/sys/fs/pstore', 'fstype': 'pstore', 'opts': 'rw,nosuid,nodev,noexec,relatime'}, 'sysfs': {'mountpoint': '/sys', 'fstype': 'sysfs', 'opts': 'rw,nosuid,nodev,noexec,relatime'}, 'tmpfs': {'mountpoint': '/sys/fs/cgroup', 'fstype': 'tmpfs', 'opts': 'ro,nosuid,nodev,noexec,mode=755'}, 'mqueue': {'mountpoint': '/dev/mqueue', 'fstype': 'mqueue', 'opts': 'rw,relatime'}, 'systemd-1': {'mountpoint': '/proc/sys/fs/binfmt_misc', 'fstype': 'autofs', 'opts': 'rw,relatime,fd=28,pgrp=1,timeout=0,minproto=5,maxproto=5,direct'}, 'fusectl': {'mountpoint': '/sys/fs/fuse/connections', 'fstype': 'fusectl', 'opts': 'rw,relatime'}, 'proc': {'mountpoint': '/proc', 'fstype': 'proc', 'opts': 'rw,nosuid,nodev,noexec,relatime'}} mounts from proc
2019-05-18 15:40:03,343 - util.py[DEBUG]: Running command ['blkid', '-tTYPE=iso9660', '-odevice'] with allowed return codes [0, 2] (shell=False, capture=True)
2019-05-18 15:40:03,355 - handlers.py[DEBUG]: finish: init-local/search-OVF: SUCCESS: no local data found from DataSourceOVF
2019-05-18 15:40:03,355 - handlers.py[DEBUG]: start: init-local/search-OpenStackLocal: searching for local data from DataSourceOpenStackLocal
2019-05-18 15:40:03,355 - __init__.py[DEBUG]: Seeing if we can get any data from <class 'cloudinit.sources.DataSourceOpenStack.DataSourceOpenStackLocal'>
2019-05-18 15:40:03,355 - __init__.py[DEBUG]: Update datasource metadata and network config due to events: New instance first boot
2019-05-18 15:40:03,355 - util.py[DEBUG]: Running command ['systemd-detect-virt', '--quiet', '--container'] with allowed return codes [0] (shell=False, capture=True)
2019-05-18 15:40:03,357 - util.py[DEBUG]: Running command ['running-in-container'] with allowed return codes [0] (shell=False, capture=True)
2019-05-18 15:40:03,358 - util.py[DEBUG]: Running command ['lxc-is-container'] with allowed return codes [0] (shell=False, capture=True)
2019-05-18 15:40:03,360 - util.py[DEBUG]: Reading from /proc/1/environ (quiet=False)
2019-05-18 15:40:03,360 - util.py[DEBUG]: Read 150 bytes from /proc/1/environ
2019-05-18 15:40:03,361 - util.py[DEBUG]: Reading from /proc/self/status (quiet=False)
2019-05-18 15:40:03,361 - util.py[DEBUG]: Read 966 bytes from /proc/self/status
2019-05-18 15:40:03,361 - util.py[DEBUG]: querying dmi data /sys/class/dmi/id/product_name
2019-05-18 15:40:03,361 - util.py[DEBUG]: Reading from /sys/class/dmi/id/product_name (quiet=False)
2019-05-18 15:40:03,361 - util.py[DEBUG]: Read 9 bytes from /sys/class/dmi/id/product_name
2019-05-18 15:40:03,361 - util.py[DEBUG]: dmi data /sys/class/dmi/id/product_name returned HVM domU
2019-05-18 15:40:03,361 - util.py[DEBUG]: Running command ['systemd-detect-virt', '--quiet', '--container'] with allowed return codes [0] (shell=False, capture=True)
2019-05-18 15:40:03,363 - util.py[DEBUG]: Running command ['running-in-container'] with allowed return codes [0] (shell=False, capture=True)
2019-05-18 15:40:03,364 - util.py[DEBUG]: Running command ['lxc-is-container'] with allowed return codes [0] (shell=False, capture=True)
2019-05-18 15:40:03,366 - util.py[DEBUG]: Reading from /proc/1/environ (quiet=False)
2019-05-18 15:40:03,366 - util.py[DEBUG]: Read 150 bytes from /proc/1/environ
2019-05-18 15:40:03,366 - util.py[DEBUG]: Reading from /proc/self/status (quiet=False)
2019-05-18 15:40:03,366 - util.py[DEBUG]: Read 966 bytes from /proc/self/status
2019-05-18 15:40:03,366 - util.py[DEBUG]: querying dmi data /sys/class/dmi/id/chassis_asset_tag
2019-05-18 15:40:03,366 - util.py[DEBUG]: Reading from /sys/class/dmi/id/chassis_asset_tag (quiet=False)
2019-05-18 15:40:03,367 - util.py[DEBUG]: Read 1 bytes from /sys/class/dmi/id/chassis_asset_tag
2019-05-18 15:40:03,367 - util.py[DEBUG]: dmi data /sys/class/dmi/id/chassis_asset_tag returned 
2019-05-18 15:40:03,367 - util.py[DEBUG]: Reading from /proc/1/environ (quiet=False)
2019-05-18 15:40:03,367 - util.py[DEBUG]: Read 150 bytes from /proc/1/environ
2019-05-18 15:40:03,367 - handlers.py[DEBUG]: finish: init-local/search-OpenStackLocal: SUCCESS: no local data found from DataSourceOpenStackLocal
2019-05-18 15:40:03,367 - handlers.py[DEBUG]: start: init-local/search-CloudSigma: searching for local data from DataSourceCloudSigma
2019-05-18 15:40:03,367 - __init__.py[DEBUG]: Seeing if we can get any data from <class 'cloudinit.sources.DataSourceCloudSigma.DataSourceCloudSigma'>
2019-05-18 15:40:03,367 - __init__.py[DEBUG]: Update datasource metadata and network config due to events: New instance first boot
2019-05-18 15:40:03,367 - DataSourceCloudSigma.py[DEBUG]: determining hypervisor product name via dmi data
2019-05-18 15:40:03,367 - util.py[DEBUG]: Running command ['systemd-detect-virt', '--quiet', '--container'] with allowed return codes [0] (shell=False, capture=True)
2019-05-18 15:40:03,369 - util.py[DEBUG]: Running command ['running-in-container'] with allowed return codes [0] (shell=False, capture=True)
2019-05-18 15:40:03,370 - util.py[DEBUG]: Running command ['lxc-is-container'] with allowed return codes [0] (shell=False, capture=True)
2019-05-18 15:40:03,372 - util.py[DEBUG]: Reading from /proc/1/environ (quiet=False)
2019-05-18 15:40:03,372 - util.py[DEBUG]: Read 150 bytes from /proc/1/environ
2019-05-18 15:40:03,372 - util.py[DEBUG]: Reading from /proc/self/status (quiet=False)
2019-05-18 15:40:03,372 - util.py[DEBUG]: Read 966 bytes from /proc/self/status
2019-05-18 15:40:03,372 - util.py[DEBUG]: querying dmi data /sys/class/dmi/id/product_name
2019-05-18 15:40:03,372 - util.py[DEBUG]: Reading from /sys/class/dmi/id/product_name (quiet=False)
2019-05-18 15:40:03,373 - util.py[DEBUG]: Read 9 bytes from /sys/class/dmi/id/product_name
2019-05-18 15:40:03,373 - util.py[DEBUG]: dmi data /sys/class/dmi/id/product_name returned HVM domU
2019-05-18 15:40:03,373 - DataSourceCloudSigma.py[DEBUG]: detected hypervisor as HVM domU
2019-05-18 15:40:03,373 - handlers.py[DEBUG]: finish: init-local/search-CloudSigma: SUCCESS: no local data found from DataSourceCloudSigma
2019-05-18 15:40:03,373 - handlers.py[DEBUG]: start: init-local/search-SmartOS: searching for local data from DataSourceSmartOS
2019-05-18 15:40:03,373 - __init__.py[DEBUG]: Seeing if we can get any data from <class 'cloudinit.sources.DataSourceSmartOS.DataSourceSmartOS'>
2019-05-18 15:40:03,373 - util.py[DEBUG]: Running command ['systemd-detect-virt', '--quiet', '--container'] with allowed return codes [0] (shell=False, capture=True)
2019-05-18 15:40:03,375 - util.py[DEBUG]: Running command ['running-in-container'] with allowed return codes [0] (shell=False, capture=True)
2019-05-18 15:40:03,376 - util.py[DEBUG]: Running command ['lxc-is-container'] with allowed return codes [0] (shell=False, capture=True)
2019-05-18 15:40:03,378 - util.py[DEBUG]: Reading from /proc/1/environ (quiet=False)
2019-05-18 15:40:03,378 - util.py[DEBUG]: Read 150 bytes from /proc/1/environ
2019-05-18 15:40:03,378 - util.py[DEBUG]: Reading from /proc/self/status (quiet=False)
2019-05-18 15:40:03,379 - util.py[DEBUG]: Read 966 bytes from /proc/self/status
2019-05-18 15:40:03,379 - util.py[DEBUG]: querying dmi data /sys/class/dmi/id/product_name
2019-05-18 15:40:03,379 - util.py[DEBUG]: Reading from /sys/class/dmi/id/product_name (quiet=False)
2019-05-18 15:40:03,379 - util.py[DEBUG]: Read 9 bytes from /sys/class/dmi/id/product_name
2019-05-18 15:40:03,379 - util.py[DEBUG]: dmi data /sys/class/dmi/id/product_name returned HVM domU
2019-05-18 15:40:03,379 - __init__.py[DEBUG]: Update datasource metadata and network config due to events: New instance first boot
2019-05-18 15:40:03,379 - DataSourceSmartOS.py[DEBUG]: Not running on smartos
2019-05-18 15:40:03,379 - handlers.py[DEBUG]: finish: init-local/search-SmartOS: SUCCESS: no local data found from DataSourceSmartOS
2019-05-18 15:40:03,379 - handlers.py[DEBUG]: start: init-local/search-Ec2Local: searching for local data from DataSourceEc2Local
2019-05-18 15:40:03,379 - __init__.py[DEBUG]: Seeing if we can get any data from <class 'cloudinit.sources.DataSourceEc2.DataSourceEc2Local'>
2019-05-18 15:40:03,379 - __init__.py[DEBUG]: Update datasource metadata and network config due to events: New instance first boot
2019-05-18 15:40:03,379 - util.py[DEBUG]: Reading from /sys/hypervisor/uuid (quiet=False)
2019-05-18 15:40:03,379 - util.py[DEBUG]: Read 37 bytes from /sys/hypervisor/uuid
2019-05-18 15:40:03,380 - util.py[DEBUG]: Running command ['systemd-detect-virt', '--quiet', '--container'] with allowed return codes [0] (shell=False, capture=True)
2019-05-18 15:40:03,381 - util.py[DEBUG]: Running command ['running-in-container'] with allowed return codes [0] (shell=False, capture=True)
2019-05-18 15:40:03,383 - util.py[DEBUG]: Running command ['lxc-is-container'] with allowed return codes [0] (shell=False, capture=True)
2019-05-18 15:40:03,384 - util.py[DEBUG]: Reading from /proc/1/environ (quiet=False)
2019-05-18 15:40:03,384 - util.py[DEBUG]: Read 150 bytes from /proc/1/environ
2019-05-18 15:40:03,385 - util.py[DEBUG]: Reading from /proc/self/status (quiet=False)
2019-05-18 15:40:03,385 - util.py[DEBUG]: Read 966 bytes from /proc/self/status
2019-05-18 15:40:03,385 - util.py[DEBUG]: querying dmi data /sys/class/dmi/id/product_serial
2019-05-18 15:40:03,385 - util.py[DEBUG]: Reading from /sys/class/dmi/id/product_serial (quiet=False)
2019-05-18 15:40:03,385 - util.py[DEBUG]: Read 37 bytes from /sys/class/dmi/id/product_serial
2019-05-18 15:40:03,385 - util.py[DEBUG]: dmi data /sys/class/dmi/id/product_serial returned ec2f6825-b517-d5ec-4cc5-718ff4d628c0
2019-05-18 15:40:03,385 - DataSourceEc2.py[DEBUG]: strict_mode: warn, cloud_platform=AWS
2019-05-18 15:40:03,385 - util.py[DEBUG]: Reading from /etc/os-release (quiet=False)
2019-05-18 15:40:03,385 - util.py[DEBUG]: Read 298 bytes from /etc/os-release
2019-05-18 15:40:03,386 - util.py[DEBUG]: Reading from /sys/class/net/ens3/name_assign_type (quiet=False)
2019-05-18 15:40:03,386 - util.py[DEBUG]: Read 2 bytes from /sys/class/net/ens3/name_assign_type
2019-05-18 15:40:03,386 - util.py[DEBUG]: Reading from /sys/class/net/ens3/carrier (quiet=False)
2019-05-18 15:40:03,386 - util.py[DEBUG]: Reading from /sys/class/net/ens3/dormant (quiet=False)
2019-05-18 15:40:03,386 - util.py[DEBUG]: Reading from /sys/class/net/ens3/operstate (quiet=False)
2019-05-18 15:40:03,386 - util.py[DEBUG]: Read 5 bytes from /sys/class/net/ens3/operstate
2019-05-18 15:40:03,386 - util.py[DEBUG]: Reading from /sys/class/net/ens3/address (quiet=False)
2019-05-18 15:40:03,386 - util.py[DEBUG]: Read 18 bytes from /sys/class/net/ens3/address
2019-05-18 15:40:03,387 - dhcp.py[DEBUG]: Performing a dhcp discovery on ens3
2019-05-18 15:40:03,387 - util.py[DEBUG]: Copying /sbin/dhclient to /var/tmp/cloud-init/cloud-init-dhcp-ggssv2ud/dhclient
2019-05-18 15:40:03,389 - util.py[DEBUG]: Running command ['ip', 'link', 'set', 'dev', 'ens3', 'up'] with allowed return codes [0] (shell=False, capture=True)
2019-05-18 15:40:03,408 - util.py[DEBUG]: Running command ['/var/tmp/cloud-init/cloud-init-dhcp-ggssv2ud/dhclient', '-1', '-v', '-lf', '/var/tmp/cloud-init/cloud-init-dhcp-ggssv2ud/dhcp.leases', '-pf', '/var/tmp/cloud-init/cloud-init-dhcp-ggssv2ud/dhclient.pid', 'ens3', '-sf', '/bin/true'] with allowed return codes [0] (shell=False, capture=True)
2019-05-18 15:40:03,449 - util.py[DEBUG]: All files appeared after 0 seconds: ['/var/tmp/cloud-init/cloud-init-dhcp-ggssv2ud/dhclient.pid', '/var/tmp/cloud-init/cloud-init-dhcp-ggssv2ud/dhcp.leases']
2019-05-18 15:40:03,449 - util.py[DEBUG]: Reading from /var/tmp/cloud-init/cloud-init-dhcp-ggssv2ud/dhclient.pid (quiet=False)
2019-05-18 15:40:03,449 - util.py[DEBUG]: Read 5 bytes from /var/tmp/cloud-init/cloud-init-dhcp-ggssv2ud/dhclient.pid
2019-05-18 15:40:03,449 - util.py[DEBUG]: Reading from /var/tmp/cloud-init/cloud-init-dhcp-ggssv2ud/dhcp.leases (quiet=False)
2019-05-18 15:40:03,449 - util.py[DEBUG]: Read 513 bytes from /var/tmp/cloud-init/cloud-init-dhcp-ggssv2ud/dhcp.leases
2019-05-18 15:40:03,450 - dhcp.py[DEBUG]: Received dhcp lease on ens3 for 10.0.0.175/255.255.255.0
2019-05-18 15:40:03,450 - __init__.py[DEBUG]: Attempting setup of ephemeral network on ens3 with 10.0.0.175/24 brd 10.0.0.255
2019-05-18 15:40:03,450 - util.py[DEBUG]: Running command ['ip', '-family', 'inet', 'addr', 'add', '10.0.0.175/24', 'broadcast', '10.0.0.255', 'dev', 'ens3'] with allowed return codes [0] (shell=False, capture=True)
2019-05-18 15:40:03,452 - util.py[DEBUG]: Running command ['ip', '-family', 'inet', 'link', 'set', 'dev', 'ens3', 'up'] with allowed return codes [0] (shell=False, capture=True)
2019-05-18 15:40:03,455 - util.py[DEBUG]: Running command ['ip', 'route', 'show', '0.0.0.0/0'] with allowed return codes [0] (shell=False, capture=True)
2019-05-18 15:40:03,457 - util.py[DEBUG]: Running command ['ip', '-4', 'route', 'add', 'default', 'via', '10.0.0.1', 'dev', 'ens3'] with allowed return codes [0] (shell=False, capture=True)
2019-05-18 15:40:03,462 - util.py[DEBUG]: Resolving URL: http://169.254.169.254 took 0.003 seconds
2019-05-18 15:40:03,462 - util.py[DEBUG]: Resolving URL: http://instance-data.:8773 took 0.000 seconds
2019-05-18 15:40:03,462 - DataSourceEc2.py[DEBUG]: Removed the following from metadata urls: ['http://instance-data.:8773']
2019-05-18 15:40:03,463 - url_helper.py[DEBUG]: [0/1] open 'http://169.254.169.254/2009-04-04/meta-data/instance-id' with {'timeout': 50.0, 'method': 'GET', 'url': 'http://169.254.169.254/2009-04-04/meta-data/instance-id', 'headers': {'User-Agent': 'Cloud-Init/18.3-9-g2e62cb8a-0ubuntu1~16.04.2'}, 'allow_redirects': True} configuration
2019-05-18 15:40:03,468 - url_helper.py[DEBUG]: Read from http://169.254.169.254/2009-04-04/meta-data/instance-id (200, 19b) after 1 attempts
2019-05-18 15:40:03,468 - DataSourceEc2.py[DEBUG]: Using metadata source: 'http://169.254.169.254'
2019-05-18 15:40:03,468 - url_helper.py[DEBUG]: [0/1] open 'http://169.254.169.254/2016-09-02/meta-data/instance-id' with {'method': 'GET', 'url': 'http://169.254.169.254/2016-09-02/meta-data/instance-id', 'headers': {'User-Agent': 'Cloud-Init/18.3-9-g2e62cb8a-0ubuntu1~16.04.2'}, 'allow_redirects': True} configuration
2019-05-18 15:40:03,469 - url_helper.py[DEBUG]: Read from http://169.254.169.254/2016-09-02/meta-data/instance-id (200, 19b) after 1 attempts
2019-05-18 15:40:03,469 - DataSourceEc2.py[DEBUG]: Found preferred metadata version 2016-09-02
2019-05-18 15:40:03,470 - url_helper.py[DEBUG]: [0/6] open 'http://169.254.169.254/2016-09-02/user-data' with {'timeout': 5.0, 'method': 'GET', 'url': 'http://169.254.169.254/2016-09-02/user-data', 'headers': {'User-Agent': 'Cloud-Init/18.3-9-g2e62cb8a-0ubuntu1~16.04.2'}, 'allow_redirects': True} configuration
2019-05-18 15:40:03,471 - url_helper.py[DEBUG]: [0/6] open 'http://169.254.169.254/2016-09-02/meta-data/' with {'timeout': 5.0, 'method': 'GET', 'url': 'http://169.254.169.254/2016-09-02/meta-data/', 'headers': {'User-Agent': 'Cloud-Init/18.3-9-g2e62cb8a-0ubuntu1~16.04.2'}, 'allow_redirects': True} configuration
2019-05-18 15:40:03,473 - url_helper.py[DEBUG]: Read from http://169.254.169.254/2016-09-02/meta-data/ (200, 268b) after 1 attempts
2019-05-18 15:40:03,473 - url_helper.py[DEBUG]: [0/6] open 'http://169.254.169.254/2016-09-02/meta-data/block-device-mapping/' with {'timeout': 5.0, 'method': 'GET', 'url': 'http://169.254.169.254/2016-09-02/meta-data/block-device-mapping/', 'headers': {'User-Agent': 'Cloud-Init/18.3-9-g2e62cb8a-0ubuntu1~16.04.2'}, 'allow_redirects': True} configuration
2019-05-18 15:40:03,474 - url_helper.py[DEBUG]: Read from http://169.254.169.254/2016-09-02/meta-data/block-device-mapping/ (200, 30b) after 1 attempts
2019-05-18 15:40:03,474 - url_helper.py[DEBUG]: [0/6] open 'http://169.254.169.254/2016-09-02/meta-data/block-device-mapping/ephemeral1' with {'timeout': 5.0, 'method': 'GET', 'url': 'http://169.254.169.254/2016-09-02/meta-data/block-device-mapping/ephemeral1', 'headers': {'User-Agent': 'Cloud-Init/18.3-9-g2e62cb8a-0ubuntu1~16.04.2'}, 'allow_redirects': True} configuration
2019-05-18 15:40:03,476 - url_helper.py[DEBUG]: Read from http://169.254.169.254/2016-09-02/meta-data/block-device-mapping/ephemeral1 (200, 3b) after 1 attempts
2019-05-18 15:40:03,476 - url_helper.py[DEBUG]: [0/6] open 'http://169.254.169.254/2016-09-02/meta-data/block-device-mapping/ephemeral0' with {'timeout': 5.0, 'method': 'GET', 'url': 'http://169.254.169.254/2016-09-02/meta-data/block-device-mapping/ephemeral0', 'headers': {'User-Agent': 'Cloud-Init/18.3-9-g2e62cb8a-0ubuntu1~16.04.2'}, 'allow_redirects': True} configuration
2019-05-18 15:40:03,477 - url_helper.py[DEBUG]: Read from http://169.254.169.254/2016-09-02/meta-data/block-device-mapping/ephemeral0 (200, 3b) after 1 attempts
2019-05-18 15:40:03,478 - url_helper.py[DEBUG]: [0/6] open 'http://169.254.169.254/2016-09-02/meta-data/block-device-mapping/root' with {'timeout': 5.0, 'method': 'GET', 'url': 'http://169.254.169.254/2016-09-02/meta-data/block-device-mapping/root', 'headers': {'User-Agent': 'Cloud-Init/18.3-9-g2e62cb8a-0ubuntu1~16.04.2'}, 'allow_redirects': True} configuration
2019-05-18 15:40:03,479 - url_helper.py[DEBUG]: Read from http://169.254.169.254/2016-09-02/meta-data/block-device-mapping/root (200, 9b) after 1 attempts
2019-05-18 15:40:03,479 - url_helper.py[DEBUG]: [0/6] open 'http://169.254.169.254/2016-09-02/meta-data/block-device-mapping/ami' with {'timeout': 5.0, 'method': 'GET', 'url': 'http://169.254.169.254/2016-09-02/meta-data/block-device-mapping/ami', 'headers': {'User-Agent': 'Cloud-Init/18.3-9-g2e62cb8a-0ubuntu1~16.04.2'}, 'allow_redirects': True} configuration
2019-05-18 15:40:03,481 - url_helper.py[DEBUG]: Read from http://169.254.169.254/2016-09-02/meta-data/block-device-mapping/ami (200, 9b) after 1 attempts
2019-05-18 15:40:03,481 - url_helper.py[DEBUG]: [0/6] open 'http://169.254.169.254/2016-09-02/meta-data/iam/' with {'timeout': 5.0, 'method': 'GET', 'url': 'http://169.254.169.254/2016-09-02/meta-data/iam/', 'headers': {'User-Agent': 'Cloud-Init/18.3-9-g2e62cb8a-0ubuntu1~16.04.2'}, 'allow_redirects': True} configuration
2019-05-18 15:40:03,482 - url_helper.py[DEBUG]: Read from http://169.254.169.254/2016-09-02/meta-data/iam/ (200, 26b) after 1 attempts
2019-05-18 15:40:03,482 - url_helper.py[DEBUG]: [0/6] open 'http://169.254.169.254/2016-09-02/meta-data/iam/info' with {'timeout': 5.0, 'method': 'GET', 'url': 'http://169.254.169.254/2016-09-02/meta-data/iam/info', 'headers': {'User-Agent': 'Cloud-Init/18.3-9-g2e62cb8a-0ubuntu1~16.04.2'}, 'allow_redirects': True} configuration
2019-05-18 15:40:03,484 - url_helper.py[DEBUG]: Read from http://169.254.169.254/2016-09-02/meta-data/iam/info (200, 246b) after 1 attempts
2019-05-18 15:40:03,484 - url_helper.py[DEBUG]: [0/6] open 'http://169.254.169.254/2016-09-02/meta-data/metrics/' with {'timeout': 5.0, 'method': 'GET', 'url': 'http://169.254.169.254/2016-09-02/meta-data/metrics/', 'headers': {'User-Agent': 'Cloud-Init/18.3-9-g2e62cb8a-0ubuntu1~16.04.2'}, 'allow_redirects': True} configuration
2019-05-18 15:40:03,485 - url_helper.py[DEBUG]: Read from http://169.254.169.254/2016-09-02/meta-data/metrics/ (200, 7b) after 1 attempts
2019-05-18 15:40:03,486 - url_helper.py[DEBUG]: [0/6] open 'http://169.254.169.254/2016-09-02/meta-data/metrics/vhostmd' with {'timeout': 5.0, 'method': 'GET', 'url': 'http://169.254.169.254/2016-09-02/meta-data/metrics/vhostmd', 'headers': {'User-Agent': 'Cloud-Init/18.3-9-g2e62cb8a-0ubuntu1~16.04.2'}, 'allow_redirects': True} configuration
2019-05-18 15:40:03,487 - url_helper.py[DEBUG]: Read from http://169.254.169.254/2016-09-02/meta-data/metrics/vhostmd (200, 38b) after 1 attempts
2019-05-18 15:40:03,487 - url_helper.py[DEBUG]: [0/6] open 'http://169.254.169.254/2016-09-02/meta-data/network/' with {'timeout': 5.0, 'method': 'GET', 'url': 'http://169.254.169.254/2016-09-02/meta-data/network/', 'headers': {'User-Agent': 'Cloud-Init/18.3-9-g2e62cb8a-0ubuntu1~16.04.2'}, 'allow_redirects': True} configuration
2019-05-18 15:40:03,489 - url_helper.py[DEBUG]: Read from http://169.254.169.254/2016-09-02/meta-data/network/ (200, 11b) after 1 attempts
2019-05-18 15:40:03,489 - url_helper.py[DEBUG]: [0/6] open 'http://169.254.169.254/2016-09-02/meta-data/network/interfaces/' with {'timeout': 5.0, 'method': 'GET', 'url': 'http://169.254.169.254/2016-09-02/meta-data/network/interfaces/', 'headers': {'User-Agent': 'Cloud-Init/18.3-9-g2e62cb8a-0ubuntu1~16.04.2'}, 'allow_redirects': True} configuration
2019-05-18 15:40:03,490 - url_helper.py[DEBUG]: Read from http://169.254.169.254/2016-09-02/meta-data/network/interfaces/ (200, 5b) after 1 attempts
2019-05-18 15:40:03,490 - url_helper.py[DEBUG]: [0/6] open 'http://169.254.169.254/2016-09-02/meta-data/network/interfaces/macs/' with {'timeout': 5.0, 'method': 'GET', 'url': 'http://169.254.169.254/2016-09-02/meta-data/network/interfaces/macs/', 'headers': {'User-Agent': 'Cloud-Init/18.3-9-g2e62cb8a-0ubuntu1~16.04.2'}, 'allow_redirects': True} configuration
2019-05-18 15:40:03,492 - url_helper.py[DEBUG]: Read from http://169.254.169.254/2016-09-02/meta-data/network/interfaces/macs/ (200, 18b) after 1 attempts
2019-05-18 15:40:03,492 - url_helper.py[DEBUG]: [0/6] open 'http://169.254.169.254/2016-09-02/meta-data/network/interfaces/macs/06:a9:b1:ee:c4:26/' with {'timeout': 5.0, 'method': 'GET', 'url': 'http://169.254.169.254/2016-09-02/meta-data/network/interfaces/macs/06:a9:b1:ee:c4:26/', 'headers': {'User-Agent': 'Cloud-Init/18.3-9-g2e62cb8a-0ubuntu1~16.04.2'}, 'allow_redirects': True} configuration
2019-05-18 15:40:03,494 - url_helper.py[DEBUG]: Read from http://169.254.169.254/2016-09-02/meta-data/network/interfaces/macs/06:a9:b1:ee:c4:26/ (200, 230b) after 1 attempts
2019-05-18 15:40:03,494 - url_helper.py[DEBUG]: [0/6] open 'http://169.254.169.254/2016-09-02/meta-data/network/interfaces/macs/06:a9:b1:ee:c4:26/ipv4-associations/' with {'timeout': 5.0, 'method': 'GET', 'url': 'http://169.254.169.254/2016-09-02/meta-data/network/interfaces/macs/06:a9:b1:ee:c4:26/ipv4-associations/', 'headers': {'User-Agent': 'Cloud-Init/18.3-9-g2e62cb8a-0ubuntu1~16.04.2'}, 'allow_redirects': True} configuration
2019-05-18 15:40:03,495 - url_helper.py[DEBUG]: Read from http://169.254.169.254/2016-09-02/meta-data/network/interfaces/macs/06:a9:b1:ee:c4:26/ipv4-associations/ (200, 11b) after 1 attempts
2019-05-18 15:40:03,495 - url_helper.py[DEBUG]: [0/6] open 'http://169.254.169.254/2016-09-02/meta-data/network/interfaces/macs/06:a9:b1:ee:c4:26/ipv4-associations/63.32.55.22' with {'timeout': 5.0, 'method': 'GET', 'url': 'http://169.254.169.254/2016-09-02/meta-data/network/interfaces/macs/06:a9:b1:ee:c4:26/ipv4-associations/63.32.55.22', 'headers': {'User-Agent': 'Cloud-Init/18.3-9-g2e62cb8a-0ubuntu1~16.04.2'}, 'allow_redirects': True} configuration
2019-05-18 15:40:03,497 - url_helper.py[DEBUG]: Read from http://169.254.169.254/2016-09-02/meta-data/network/interfaces/macs/06:a9:b1:ee:c4:26/ipv4-associations/63.32.55.22 (200, 10b) after 1 attempts
2019-05-18 15:40:03,497 - url_helper.py[DEBUG]: [0/6] open 'http://169.254.169.254/2016-09-02/meta-data/network/interfaces/macs/06:a9:b1:ee:c4:26/security-groups' with {'timeout': 5.0, 'method': 'GET', 'url': 'http://169.254.169.254/2016-09-02/meta-data/network/interfaces/macs/06:a9:b1:ee:c4:26/security-groups', 'headers': {'User-Agent': 'Cloud-Init/18.3-9-g2e62cb8a-0ubuntu1~16.04.2'}, 'allow_redirects': True} configuration
2019-05-18 15:40:03,498 - url_helper.py[DEBUG]: Read from http://169.254.169.254/2016-09-02/meta-data/network/interfaces/macs/06:a9:b1:ee:c4:26/security-groups (200, 81b) after 1 attempts
2019-05-18 15:40:03,499 - url_helper.py[DEBUG]: [0/6] open 'http://169.254.169.254/2016-09-02/meta-data/network/interfaces/macs/06:a9:b1:ee:c4:26/device-number' with {'timeout': 5.0, 'method': 'GET', 'url': 'http://169.254.169.254/2016-09-02/meta-data/network/interfaces/macs/06:a9:b1:ee:c4:26/device-number', 'headers': {'User-Agent': 'Cloud-Init/18.3-9-g2e62cb8a-0ubuntu1~16.04.2'}, 'allow_redirects': True} configuration
2019-05-18 15:40:03,500 - url_helper.py[DEBUG]: Read from http://169.254.169.254/2016-09-02/meta-data/network/interfaces/macs/06:a9:b1:ee:c4:26/device-number (200, 1b) after 1 attempts
2019-05-18 15:40:03,500 - url_helper.py[DEBUG]: [0/6] open 'http://169.254.169.254/2016-09-02/meta-data/network/interfaces/macs/06:a9:b1:ee:c4:26/owner-id' with {'timeout': 5.0, 'method': 'GET', 'url': 'http://169.254.169.254/2016-09-02/meta-data/network/interfaces/macs/06:a9:b1:ee:c4:26/owner-id', 'headers': {'User-Agent': 'Cloud-Init/18.3-9-g2e62cb8a-0ubuntu1~16.04.2'}, 'allow_redirects': True} configuration
2019-05-18 15:40:03,502 - url_helper.py[DEBUG]: Read from http://169.254.169.254/2016-09-02/meta-data/network/interfaces/macs/06:a9:b1:ee:c4:26/owner-id (200, 12b) after 1 attempts
2019-05-18 15:40:03,502 - url_helper.py[DEBUG]: [0/6] open 'http://169.254.169.254/2016-09-02/meta-data/network/interfaces/macs/06:a9:b1:ee:c4:26/vpc-ipv4-cidr-blocks' with {'timeout': 5.0, 'method': 'GET', 'url': 'http://169.254.169.254/2016-09-02/meta-data/network/interfaces/macs/06:a9:b1:ee:c4:26/vpc-ipv4-cidr-blocks', 'headers': {'User-Agent': 'Cloud-Init/18.3-9-g2e62cb8a-0ubuntu1~16.04.2'}, 'allow_redirects': True} configuration
2019-05-18 15:40:03,503 - url_helper.py[DEBUG]: Read from http://169.254.169.254/2016-09-02/meta-data/network/interfaces/macs/06:a9:b1:ee:c4:26/vpc-ipv4-cidr-blocks (200, 11b) after 1 attempts
2019-05-18 15:40:03,503 - url_helper.py[DEBUG]: [0/6] open 'http://169.254.169.254/2016-09-02/meta-data/network/interfaces/macs/06:a9:b1:ee:c4:26/public-hostname' with {'timeout': 5.0, 'method': 'GET', 'url': 'http://169.254.169.254/2016-09-02/meta-data/network/interfaces/macs/06:a9:b1:ee:c4:26/public-hostname', 'headers': {'User-Agent': 'Cloud-Init/18.3-9-g2e62cb8a-0ubuntu1~16.04.2'}, 'allow_redirects': True} configuration
2019-05-18 15:40:03,505 - url_helper.py[DEBUG]: Read from http://169.254.169.254/2016-09-02/meta-data/network/interfaces/macs/06:a9:b1:ee:c4:26/public-hostname (200, 47b) after 1 attempts
2019-05-18 15:40:03,505 - url_helper.py[DEBUG]: [0/6] open 'http://169.254.169.254/2016-09-02/meta-data/network/interfaces/macs/06:a9:b1:ee:c4:26/vpc-ipv4-cidr-block' with {'timeout': 5.0, 'method': 'GET', 'url': 'http://169.254.169.254/2016-09-02/meta-data/network/interfaces/macs/06:a9:b1:ee:c4:26/vpc-ipv4-cidr-block', 'headers': {'User-Agent': 'Cloud-Init/18.3-9-g2e62cb8a-0ubuntu1~16.04.2'}, 'allow_redirects': True} configuration
2019-05-18 15:40:03,506 - url_helper.py[DEBUG]: Read from http://169.254.169.254/2016-09-02/meta-data/network/interfaces/macs/06:a9:b1:ee:c4:26/vpc-ipv4-cidr-block (200, 11b) after 1 attempts
2019-05-18 15:40:03,507 - url_helper.py[DEBUG]: [0/6] open 'http://169.254.169.254/2016-09-02/meta-data/network/interfaces/macs/06:a9:b1:ee:c4:26/mac' with {'timeout': 5.0, 'method': 'GET', 'url': 'http://169.254.169.254/2016-09-02/meta-data/network/interfaces/macs/06:a9:b1:ee:c4:26/mac', 'headers': {'User-Agent': 'Cloud-Init/18.3-9-g2e62cb8a-0ubuntu1~16.04.2'}, 'allow_redirects': True} configuration
2019-05-18 15:40:03,508 - url_helper.py[DEBUG]: Read from http://169.254.169.254/2016-09-02/meta-data/network/interfaces/macs/06:a9:b1:ee:c4:26/mac (200, 17b) after 1 attempts
2019-05-18 15:40:03,508 - url_helper.py[DEBUG]: [0/6] open 'http://169.254.169.254/2016-09-02/meta-data/network/interfaces/macs/06:a9:b1:ee:c4:26/subnet-id' with {'timeout': 5.0, 'method': 'GET', 'url': 'http://169.254.169.254/2016-09-02/meta-data/network/interfaces/macs/06:a9:b1:ee:c4:26/subnet-id', 'headers': {'User-Agent': 'Cloud-Init/18.3-9-g2e62cb8a-0ubuntu1~16.04.2'}, 'allow_redirects': True} configuration
2019-05-18 15:40:03,511 - url_helper.py[DEBUG]: Read from http://169.254.169.254/2016-09-02/meta-data/network/interfaces/macs/06:a9:b1:ee:c4:26/subnet-id (200, 24b) after 1 attempts
2019-05-18 15:40:03,511 - url_helper.py[DEBUG]: [0/6] open 'http://169.254.169.254/2016-09-02/meta-data/network/interfaces/macs/06:a9:b1:ee:c4:26/local-ipv4s' with {'timeout': 5.0, 'method': 'GET', 'url': 'http://169.254.169.254/2016-09-02/meta-data/network/interfaces/macs/06:a9:b1:ee:c4:26/local-ipv4s', 'headers': {'User-Agent': 'Cloud-Init/18.3-9-g2e62cb8a-0ubuntu1~16.04.2'}, 'allow_redirects': True} configuration
2019-05-18 15:40:03,512 - url_helper.py[DEBUG]: Read from http://169.254.169.254/2016-09-02/meta-data/network/interfaces/macs/06:a9:b1:ee:c4:26/local-ipv4s (200, 10b) after 1 attempts
2019-05-18 15:40:03,512 - url_helper.py[DEBUG]: [0/6] open 'http://169.254.169.254/2016-09-02/meta-data/network/interfaces/macs/06:a9:b1:ee:c4:26/interface-id' with {'timeout': 5.0, 'method': 'GET', 'url': 'http://169.254.169.254/2016-09-02/meta-data/network/interfaces/macs/06:a9:b1:ee:c4:26/interface-id', 'headers': {'User-Agent': 'Cloud-Init/18.3-9-g2e62cb8a-0ubuntu1~16.04.2'}, 'allow_redirects': True} configuration
2019-05-18 15:40:03,514 - url_helper.py[DEBUG]: Read from http://169.254.169.254/2016-09-02/meta-data/network/interfaces/macs/06:a9:b1:ee:c4:26/interface-id (200, 21b) after 1 attempts
2019-05-18 15:40:03,514 - url_helper.py[DEBUG]: [0/6] open 'http://169.254.169.254/2016-09-02/meta-data/network/interfaces/macs/06:a9:b1:ee:c4:26/vpc-id' with {'timeout': 5.0, 'method': 'GET', 'url': 'http://169.254.169.254/2016-09-02/meta-data/network/interfaces/macs/06:a9:b1:ee:c4:26/vpc-id', 'headers': {'User-Agent': 'Cloud-Init/18.3-9-g2e62cb8a-0ubuntu1~16.04.2'}, 'allow_redirects': True} configuration
2019-05-18 15:40:03,515 - url_helper.py[DEBUG]: Read from http://169.254.169.254/2016-09-02/meta-data/network/interfaces/macs/06:a9:b1:ee:c4:26/vpc-id (200, 21b) after 1 attempts
2019-05-18 15:40:03,515 - url_helper.py[DEBUG]: [0/6] open 'http://169.254.169.254/2016-09-02/meta-data/network/interfaces/macs/06:a9:b1:ee:c4:26/subnet-ipv4-cidr-block' with {'timeout': 5.0, 'method': 'GET', 'url': 'http://169.254.169.254/2016-09-02/meta-data/network/interfaces/macs/06:a9:b1:ee:c4:26/subnet-ipv4-cidr-block', 'headers': {'User-Agent': 'Cloud-Init/18.3-9-g2e62cb8a-0ubuntu1~16.04.2'}, 'allow_redirects': True} configuration
2019-05-18 15:40:03,517 - url_helper.py[DEBUG]: Read from http://169.254.169.254/2016-09-02/meta-data/network/interfaces/macs/06:a9:b1:ee:c4:26/subnet-ipv4-cidr-block (200, 11b) after 1 attempts
2019-05-18 15:40:03,517 - url_helper.py[DEBUG]: [0/6] open 'http://169.254.169.254/2016-09-02/meta-data/network/interfaces/macs/06:a9:b1:ee:c4:26/security-group-ids' with {'timeout': 5.0, 'method': 'GET', 'url': 'http://169.254.169.254/2016-09-02/meta-data/network/interfaces/macs/06:a9:b1:ee:c4:26/security-group-ids', 'headers': {'User-Agent': 'Cloud-Init/18.3-9-g2e62cb8a-0ubuntu1~16.04.2'}, 'allow_redirects': True} configuration
2019-05-18 15:40:03,518 - url_helper.py[DEBUG]: Read from http://169.254.169.254/2016-09-02/meta-data/network/interfaces/macs/06:a9:b1:ee:c4:26/security-group-ids (200, 20b) after 1 attempts
2019-05-18 15:40:03,519 - url_helper.py[DEBUG]: [0/6] open 'http://169.254.169.254/2016-09-02/meta-data/network/interfaces/macs/06:a9:b1:ee:c4:26/local-hostname' with {'timeout': 5.0, 'method': 'GET', 'url': 'http://169.254.169.254/2016-09-02/meta-data/network/interfaces/macs/06:a9:b1:ee:c4:26/local-hostname', 'headers': {'User-Agent': 'Cloud-Init/18.3-9-g2e62cb8a-0ubuntu1~16.04.2'}, 'allow_redirects': True} configuration
2019-05-18 15:40:03,520 - url_helper.py[DEBUG]: Read from http://169.254.169.254/2016-09-02/meta-data/network/interfaces/macs/06:a9:b1:ee:c4:26/local-hostname (200, 40b) after 1 attempts
2019-05-18 15:40:03,520 - url_helper.py[DEBUG]: [0/6] open 'http://169.254.169.254/2016-09-02/meta-data/network/interfaces/macs/06:a9:b1:ee:c4:26/public-ipv4s' with {'timeout': 5.0, 'method': 'GET', 'url': 'http://169.254.169.254/2016-09-02/meta-data/network/interfaces/macs/06:a9:b1:ee:c4:26/public-ipv4s', 'headers': {'User-Agent': 'Cloud-Init/18.3-9-g2e62cb8a-0ubuntu1~16.04.2'}, 'allow_redirects': True} configuration
2019-05-18 15:40:03,522 - url_helper.py[DEBUG]: Read from http://169.254.169.254/2016-09-02/meta-data/network/interfaces/macs/06:a9:b1:ee:c4:26/public-ipv4s (200, 11b) after 1 attempts
2019-05-18 15:40:03,522 - url_helper.py[DEBUG]: [0/6] open 'http://169.254.169.254/2016-09-02/meta-data/placement/' with {'timeout': 5.0, 'method': 'GET', 'url': 'http://169.254.169.254/2016-09-02/meta-data/placement/', 'headers': {'User-Agent': 'Cloud-Init/18.3-9-g2e62cb8a-0ubuntu1~16.04.2'}, 'allow_redirects': True} configuration
2019-05-18 15:40:03,523 - url_helper.py[DEBUG]: Read from http://169.254.169.254/2016-09-02/meta-data/placement/ (200, 17b) after 1 attempts
2019-05-18 15:40:03,523 - url_helper.py[DEBUG]: [0/6] open 'http://169.254.169.254/2016-09-02/meta-data/placement/availability-zone' with {'timeout': 5.0, 'method': 'GET', 'url': 'http://169.254.169.254/2016-09-02/meta-data/placement/availability-zone', 'headers': {'User-Agent': 'Cloud-Init/18.3-9-g2e62cb8a-0ubuntu1~16.04.2'}, 'allow_redirects': True} configuration
2019-05-18 15:40:03,525 - url_helper.py[DEBUG]: Read from http://169.254.169.254/2016-09-02/meta-data/placement/availability-zone (200, 10b) after 1 attempts
2019-05-18 15:40:03,525 - url_helper.py[DEBUG]: [0/6] open 'http://169.254.169.254/2016-09-02/meta-data/public-keys/' with {'timeout': 5.0, 'method': 'GET', 'url': 'http://169.254.169.254/2016-09-02/meta-data/public-keys/', 'headers': {'User-Agent': 'Cloud-Init/18.3-9-g2e62cb8a-0ubuntu1~16.04.2'}, 'allow_redirects': True} configuration
2019-05-18 15:40:03,526 - url_helper.py[DEBUG]: Read from http://169.254.169.254/2016-09-02/meta-data/public-keys/ (200, 68b) after 1 attempts
2019-05-18 15:40:03,526 - url_helper.py[DEBUG]: [0/6] open 'http://169.254.169.254/2016-09-02/meta-data/public-keys/0/openssh-key' with {'timeout': 5.0, 'method': 'GET', 'url': 'http://169.254.169.254/2016-09-02/meta-data/public-keys/0/openssh-key', 'headers': {'User-Agent': 'Cloud-Init/18.3-9-g2e62cb8a-0ubuntu1~16.04.2'}, 'allow_redirects': True} configuration
2019-05-18 15:40:03,528 - url_helper.py[DEBUG]: Read from http://169.254.169.254/2016-09-02/meta-data/public-keys/0/openssh-key (200, 448b) after 1 attempts
2019-05-18 15:40:03,528 - url_helper.py[DEBUG]: [0/6] open 'http://169.254.169.254/2016-09-02/meta-data/services/' with {'timeout': 5.0, 'method': 'GET', 'url': 'http://169.254.169.254/2016-09-02/meta-data/services/', 'headers': {'User-Agent': 'Cloud-Init/18.3-9-g2e62cb8a-0ubuntu1~16.04.2'}, 'allow_redirects': True} configuration
2019-05-18 15:40:03,530 - url_helper.py[DEBUG]: Read from http://169.254.169.254/2016-09-02/meta-data/services/ (200, 16b) after 1 attempts
2019-05-18 15:40:03,530 - url_helper.py[DEBUG]: [0/6] open 'http://169.254.169.254/2016-09-02/meta-data/services/partition' with {'timeout': 5.0, 'method': 'GET', 'url': 'http://169.254.169.254/2016-09-02/meta-data/services/partition', 'headers': {'User-Agent': 'Cloud-Init/18.3-9-g2e62cb8a-0ubuntu1~16.04.2'}, 'allow_redirects': True} configuration
2019-05-18 15:40:03,531 - url_helper.py[DEBUG]: Read from http://169.254.169.254/2016-09-02/meta-data/services/partition (200, 3b) after 1 attempts
2019-05-18 15:40:03,531 - url_helper.py[DEBUG]: [0/6] open 'http://169.254.169.254/2016-09-02/meta-data/services/domain' with {'timeout': 5.0, 'method': 'GET', 'url': 'http://169.254.169.254/2016-09-02/meta-data/services/domain', 'headers': {'User-Agent': 'Cloud-Init/18.3-9-g2e62cb8a-0ubuntu1~16.04.2'}, 'allow_redirects': True} configuration
2019-05-18 15:40:03,533 - url_helper.py[DEBUG]: Read from http://169.254.169.254/2016-09-02/meta-data/services/domain (200, 13b) after 1 attempts
2019-05-18 15:40:03,533 - url_helper.py[DEBUG]: [0/6] open 'http://169.254.169.254/2016-09-02/meta-data/reservation-id' with {'timeout': 5.0, 'method': 'GET', 'url': 'http://169.254.169.254/2016-09-02/meta-data/reservation-id', 'headers': {'User-Agent': 'Cloud-Init/18.3-9-g2e62cb8a-0ubuntu1~16.04.2'}, 'allow_redirects': True} configuration
2019-05-18 15:40:03,534 - url_helper.py[DEBUG]: Read from http://169.254.169.254/2016-09-02/meta-data/reservation-id (200, 19b) after 1 attempts
2019-05-18 15:40:03,535 - url_helper.py[DEBUG]: [0/6] open 'http://169.254.169.254/2016-09-02/meta-data/ami-id' with {'timeout': 5.0, 'method': 'GET', 'url': 'http://169.254.169.254/2016-09-02/meta-data/ami-id', 'headers': {'User-Agent': 'Cloud-Init/18.3-9-g2e62cb8a-0ubuntu1~16.04.2'}, 'allow_redirects': True} configuration
2019-05-18 15:40:03,536 - url_helper.py[DEBUG]: Read from http://169.254.169.254/2016-09-02/meta-data/ami-id (200, 21b) after 1 attempts
2019-05-18 15:40:03,536 - url_helper.py[DEBUG]: [0/6] open 'http://169.254.169.254/2016-09-02/meta-data/hostname' with {'timeout': 5.0, 'method': 'GET', 'url': 'http://169.254.169.254/2016-09-02/meta-data/hostname', 'headers': {'User-Agent': 'Cloud-Init/18.3-9-g2e62cb8a-0ubuntu1~16.04.2'}, 'allow_redirects': True} configuration
2019-05-18 15:40:03,537 - url_helper.py[DEBUG]: Read from http://169.254.169.254/2016-09-02/meta-data/hostname (200, 40b) after 1 attempts
2019-05-18 15:40:03,538 - url_helper.py[DEBUG]: [0/6] open 'http://169.254.169.254/2016-09-02/meta-data/ami-manifest-path' with {'timeout': 5.0, 'method': 'GET', 'url': 'http://169.254.169.254/2016-09-02/meta-data/ami-manifest-path', 'headers': {'User-Agent': 'Cloud-Init/18.3-9-g2e62cb8a-0ubuntu1~16.04.2'}, 'allow_redirects': True} configuration
2019-05-18 15:40:03,539 - url_helper.py[DEBUG]: Read from http://169.254.169.254/2016-09-02/meta-data/ami-manifest-path (200, 9b) after 1 attempts
2019-05-18 15:40:03,539 - url_helper.py[DEBUG]: [0/6] open 'http://169.254.169.254/2016-09-02/meta-data/instance-id' with {'timeout': 5.0, 'method': 'GET', 'url': 'http://169.254.169.254/2016-09-02/meta-data/instance-id', 'headers': {'User-Agent': 'Cloud-Init/18.3-9-g2e62cb8a-0ubuntu1~16.04.2'}, 'allow_redirects': True} configuration
2019-05-18 15:40:03,541 - url_helper.py[DEBUG]: Read from http://169.254.169.254/2016-09-02/meta-data/instance-id (200, 19b) after 1 attempts
2019-05-18 15:40:03,541 - url_helper.py[DEBUG]: [0/6] open 'http://169.254.169.254/2016-09-02/meta-data/local-ipv4' with {'timeout': 5.0, 'method': 'GET', 'url': 'http://169.254.169.254/2016-09-02/meta-data/local-ipv4', 'headers': {'User-Agent': 'Cloud-Init/18.3-9-g2e62cb8a-0ubuntu1~16.04.2'}, 'allow_redirects': True} configuration
2019-05-18 15:40:03,542 - url_helper.py[DEBUG]: Read from http://169.254.169.254/2016-09-02/meta-data/local-ipv4 (200, 10b) after 1 attempts
2019-05-18 15:40:03,542 - url_helper.py[DEBUG]: [0/6] open 'http://169.254.169.254/2016-09-02/meta-data/profile' with {'timeout': 5.0, 'method': 'GET', 'url': 'http://169.254.169.254/2016-09-02/meta-data/profile', 'headers': {'User-Agent': 'Cloud-Init/18.3-9-g2e62cb8a-0ubuntu1~16.04.2'}, 'allow_redirects': True} configuration
2019-05-18 15:40:03,544 - url_helper.py[DEBUG]: Read from http://169.254.169.254/2016-09-02/meta-data/profile (200, 11b) after 1 attempts
2019-05-18 15:40:03,544 - url_helper.py[DEBUG]: [0/6] open 'http://169.254.169.254/2016-09-02/meta-data/security-groups' with {'timeout': 5.0, 'method': 'GET', 'url': 'http://169.254.169.254/2016-09-02/meta-data/security-groups', 'headers': {'User-Agent': 'Cloud-Init/18.3-9-g2e62cb8a-0ubuntu1~16.04.2'}, 'allow_redirects': True} configuration
2019-05-18 15:40:03,545 - url_helper.py[DEBUG]: Read from http://169.254.169.254/2016-09-02/meta-data/security-groups (200, 81b) after 1 attempts
2019-05-18 15:40:03,545 - url_helper.py[DEBUG]: [0/6] open 'http://169.254.169.254/2016-09-02/meta-data/instance-action' with {'timeout': 5.0, 'method': 'GET', 'url': 'http://169.254.169.254/2016-09-02/meta-data/instance-action', 'headers': {'User-Agent': 'Cloud-Init/18.3-9-g2e62cb8a-0ubuntu1~16.04.2'}, 'allow_redirects': True} configuration
2019-05-18 15:40:03,547 - url_helper.py[DEBUG]: Read from http://169.254.169.254/2016-09-02/meta-data/instance-action (200, 4b) after 1 attempts
2019-05-18 15:40:03,547 - url_helper.py[DEBUG]: [0/6] open 'http://169.254.169.254/2016-09-02/meta-data/instance-type' with {'timeout': 5.0, 'method': 'GET', 'url': 'http://169.254.169.254/2016-09-02/meta-data/instance-type', 'headers': {'User-Agent': 'Cloud-Init/18.3-9-g2e62cb8a-0ubuntu1~16.04.2'}, 'allow_redirects': True} configuration
2019-05-18 15:40:03,548 - url_helper.py[DEBUG]: Read from http://169.254.169.254/2016-09-02/meta-data/instance-type (200, 10b) after 1 attempts
2019-05-18 15:40:03,549 - url_helper.py[DEBUG]: [0/6] open 'http://169.254.169.254/2016-09-02/meta-data/mac' with {'timeout': 5.0, 'method': 'GET', 'url': 'http://169.254.169.254/2016-09-02/meta-data/mac', 'headers': {'User-Agent': 'Cloud-Init/18.3-9-g2e62cb8a-0ubuntu1~16.04.2'}, 'allow_redirects': True} configuration
2019-05-18 15:40:03,550 - url_helper.py[DEBUG]: Read from http://169.254.169.254/2016-09-02/meta-data/mac (200, 17b) after 1 attempts
2019-05-18 15:40:03,550 - url_helper.py[DEBUG]: [0/6] open 'http://169.254.169.254/2016-09-02/meta-data/ami-launch-index' with {'timeout': 5.0, 'method': 'GET', 'url': 'http://169.254.169.254/2016-09-02/meta-data/ami-launch-index', 'headers': {'User-Agent': 'Cloud-Init/18.3-9-g2e62cb8a-0ubuntu1~16.04.2'}, 'allow_redirects': True} configuration
2019-05-18 15:40:03,552 - url_helper.py[DEBUG]: Read from http://169.254.169.254/2016-09-02/meta-data/ami-launch-index (200, 1b) after 1 attempts
2019-05-18 15:40:03,552 - url_helper.py[DEBUG]: [0/6] open 'http://169.254.169.254/2016-09-02/meta-data/public-ipv4' with {'timeout': 5.0, 'method': 'GET', 'url': 'http://169.254.169.254/2016-09-02/meta-data/public-ipv4', 'headers': {'User-Agent': 'Cloud-Init/18.3-9-g2e62cb8a-0ubuntu1~16.04.2'}, 'allow_redirects': True} configuration
2019-05-18 15:40:03,553 - url_helper.py[DEBUG]: Read from http://169.254.169.254/2016-09-02/meta-data/public-ipv4 (200, 11b) after 1 attempts
2019-05-18 15:40:03,553 - url_helper.py[DEBUG]: [0/6] open 'http://169.254.169.254/2016-09-02/meta-data/public-hostname' with {'timeout': 5.0, 'method': 'GET', 'url': 'http://169.254.169.254/2016-09-02/meta-data/public-hostname', 'headers': {'User-Agent': 'Cloud-Init/18.3-9-g2e62cb8a-0ubuntu1~16.04.2'}, 'allow_redirects': True} configuration
2019-05-18 15:40:03,555 - url_helper.py[DEBUG]: Read from http://169.254.169.254/2016-09-02/meta-data/public-hostname (200, 47b) after 1 attempts
2019-05-18 15:40:03,555 - url_helper.py[DEBUG]: [0/6] open 'http://169.254.169.254/2016-09-02/meta-data/local-hostname' with {'timeout': 5.0, 'method': 'GET', 'url': 'http://169.254.169.254/2016-09-02/meta-data/local-hostname', 'headers': {'User-Agent': 'Cloud-Init/18.3-9-g2e62cb8a-0ubuntu1~16.04.2'}, 'allow_redirects': True} configuration
2019-05-18 15:40:03,556 - url_helper.py[DEBUG]: Read from http://169.254.169.254/2016-09-02/meta-data/local-hostname (200, 40b) after 1 attempts
2019-05-18 15:40:03,557 - url_helper.py[DEBUG]: [0/6] open 'http://169.254.169.254/2016-09-02/dynamic/instance-identity' with {'timeout': 5.0, 'method': 'GET', 'url': 'http://169.254.169.254/2016-09-02/dynamic/instance-identity', 'headers': {'User-Agent': 'Cloud-Init/18.3-9-g2e62cb8a-0ubuntu1~16.04.2'}, 'allow_redirects': True} configuration
2019-05-18 15:40:03,559 - url_helper.py[DEBUG]: Read from http://169.254.169.254/2016-09-02/dynamic/instance-identity (200, 33b) after 1 attempts
2019-05-18 15:40:03,560 - url_helper.py[DEBUG]: [0/6] open 'http://169.254.169.254/2016-09-02/dynamic/instance-identity/pkcs7' with {'timeout': 5.0, 'method': 'GET', 'url': 'http://169.254.169.254/2016-09-02/dynamic/instance-identity/pkcs7', 'headers': {'User-Agent': 'Cloud-Init/18.3-9-g2e62cb8a-0ubuntu1~16.04.2'}, 'allow_redirects': True} configuration
2019-05-18 15:40:03,561 - url_helper.py[DEBUG]: Read from http://169.254.169.254/2016-09-02/dynamic/instance-identity/pkcs7 (200, 1118b) after 1 attempts
2019-05-18 15:40:03,561 - url_helper.py[DEBUG]: [0/6] open 'http://169.254.169.254/2016-09-02/dynamic/instance-identity/document' with {'timeout': 5.0, 'method': 'GET', 'url': 'http://169.254.169.254/2016-09-02/dynamic/instance-identity/document', 'headers': {'User-Agent': 'Cloud-Init/18.3-9-g2e62cb8a-0ubuntu1~16.04.2'}, 'allow_redirects': True} configuration
2019-05-18 15:40:03,563 - url_helper.py[DEBUG]: Read from http://169.254.169.254/2016-09-02/dynamic/instance-identity/document (200, 476b) after 1 attempts
2019-05-18 15:40:03,563 - url_helper.py[DEBUG]: [0/6] open 'http://169.254.169.254/2016-09-02/dynamic/instance-identity/signature' with {'timeout': 5.0, 'method': 'GET', 'url': 'http://169.254.169.254/2016-09-02/dynamic/instance-identity/signature', 'headers': {'User-Agent': 'Cloud-Init/18.3-9-g2e62cb8a-0ubuntu1~16.04.2'}, 'allow_redirects': True} configuration
2019-05-18 15:40:03,564 - url_helper.py[DEBUG]: Read from http://169.254.169.254/2016-09-02/dynamic/instance-identity/signature (200, 174b) after 1 attempts
2019-05-18 15:40:03,564 - url_helper.py[DEBUG]: [0/6] open 'http://169.254.169.254/2016-09-02/dynamic/instance-identity/rsa2048' with {'timeout': 5.0, 'method': 'GET', 'url': 'http://169.254.169.254/2016-09-02/dynamic/instance-identity/rsa2048', 'headers': {'User-Agent': 'Cloud-Init/18.3-9-g2e62cb8a-0ubuntu1~16.04.2'}, 'allow_redirects': True} configuration
2019-05-18 15:40:03,566 - url_helper.py[DEBUG]: Read from http://169.254.169.254/2016-09-02/dynamic/instance-identity/rsa2048 (200, 1434b) after 1 attempts
2019-05-18 15:40:03,566 - util.py[DEBUG]: Crawl of metadata service took 0.107 seconds
2019-05-18 15:40:03,566 - util.py[DEBUG]: Running command ['ip', '-4', 'route', 'del', 'default', 'dev', 'ens3'] with allowed return codes [0] (shell=False, capture=True)
2019-05-18 15:40:03,568 - util.py[DEBUG]: Running command ['ip', '-family', 'inet', 'link', 'set', 'dev', 'ens3', 'down'] with allowed return codes [0] (shell=False, capture=True)
2019-05-18 15:40:03,603 - util.py[DEBUG]: Running command ['ip', '-family', 'inet', 'addr', 'del', '10.0.0.175/24', 'dev', 'ens3'] with allowed return codes [0] (shell=False, capture=True)
2019-05-18 15:40:03,606 - handlers.py[DEBUG]: finish: init-local/search-Ec2Local: SUCCESS: found local data from DataSourceEc2Local
2019-05-18 15:40:03,607 - stages.py[INFO]: Loaded datasource DataSourceEc2Local - DataSourceEc2Local
2019-05-18 15:40:03,607 - util.py[DEBUG]: Reading from /etc/cloud/cloud.cfg (quiet=False)
2019-05-18 15:40:03,607 - util.py[DEBUG]: Read 3169 bytes from /etc/cloud/cloud.cfg
2019-05-18 15:40:03,607 - util.py[DEBUG]: Attempting to load yaml from string of length 3169 with allowed root types (<class 'dict'>,)
2019-05-18 15:40:03,617 - util.py[DEBUG]: Reading from /etc/cloud/cloud.cfg.d/90_dpkg.cfg (quiet=False)
2019-05-18 15:40:03,618 - util.py[DEBUG]: Read 238 bytes from /etc/cloud/cloud.cfg.d/90_dpkg.cfg
2019-05-18 15:40:03,618 - util.py[DEBUG]: Attempting to load yaml from string of length 238 with allowed root types (<class 'dict'>,)
2019-05-18 15:40:03,619 - util.py[DEBUG]: Reading from /etc/cloud/cloud.cfg.d/05_logging.cfg (quiet=False)
2019-05-18 15:40:03,619 - util.py[DEBUG]: Read 2057 bytes from /etc/cloud/cloud.cfg.d/05_logging.cfg
2019-05-18 15:40:03,619 - util.py[DEBUG]: Attempting to load yaml from string of length 2057 with allowed root types (<class 'dict'>,)
2019-05-18 15:40:03,622 - util.py[DEBUG]: Reading from /run/cloud-init/cloud.cfg (quiet=False)
2019-05-18 15:40:03,622 - util.py[DEBUG]: Read 44 bytes from /run/cloud-init/cloud.cfg
2019-05-18 15:40:03,622 - util.py[DEBUG]: Attempting to load yaml from string of length 44 with allowed root types (<class 'dict'>,)
2019-05-18 15:40:03,623 - util.py[DEBUG]: Attempting to load yaml from string of length 0 with allowed root types (<class 'dict'>,)
2019-05-18 15:40:03,623 - util.py[DEBUG]: loaded blob returned None, returning default.
2019-05-18 15:40:03,624 - util.py[DEBUG]: Attempting to remove /var/lib/cloud/instance
2019-05-18 15:40:03,624 - util.py[DEBUG]: Creating symbolic link from '/var/lib/cloud/instance' => '/var/lib/cloud/instances/i-0ca59a4b9f642f204'
2019-05-18 15:40:03,625 - util.py[DEBUG]: Reading from /var/lib/cloud/instances/i-0ca59a4b9f642f204/datasource (quiet=False)
2019-05-18 15:40:03,625 - util.py[DEBUG]: Writing to /var/lib/cloud/instances/i-0ca59a4b9f642f204/datasource - wb: [644] 39 bytes
2019-05-18 15:40:03,625 - util.py[DEBUG]: Writing to /var/lib/cloud/data/previous-datasource - wb: [644] 39 bytes
2019-05-18 15:40:03,625 - util.py[DEBUG]: Reading from /var/lib/cloud/data/instance-id (quiet=False)
2019-05-18 15:40:03,626 - stages.py[DEBUG]: previous iid found to be NO_PREVIOUS_INSTANCE_ID
2019-05-18 15:40:03,626 - util.py[DEBUG]: Writing to /var/lib/cloud/data/instance-id - wb: [644] 20 bytes
2019-05-18 15:40:03,626 - util.py[DEBUG]: Writing to /run/cloud-init/.instance-id - wb: [644] 20 bytes
2019-05-18 15:40:03,626 - util.py[DEBUG]: Writing to /var/lib/cloud/data/previous-instance-id - wb: [644] 24 bytes
2019-05-18 15:40:03,627 - util.py[DEBUG]: Writing to /var/lib/cloud/instance/obj.pkl - wb: [400] 9121 bytes
2019-05-18 15:40:03,627 - main.py[DEBUG]: [local] init will now be targeting instance id: i-0ca59a4b9f642f204. new=True
2019-05-18 15:40:03,627 - util.py[DEBUG]: Reading from /etc/cloud/cloud.cfg (quiet=False)
2019-05-18 15:40:03,627 - util.py[DEBUG]: Read 3169 bytes from /etc/cloud/cloud.cfg
2019-05-18 15:40:03,628 - util.py[DEBUG]: Attempting to load yaml from string of length 3169 with allowed root types (<class 'dict'>,)
2019-05-18 15:40:03,638 - util.py[DEBUG]: Reading from /etc/cloud/cloud.cfg.d/90_dpkg.cfg (quiet=False)
2019-05-18 15:40:03,638 - util.py[DEBUG]: Read 238 bytes from /etc/cloud/cloud.cfg.d/90_dpkg.cfg
2019-05-18 15:40:03,638 - util.py[DEBUG]: Attempting to load yaml from string of length 238 with allowed root types (<class 'dict'>,)
2019-05-18 15:40:03,639 - util.py[DEBUG]: Reading from /etc/cloud/cloud.cfg.d/05_logging.cfg (quiet=False)
2019-05-18 15:40:03,639 - util.py[DEBUG]: Read 2057 bytes from /etc/cloud/cloud.cfg.d/05_logging.cfg
2019-05-18 15:40:03,639 - util.py[DEBUG]: Attempting to load yaml from string of length 2057 with allowed root types (<class 'dict'>,)
2019-05-18 15:40:03,642 - util.py[DEBUG]: Reading from /run/cloud-init/cloud.cfg (quiet=False)
2019-05-18 15:40:03,643 - util.py[DEBUG]: Read 44 bytes from /run/cloud-init/cloud.cfg
2019-05-18 15:40:03,643 - util.py[DEBUG]: Attempting to load yaml from string of length 44 with allowed root types (<class 'dict'>,)
2019-05-18 15:40:03,643 - util.py[DEBUG]: Attempting to load yaml from string of length 0 with allowed root types (<class 'dict'>,)
2019-05-18 15:40:03,643 - util.py[DEBUG]: loaded blob returned None, returning default.
2019-05-18 15:40:03,644 - stages.py[DEBUG]: Using distro class <class 'cloudinit.distros.ubuntu.Distro'>
2019-05-18 15:40:03,645 - cc_set_hostname.py[DEBUG]: Setting the hostname to ip-10-0-0-175.eu-west-1.compute.internal (ip-10-0-0-175)
2019-05-18 15:40:03,645 - util.py[DEBUG]: Reading from /etc/hostname (quiet=False)
2019-05-18 15:40:03,645 - util.py[DEBUG]: Read 7 bytes from /etc/hostname
2019-05-18 15:40:03,645 - util.py[DEBUG]: Writing to /etc/hostname - wb: [644] 14 bytes
2019-05-18 15:40:03,645 - __init__.py[DEBUG]: Non-persistently setting the system hostname to ip-10-0-0-175
2019-05-18 15:40:03,645 - util.py[DEBUG]: Running command ['hostname', 'ip-10-0-0-175'] with allowed return codes [0] (shell=False, capture=True)
2019-05-18 15:40:03,648 - util.py[DEBUG]: Reading from /sys/class/net/ens3/address (quiet=False)
2019-05-18 15:40:03,648 - util.py[DEBUG]: Read 18 bytes from /sys/class/net/ens3/address
2019-05-18 15:40:03,649 - stages.py[DEBUG]: applying net config names for {'config': [{'name': 'ens3', 'mac_address': '06:a9:b1:ee:c4:26', 'type': 'physical', 'subnets': [{'type': 'dhcp4'}]}], 'version': 1}
2019-05-18 15:40:03,649 - util.py[DEBUG]: Reading from /sys/class/net/ens3/device/device (quiet=False)
2019-05-18 15:40:03,649 - util.py[DEBUG]: Read 7 bytes from /sys/class/net/ens3/device/device
2019-05-18 15:40:03,649 - util.py[DEBUG]: Reading from /sys/class/net/lo/addr_assign_type (quiet=False)
2019-05-18 15:40:03,649 - util.py[DEBUG]: Read 2 bytes from /sys/class/net/lo/addr_assign_type
2019-05-18 15:40:03,649 - util.py[DEBUG]: Reading from /sys/class/net/lo/uevent (quiet=False)
2019-05-18 15:40:03,649 - util.py[DEBUG]: Read 23 bytes from /sys/class/net/lo/uevent
2019-05-18 15:40:03,649 - util.py[DEBUG]: Reading from /sys/class/net/lo/address (quiet=False)
2019-05-18 15:40:03,649 - util.py[DEBUG]: Read 18 bytes from /sys/class/net/lo/address
2019-05-18 15:40:03,649 - util.py[DEBUG]: Reading from /sys/class/net/lo/device/device (quiet=False)
2019-05-18 15:40:03,649 - util.py[DEBUG]: Reading from /sys/class/net/ens3/addr_assign_type (quiet=False)
2019-05-18 15:40:03,650 - util.py[DEBUG]: Read 2 bytes from /sys/class/net/ens3/addr_assign_type
2019-05-18 15:40:03,650 - util.py[DEBUG]: Reading from /sys/class/net/ens3/uevent (quiet=False)
2019-05-18 15:40:03,650 - util.py[DEBUG]: Read 25 bytes from /sys/class/net/ens3/uevent
2019-05-18 15:40:03,650 - util.py[DEBUG]: Reading from /sys/class/net/ens3/address (quiet=False)
2019-05-18 15:40:03,650 - util.py[DEBUG]: Read 18 bytes from /sys/class/net/ens3/address
2019-05-18 15:40:03,650 - util.py[DEBUG]: Reading from /sys/class/net/ens3/device/device (quiet=False)
2019-05-18 15:40:03,650 - util.py[DEBUG]: Read 7 bytes from /sys/class/net/ens3/device/device
2019-05-18 15:40:03,650 - util.py[DEBUG]: Reading from /sys/class/net/lo/operstate (quiet=False)
2019-05-18 15:40:03,650 - util.py[DEBUG]: Read 8 bytes from /sys/class/net/lo/operstate
2019-05-18 15:40:03,650 - util.py[DEBUG]: Reading from /sys/class/net/ens3/operstate (quiet=False)
2019-05-18 15:40:03,650 - util.py[DEBUG]: Read 5 bytes from /sys/class/net/ens3/operstate
2019-05-18 15:40:03,650 - util.py[DEBUG]: Running command ['ip', '-6', 'addr', 'show', 'permanent', 'scope', 'global'] with allowed return codes [0] (shell=False, capture=True)
2019-05-18 15:40:03,653 - util.py[DEBUG]: Running command ['ip', '-4', 'addr', 'show'] with allowed return codes [0] (shell=False, capture=True)
2019-05-18 15:40:03,655 - __init__.py[DEBUG]: no work necessary for renaming of [['06:a9:b1:ee:c4:26', 'ens3', 'ixgbevf', '0x10ed']]
2019-05-18 15:40:03,655 - stages.py[INFO]: Applying network configuration from ds bringup=False: {'config': [{'name': 'ens3', 'mac_address': '06:a9:b1:ee:c4:26', 'type': 'physical', 'subnets': [{'type': 'dhcp4'}]}], 'version': 1}
2019-05-18 15:40:03,656 - __init__.py[DEBUG]: Selected renderer 'eni' from priority list: None
2019-05-18 15:40:03,658 - util.py[DEBUG]: Writing to /etc/network/interfaces.d/50-cloud-init.cfg - wb: [644] 367 bytes
2019-05-18 15:40:03,658 - util.py[DEBUG]: Writing to /etc/udev/rules.d/70-persistent-net.rules - wb: [644] 96 bytes
2019-05-18 15:40:03,659 - main.py[DEBUG]: [local] Exiting. datasource DataSourceEc2Local not in local mode.
2019-05-18 15:40:03,659 - util.py[DEBUG]: Reading from /proc/uptime (quiet=False)
2019-05-18 15:40:03,660 - util.py[DEBUG]: Read 12 bytes from /proc/uptime
2019-05-18 15:40:03,660 - util.py[DEBUG]: cloud-init mode 'init' took 0.568 seconds (0.56)
2019-05-18 15:40:03,660 - handlers.py[DEBUG]: finish: init-local: SUCCESS: searching for local datasources
2019-05-18 15:40:04,215 - util.py[DEBUG]: Cloud-init v. 18.3-9-g2e62cb8a-0ubuntu1~16.04.2 running 'init' at Sat, 18 May 2019 15:40:04 +0000. Up 7.49 seconds.
2019-05-18 15:40:04,215 - main.py[DEBUG]: No kernel command line url found.
2019-05-18 15:40:04,215 - main.py[DEBUG]: Closing stdin.
2019-05-18 15:40:04,217 - util.py[DEBUG]: Writing to /var/log/cloud-init.log - ab: [644] 0 bytes
2019-05-18 15:40:04,217 - util.py[DEBUG]: Changing the ownership of /var/log/cloud-init.log to 104:4
2019-05-18 15:40:04,218 - util.py[DEBUG]: Running command ['ip', 'addr', 'show'] with allowed return codes [0] (shell=False, capture=True)
2019-05-18 15:40:04,221 - util.py[DEBUG]: Running command ['ip', '-o', 'route', 'list'] with allowed return codes [0] (shell=False, capture=True)
2019-05-18 15:40:04,223 - util.py[DEBUG]: Running command ['ip', '--oneline', '-6', 'route', 'list', 'table', 'all'] with allowed return codes [0, 1] (shell=False, capture=True)
2019-05-18 15:40:04,225 - main.py[DEBUG]: Checking to see if files that we need already exist from a previous run that would allow us to stop early.
2019-05-18 15:40:04,225 - main.py[DEBUG]: Execution continuing, no previous run detected that would allow us to stop early.
2019-05-18 15:40:04,226 - handlers.py[DEBUG]: start: init-network/check-cache: attempting to read from cache [trust]
2019-05-18 15:40:04,226 - util.py[DEBUG]: Reading from /var/lib/cloud/instance/obj.pkl (quiet=False)
2019-05-18 15:40:04,226 - util.py[DEBUG]: Read 9121 bytes from /var/lib/cloud/instance/obj.pkl
2019-05-18 15:40:04,228 - util.py[DEBUG]: Reading from /run/cloud-init/.instance-id (quiet=False)
2019-05-18 15:40:04,228 - util.py[DEBUG]: Read 20 bytes from /run/cloud-init/.instance-id
2019-05-18 15:40:04,228 - stages.py[DEBUG]: restored from cache with run check: DataSourceEc2Local
2019-05-18 15:40:04,228 - handlers.py[DEBUG]: finish: init-network/check-cache: SUCCESS: restored from cache with run check: DataSourceEc2Local
2019-05-18 15:40:04,228 - util.py[DEBUG]: Reading from /etc/cloud/cloud.cfg (quiet=False)
2019-05-18 15:40:04,228 - util.py[DEBUG]: Read 3169 bytes from /etc/cloud/cloud.cfg
2019-05-18 15:40:04,228 - util.py[DEBUG]: Attempting to load yaml from string of length 3169 with allowed root types (<class 'dict'>,)
2019-05-18 15:40:04,239 - util.py[DEBUG]: Reading from /etc/cloud/cloud.cfg.d/90_dpkg.cfg (quiet=False)
2019-05-18 15:40:04,239 - util.py[DEBUG]: Read 238 bytes from /etc/cloud/cloud.cfg.d/90_dpkg.cfg
2019-05-18 15:40:04,239 - util.py[DEBUG]: Attempting to load yaml from string of length 238 with allowed root types (<class 'dict'>,)
2019-05-18 15:40:04,241 - util.py[DEBUG]: Reading from /etc/cloud/cloud.cfg.d/05_logging.cfg (quiet=False)
2019-05-18 15:40:04,241 - util.py[DEBUG]: Read 2057 bytes from /etc/cloud/cloud.cfg.d/05_logging.cfg
2019-05-18 15:40:04,241 - util.py[DEBUG]: Attempting to load yaml from string of length 2057 with allowed root types (<class 'dict'>,)
2019-05-18 15:40:04,244 - util.py[DEBUG]: Reading from /run/cloud-init/cloud.cfg (quiet=False)
2019-05-18 15:40:04,244 - util.py[DEBUG]: Read 44 bytes from /run/cloud-init/cloud.cfg
2019-05-18 15:40:04,244 - util.py[DEBUG]: Attempting to load yaml from string of length 44 with allowed root types (<class 'dict'>,)
2019-05-18 15:40:04,245 - util.py[DEBUG]: Attempting to load yaml from string of length 0 with allowed root types (<class 'dict'>,)
2019-05-18 15:40:04,245 - util.py[DEBUG]: loaded blob returned None, returning default.
2019-05-18 15:40:04,245 - util.py[DEBUG]: Attempting to remove /var/lib/cloud/instance
2019-05-18 15:40:04,245 - util.py[DEBUG]: Creating symbolic link from '/var/lib/cloud/instance' => '/var/lib/cloud/instances/i-0ca59a4b9f642f204'
2019-05-18 15:40:04,246 - util.py[DEBUG]: Reading from /var/lib/cloud/instances/i-0ca59a4b9f642f204/datasource (quiet=False)
2019-05-18 15:40:04,246 - util.py[DEBUG]: Read 39 bytes from /var/lib/cloud/instances/i-0ca59a4b9f642f204/datasource
2019-05-18 15:40:04,246 - util.py[DEBUG]: Writing to /var/lib/cloud/instances/i-0ca59a4b9f642f204/datasource - wb: [644] 39 bytes
2019-05-18 15:40:04,246 - util.py[DEBUG]: Writing to /var/lib/cloud/data/previous-datasource - wb: [644] 39 bytes
2019-05-18 15:40:04,247 - util.py[DEBUG]: Reading from /var/lib/cloud/data/instance-id (quiet=False)
2019-05-18 15:40:04,247 - util.py[DEBUG]: Read 20 bytes from /var/lib/cloud/data/instance-id
2019-05-18 15:40:04,247 - stages.py[DEBUG]: previous iid found to be i-0ca59a4b9f642f204
2019-05-18 15:40:04,247 - util.py[DEBUG]: Writing to /var/lib/cloud/data/instance-id - wb: [644] 20 bytes
2019-05-18 15:40:04,247 - util.py[DEBUG]: Writing to /run/cloud-init/.instance-id - wb: [644] 20 bytes
2019-05-18 15:40:04,248 - util.py[DEBUG]: Writing to /var/lib/cloud/data/previous-instance-id - wb: [644] 20 bytes
2019-05-18 15:40:04,248 - util.py[DEBUG]: Writing to /var/lib/cloud/instance/obj.pkl - wb: [400] 9200 bytes
2019-05-18 15:40:04,249 - main.py[DEBUG]: [net] init will now be targeting instance id: i-0ca59a4b9f642f204. new=False
2019-05-18 15:40:04,249 - util.py[DEBUG]: Reading from /etc/cloud/cloud.cfg (quiet=False)
2019-05-18 15:40:04,249 - util.py[DEBUG]: Read 3169 bytes from /etc/cloud/cloud.cfg
2019-05-18 15:40:04,249 - util.py[DEBUG]: Attempting to load yaml from string of length 3169 with allowed root types (<class 'dict'>,)
2019-05-18 15:40:04,259 - util.py[DEBUG]: Reading from /etc/cloud/cloud.cfg.d/90_dpkg.cfg (quiet=False)
2019-05-18 15:40:04,259 - util.py[DEBUG]: Read 238 bytes from /etc/cloud/cloud.cfg.d/90_dpkg.cfg
2019-05-18 15:40:04,259 - util.py[DEBUG]: Attempting to load yaml from string of length 238 with allowed root types (<class 'dict'>,)
2019-05-18 15:40:04,260 - util.py[DEBUG]: Reading from /etc/cloud/cloud.cfg.d/05_logging.cfg (quiet=False)
2019-05-18 15:40:04,261 - util.py[DEBUG]: Read 2057 bytes from /etc/cloud/cloud.cfg.d/05_logging.cfg
2019-05-18 15:40:04,261 - util.py[DEBUG]: Attempting to load yaml from string of length 2057 with allowed root types (<class 'dict'>,)
2019-05-18 15:40:04,264 - util.py[DEBUG]: Reading from /run/cloud-init/cloud.cfg (quiet=False)
2019-05-18 15:40:04,264 - util.py[DEBUG]: Read 44 bytes from /run/cloud-init/cloud.cfg
2019-05-18 15:40:04,264 - util.py[DEBUG]: Attempting to load yaml from string of length 44 with allowed root types (<class 'dict'>,)
2019-05-18 15:40:04,264 - util.py[DEBUG]: Attempting to load yaml from string of length 0 with allowed root types (<class 'dict'>,)
2019-05-18 15:40:04,265 - util.py[DEBUG]: loaded blob returned None, returning default.
2019-05-18 15:40:04,265 - util.py[DEBUG]: Reading from /sys/class/net/ens3/address (quiet=False)
2019-05-18 15:40:04,266 - util.py[DEBUG]: Read 18 bytes from /sys/class/net/ens3/address
2019-05-18 15:40:04,266 - stages.py[DEBUG]: applying net config names for {'config': [{'type': 'physical', 'name': 'ens3', 'subnets': [{'type': 'dhcp4'}], 'mac_address': '06:a9:b1:ee:c4:26'}], 'version': 1}
2019-05-18 15:40:04,266 - stages.py[DEBUG]: Using distro class <class 'cloudinit.distros.ubuntu.Distro'>
2019-05-18 15:40:04,266 - util.py[DEBUG]: Reading from /sys/class/net/ens3/device/device (quiet=False)
2019-05-18 15:40:04,267 - util.py[DEBUG]: Read 7 bytes from /sys/class/net/ens3/device/device
2019-05-18 15:40:04,267 - util.py[DEBUG]: Reading from /sys/class/net/lo/addr_assign_type (quiet=False)
2019-05-18 15:40:04,267 - util.py[DEBUG]: Read 2 bytes from /sys/class/net/lo/addr_assign_type
2019-05-18 15:40:04,267 - util.py[DEBUG]: Reading from /sys/class/net/lo/uevent (quiet=False)
2019-05-18 15:40:04,267 - util.py[DEBUG]: Read 23 bytes from /sys/class/net/lo/uevent
2019-05-18 15:40:04,267 - util.py[DEBUG]: Reading from /sys/class/net/lo/address (quiet=False)
2019-05-18 15:40:04,267 - util.py[DEBUG]: Read 18 bytes from /sys/class/net/lo/address
2019-05-18 15:40:04,267 - util.py[DEBUG]: Reading from /sys/class/net/lo/device/device (quiet=False)
2019-05-18 15:40:04,267 - util.py[DEBUG]: Reading from /sys/class/net/ens3/addr_assign_type (quiet=False)
2019-05-18 15:40:04,267 - util.py[DEBUG]: Read 2 bytes from /sys/class/net/ens3/addr_assign_type
2019-05-18 15:40:04,267 - util.py[DEBUG]: Reading from /sys/class/net/ens3/uevent (quiet=False)
2019-05-18 15:40:04,267 - util.py[DEBUG]: Read 25 bytes from /sys/class/net/ens3/uevent
2019-05-18 15:40:04,267 - util.py[DEBUG]: Reading from /sys/class/net/ens3/address (quiet=False)
2019-05-18 15:40:04,267 - util.py[DEBUG]: Read 18 bytes from /sys/class/net/ens3/address
2019-05-18 15:40:04,267 - util.py[DEBUG]: Reading from /sys/class/net/ens3/device/device (quiet=False)
2019-05-18 15:40:04,267 - util.py[DEBUG]: Read 7 bytes from /sys/class/net/ens3/device/device
2019-05-18 15:40:04,267 - util.py[DEBUG]: Reading from /sys/class/net/lo/operstate (quiet=False)
2019-05-18 15:40:04,268 - util.py[DEBUG]: Read 8 bytes from /sys/class/net/lo/operstate
2019-05-18 15:40:04,268 - util.py[DEBUG]: Reading from /sys/class/net/ens3/operstate (quiet=False)
2019-05-18 15:40:04,268 - util.py[DEBUG]: Read 3 bytes from /sys/class/net/ens3/operstate
2019-05-18 15:40:04,268 - util.py[DEBUG]: Running command ['ip', '-6', 'addr', 'show', 'permanent', 'scope', 'global'] with allowed return codes [0] (shell=False, capture=True)
2019-05-18 15:40:04,270 - util.py[DEBUG]: Running command ['ip', '-4', 'addr', 'show'] with allowed return codes [0] (shell=False, capture=True)
2019-05-18 15:40:04,271 - __init__.py[DEBUG]: no work necessary for renaming of [['06:a9:b1:ee:c4:26', 'ens3', 'ixgbevf', '0x10ed']]
2019-05-18 15:40:04,272 - stages.py[DEBUG]: No network config applied. Neither a new instance nor datasource network update on 'System boot' event
2019-05-18 15:40:04,272 - handlers.py[DEBUG]: start: init-network/setup-datasource: setting up datasource
2019-05-18 15:40:04,272 - handlers.py[DEBUG]: finish: init-network/setup-datasource: SUCCESS: setting up datasource
2019-05-18 15:40:04,272 - util.py[DEBUG]: Writing to /var/lib/cloud/instances/i-0ca59a4b9f642f204/user-data.txt - wb: [600] 0 bytes
2019-05-18 15:40:04,274 - util.py[DEBUG]: Writing to /var/lib/cloud/instances/i-0ca59a4b9f642f204/user-data.txt.i - wb: [600] 308 bytes
2019-05-18 15:40:04,275 - util.py[DEBUG]: Writing to /var/lib/cloud/instances/i-0ca59a4b9f642f204/vendor-data.txt - wb: [600] 0 bytes
2019-05-18 15:40:04,276 - util.py[DEBUG]: Writing to /var/lib/cloud/instances/i-0ca59a4b9f642f204/vendor-data.txt.i - wb: [600] 308 bytes
2019-05-18 15:40:04,277 - util.py[DEBUG]: Reading from /var/lib/cloud/data/set-hostname (quiet=False)
2019-05-18 15:40:04,277 - util.py[DEBUG]: Read 86 bytes from /var/lib/cloud/data/set-hostname
2019-05-18 15:40:04,277 - cc_set_hostname.py[DEBUG]: No hostname changes. Skipping set-hostname
2019-05-18 15:40:04,277 - util.py[DEBUG]: Writing to /var/lib/cloud/instances/i-0ca59a4b9f642f204/sem/consume_data - wb: [644] 25 bytes
2019-05-18 15:40:04,277 - helpers.py[DEBUG]: Running consume_data using lock (<FileLock using file '/var/lib/cloud/instances/i-0ca59a4b9f642f204/sem/consume_data'>)
2019-05-18 15:40:04,277 - handlers.py[DEBUG]: start: init-network/consume-user-data: reading and applying user-data
2019-05-18 15:40:04,278 - launch_index.py[DEBUG]: Discarding 0 multipart messages which do not match launch index 0
2019-05-18 15:40:04,278 - stages.py[DEBUG]: Added default handler for {'text/cloud-config-jsonp', 'text/cloud-config'} from CloudConfigPartHandler: [['text/cloud-config', 'text/cloud-config-jsonp']]
2019-05-18 15:40:04,278 - stages.py[DEBUG]: Added default handler for {'text/x-shellscript'} from ShellScriptPartHandler: [['text/x-shellscript']]
2019-05-18 15:40:04,278 - stages.py[DEBUG]: Added default handler for {'text/cloud-boothook'} from BootHookPartHandler: [['text/cloud-boothook']]
2019-05-18 15:40:04,278 - stages.py[DEBUG]: Added default handler for {'text/upstart-job'} from UpstartJobPartHandler: [['text/upstart-job']]
2019-05-18 15:40:04,278 - __init__.py[DEBUG]: Calling handler ShellScriptPartHandler: [['text/x-shellscript']] (__begin__, None, 2) with frequency once-per-instance
2019-05-18 15:40:04,278 - __init__.py[DEBUG]: Calling handler BootHookPartHandler: [['text/cloud-boothook']] (__begin__, None, 2) with frequency once-per-instance
2019-05-18 15:40:04,278 - __init__.py[DEBUG]: Calling handler CloudConfigPartHandler: [['text/cloud-config', 'text/cloud-config-jsonp']] (__begin__, None, 3) with frequency once-per-instance
2019-05-18 15:40:04,278 - __init__.py[DEBUG]: Calling handler UpstartJobPartHandler: [['text/upstart-job']] (__begin__, None, 2) with frequency once-per-instance
2019-05-18 15:40:04,279 - __init__.py[DEBUG]: {'MIME-Version': '1.0', 'Content-Disposition': 'attachment; filename="part-001"', 'Content-Type': 'text/x-not-multipart'}
2019-05-18 15:40:04,279 - __init__.py[DEBUG]: Empty payload of type text/x-not-multipart
2019-05-18 15:40:04,279 - __init__.py[DEBUG]: Calling handler ShellScriptPartHandler: [['text/x-shellscript']] (__end__, None, 2) with frequency once-per-instance
2019-05-18 15:40:04,279 - __init__.py[DEBUG]: Calling handler BootHookPartHandler: [['text/cloud-boothook']] (__end__, None, 2) with frequency once-per-instance
2019-05-18 15:40:04,279 - __init__.py[DEBUG]: Calling handler CloudConfigPartHandler: [['text/cloud-config', 'text/cloud-config-jsonp']] (__end__, None, 3) with frequency once-per-instance
2019-05-18 15:40:04,279 - util.py[DEBUG]: Writing to /var/lib/cloud/instances/i-0ca59a4b9f642f204/cloud-config.txt - wb: [600] 0 bytes
2019-05-18 15:40:04,279 - __init__.py[DEBUG]: Calling handler UpstartJobPartHandler: [['text/upstart-job']] (__end__, None, 2) with frequency once-per-instance
2019-05-18 15:40:04,279 - handlers.py[DEBUG]: finish: init-network/consume-user-data: SUCCESS: reading and applying user-data
2019-05-18 15:40:04,279 - handlers.py[DEBUG]: start: init-network/consume-vendor-data: reading and applying vendor-data
2019-05-18 15:40:04,279 - stages.py[DEBUG]: no vendordata from datasource
2019-05-18 15:40:04,280 - handlers.py[DEBUG]: finish: init-network/consume-vendor-data: SUCCESS: reading and applying vendor-data
2019-05-18 15:40:04,280 - util.py[DEBUG]: Reading from /etc/cloud/cloud.cfg (quiet=False)
2019-05-18 15:40:04,280 - util.py[DEBUG]: Read 3169 bytes from /etc/cloud/cloud.cfg
2019-05-18 15:40:04,280 - util.py[DEBUG]: Attempting to load yaml from string of length 3169 with allowed root types (<class 'dict'>,)
2019-05-18 15:40:04,290 - util.py[DEBUG]: Reading from /etc/cloud/cloud.cfg.d/90_dpkg.cfg (quiet=False)
2019-05-18 15:40:04,290 - util.py[DEBUG]: Read 238 bytes from /etc/cloud/cloud.cfg.d/90_dpkg.cfg
2019-05-18 15:40:04,290 - util.py[DEBUG]: Attempting to load yaml from string of length 238 with allowed root types (<class 'dict'>,)
2019-05-18 15:40:04,291 - util.py[DEBUG]: Reading from /etc/cloud/cloud.cfg.d/05_logging.cfg (quiet=False)
2019-05-18 15:40:04,292 - util.py[DEBUG]: Read 2057 bytes from /etc/cloud/cloud.cfg.d/05_logging.cfg
2019-05-18 15:40:04,292 - util.py[DEBUG]: Attempting to load yaml from string of length 2057 with allowed root types (<class 'dict'>,)
2019-05-18 15:40:04,295 - util.py[DEBUG]: Reading from /run/cloud-init/cloud.cfg (quiet=False)
2019-05-18 15:40:04,295 - util.py[DEBUG]: Read 44 bytes from /run/cloud-init/cloud.cfg
2019-05-18 15:40:04,295 - util.py[DEBUG]: Attempting to load yaml from string of length 44 with allowed root types (<class 'dict'>,)
2019-05-18 15:40:04,296 - util.py[DEBUG]: Attempting to load yaml from string of length 0 with allowed root types (<class 'dict'>,)
2019-05-18 15:40:04,296 - util.py[DEBUG]: loaded blob returned None, returning default.
2019-05-18 15:40:04,296 - util.py[DEBUG]: Reading from /var/lib/cloud/instance/cloud-config.txt (quiet=False)
2019-05-18 15:40:04,296 - util.py[DEBUG]: Read 0 bytes from /var/lib/cloud/instance/cloud-config.txt
2019-05-18 15:40:04,296 - util.py[DEBUG]: Attempting to load yaml from string of length 0 with allowed root types (<class 'dict'>,)
2019-05-18 15:40:04,296 - util.py[DEBUG]: loaded blob returned None, returning default.
2019-05-18 15:40:04,297 - util.py[DEBUG]: Reading from /var/lib/cloud/instance/cloud-config.txt (quiet=False)
2019-05-18 15:40:04,297 - util.py[DEBUG]: Read 0 bytes from /var/lib/cloud/instance/cloud-config.txt
2019-05-18 15:40:04,297 - util.py[DEBUG]: Attempting to load yaml from string of length 0 with allowed root types (<class 'dict'>,)
2019-05-18 15:40:04,297 - util.py[DEBUG]: loaded blob returned None, returning default.
2019-05-18 15:40:04,298 - handlers.py[DEBUG]: start: init-network/activate-datasource: activating datasource
2019-05-18 15:40:04,299 - util.py[DEBUG]: Writing to /var/lib/cloud/instance/obj.pkl - wb: [400] 8486 bytes
2019-05-18 15:40:04,299 - handlers.py[DEBUG]: finish: init-network/activate-datasource: SUCCESS: activating datasource
2019-05-18 15:40:04,299 - main.py[DEBUG]: used datasource 'DataSourceEc2Local' from 'Ec2' was in di_report's list: ['Ec2', 'None']
2019-05-18 15:40:04,354 - stages.py[DEBUG]: Using distro class <class 'cloudinit.distros.ubuntu.Distro'>
2019-05-18 15:40:04,354 - stages.py[DEBUG]: Running module migrator (<module 'cloudinit.config.cc_migrator' from '/usr/lib/python3/dist-packages/cloudinit/config/cc_migrator.py'>) with frequency always
2019-05-18 15:40:04,354 - handlers.py[DEBUG]: start: init-network/config-migrator: running config-migrator with frequency always
2019-05-18 15:40:04,354 - helpers.py[DEBUG]: Running config-migrator using lock (<cloudinit.helpers.DummyLock object at 0x7f54bd1ba0b8>)
2019-05-18 15:40:04,354 - cc_migrator.py[DEBUG]: Migrated 0 semaphore files to there canonicalized names
2019-05-18 15:40:04,355 - handlers.py[DEBUG]: finish: init-network/config-migrator: SUCCESS: config-migrator ran successfully
2019-05-18 15:40:04,355 - stages.py[DEBUG]: Running module seed_random (<module 'cloudinit.config.cc_seed_random' from '/usr/lib/python3/dist-packages/cloudinit/config/cc_seed_random.py'>) with frequency once-per-instance
2019-05-18 15:40:04,355 - handlers.py[DEBUG]: start: init-network/config-seed_random: running config-seed_random with frequency once-per-instance
2019-05-18 15:40:04,355 - util.py[DEBUG]: Writing to /var/lib/cloud/instances/i-0ca59a4b9f642f204/sem/config_seed_random - wb: [644] 25 bytes
2019-05-18 15:40:04,356 - helpers.py[DEBUG]: Running config-seed_random using lock (<FileLock using file '/var/lib/cloud/instances/i-0ca59a4b9f642f204/sem/config_seed_random'>)
2019-05-18 15:40:04,356 - cc_seed_random.py[DEBUG]: no command provided
2019-05-18 15:40:04,356 - handlers.py[DEBUG]: finish: init-network/config-seed_random: SUCCESS: config-seed_random ran successfully
2019-05-18 15:40:04,356 - stages.py[DEBUG]: Running module bootcmd (<module 'cloudinit.config.cc_bootcmd' from '/usr/lib/python3/dist-packages/cloudinit/config/cc_bootcmd.py'>) with frequency always
2019-05-18 15:40:04,356 - handlers.py[DEBUG]: start: init-network/config-bootcmd: running config-bootcmd with frequency always
2019-05-18 15:40:04,356 - helpers.py[DEBUG]: Running config-bootcmd using lock (<cloudinit.helpers.DummyLock object at 0x7f54bd1c4ba8>)
2019-05-18 15:40:04,356 - cc_bootcmd.py[DEBUG]: Skipping module named bootcmd, no 'bootcmd' key in configuration
2019-05-18 15:40:04,356 - handlers.py[DEBUG]: finish: init-network/config-bootcmd: SUCCESS: config-bootcmd ran successfully
2019-05-18 15:40:04,356 - stages.py[DEBUG]: Running module write-files (<module 'cloudinit.config.cc_write_files' from '/usr/lib/python3/dist-packages/cloudinit/config/cc_write_files.py'>) with frequency once-per-instance
2019-05-18 15:40:04,356 - handlers.py[DEBUG]: start: init-network/config-write-files: running config-write-files with frequency once-per-instance
2019-05-18 15:40:04,357 - util.py[DEBUG]: Writing to /var/lib/cloud/instances/i-0ca59a4b9f642f204/sem/config_write_files - wb: [644] 24 bytes
2019-05-18 15:40:04,357 - helpers.py[DEBUG]: Running config-write-files using lock (<FileLock using file '/var/lib/cloud/instances/i-0ca59a4b9f642f204/sem/config_write_files'>)
2019-05-18 15:40:04,357 - cc_write_files.py[DEBUG]: Skipping module named write-files, no/empty 'write_files' key in configuration
2019-05-18 15:40:04,357 - handlers.py[DEBUG]: finish: init-network/config-write-files: SUCCESS: config-write-files ran successfully
2019-05-18 15:40:04,357 - stages.py[DEBUG]: Running module growpart (<module 'cloudinit.config.cc_growpart' from '/usr/lib/python3/dist-packages/cloudinit/config/cc_growpart.py'>) with frequency always
2019-05-18 15:40:04,357 - handlers.py[DEBUG]: start: init-network/config-growpart: running config-growpart with frequency always
2019-05-18 15:40:04,357 - helpers.py[DEBUG]: Running config-growpart using lock (<cloudinit.helpers.DummyLock object at 0x7f54bd1c4160>)
2019-05-18 15:40:04,357 - cc_growpart.py[DEBUG]: No 'growpart' entry in cfg.  Using default: {'devices': ['/'], 'mode': 'auto', 'ignore_growroot_disabled': False}
2019-05-18 15:40:04,358 - util.py[DEBUG]: Running command ['growpart', '--help'] with allowed return codes [0] (shell=False, capture=True)
2019-05-18 15:40:04,361 - util.py[DEBUG]: Reading from /proc/1327/mountinfo (quiet=False)
2019-05-18 15:40:04,361 - util.py[DEBUG]: Read 2627 bytes from /proc/1327/mountinfo
2019-05-18 15:40:04,361 - util.py[DEBUG]: Running command ['systemd-detect-virt', '--quiet', '--container'] with allowed return codes [0] (shell=False, capture=True)
2019-05-18 15:40:04,363 - util.py[DEBUG]: Running command ['running-in-container'] with allowed return codes [0] (shell=False, capture=True)
2019-05-18 15:40:04,365 - util.py[DEBUG]: Running command ['lxc-is-container'] with allowed return codes [0] (shell=False, capture=True)
2019-05-18 15:40:04,366 - util.py[DEBUG]: Reading from /proc/1/environ (quiet=False)
2019-05-18 15:40:04,366 - util.py[DEBUG]: Read 150 bytes from /proc/1/environ
2019-05-18 15:40:04,367 - util.py[DEBUG]: Reading from /proc/self/status (quiet=False)
2019-05-18 15:40:04,367 - util.py[DEBUG]: Read 971 bytes from /proc/self/status
2019-05-18 15:40:04,369 - util.py[DEBUG]: Reading from /etc/os-release (quiet=False)
2019-05-18 15:40:04,369 - util.py[DEBUG]: Read 298 bytes from /etc/os-release
2019-05-18 15:40:04,370 - util.py[DEBUG]: Reading from /sys/class/block/xvda1/partition (quiet=False)
2019-05-18 15:40:04,370 - util.py[DEBUG]: Read 2 bytes from /sys/class/block/xvda1/partition
2019-05-18 15:40:04,370 - util.py[DEBUG]: Reading from /sys/devices/vbd-768/block/xvda/dev (quiet=False)
2019-05-18 15:40:04,370 - util.py[DEBUG]: Read 6 bytes from /sys/devices/vbd-768/block/xvda/dev
2019-05-18 15:40:04,370 - util.py[DEBUG]: Running command ['growpart', '--dry-run', '/dev/xvda', '1'] with allowed return codes [0] (shell=False, capture=True)
2019-05-18 15:40:04,404 - util.py[DEBUG]: Running command ['growpart', '/dev/xvda', '1'] with allowed return codes [0] (shell=False, capture=True)
2019-05-18 15:40:04,452 - util.py[DEBUG]: resize_devices took 0.091 seconds
2019-05-18 15:40:04,452 - cc_growpart.py[INFO]: '/' resized: changed (/dev/xvda, 1) from 8588869120 to 32211189248
2019-05-18 15:40:04,452 - handlers.py[DEBUG]: finish: init-network/config-growpart: SUCCESS: config-growpart ran successfully
2019-05-18 15:40:04,452 - stages.py[DEBUG]: Running module resizefs (<module 'cloudinit.config.cc_resizefs' from '/usr/lib/python3/dist-packages/cloudinit/config/cc_resizefs.py'>) with frequency always
2019-05-18 15:40:04,453 - handlers.py[DEBUG]: start: init-network/config-resizefs: running config-resizefs with frequency always
2019-05-18 15:40:04,453 - helpers.py[DEBUG]: Running config-resizefs using lock (<cloudinit.helpers.DummyLock object at 0x7f54bd1c0e48>)
2019-05-18 15:40:04,453 - schema.py[DEBUG]: Ignoring schema validation. python-jsonschema is not present
2019-05-18 15:40:04,453 - util.py[DEBUG]: Reading from /proc/1327/mountinfo (quiet=False)
2019-05-18 15:40:04,453 - util.py[DEBUG]: Read 2627 bytes from /proc/1327/mountinfo
2019-05-18 15:40:04,453 - cc_resizefs.py[DEBUG]: resize_info: dev=/dev/xvda1 mnt_point=/ path=/
2019-05-18 15:40:04,453 - util.py[DEBUG]: Running command ['systemd-detect-virt', '--quiet', '--container'] with allowed return codes [0] (shell=False, capture=True)
2019-05-18 15:40:04,455 - util.py[DEBUG]: Running command ['running-in-container'] with allowed return codes [0] (shell=False, capture=True)
2019-05-18 15:40:04,456 - util.py[DEBUG]: Running command ['lxc-is-container'] with allowed return codes [0] (shell=False, capture=True)
2019-05-18 15:40:04,458 - util.py[DEBUG]: Reading from /proc/1/environ (quiet=False)
2019-05-18 15:40:04,458 - util.py[DEBUG]: Read 150 bytes from /proc/1/environ
2019-05-18 15:40:04,458 - util.py[DEBUG]: Reading from /proc/self/status (quiet=False)
2019-05-18 15:40:04,458 - util.py[DEBUG]: Read 972 bytes from /proc/self/status
2019-05-18 15:40:04,458 - cc_resizefs.py[DEBUG]: Resizing / (ext4) using resize2fs /dev/xvda1
2019-05-18 15:40:04,458 - util.py[DEBUG]: Running command ('resize2fs', '/dev/xvda1') with allowed return codes [0] (shell=False, capture=True)
2019-05-18 15:40:04,492 - util.py[DEBUG]: Resizing took 0.034 seconds
2019-05-18 15:40:04,492 - cc_resizefs.py[DEBUG]: Resized root filesystem (type=ext4, val=True)
2019-05-18 15:40:04,492 - handlers.py[DEBUG]: finish: init-network/config-resizefs: SUCCESS: config-resizefs ran successfully
2019-05-18 15:40:04,492 - stages.py[DEBUG]: Running module disk_setup (<module 'cloudinit.config.cc_disk_setup' from '/usr/lib/python3/dist-packages/cloudinit/config/cc_disk_setup.py'>) with frequency once-per-instance
2019-05-18 15:40:04,492 - handlers.py[DEBUG]: start: init-network/config-disk_setup: running config-disk_setup with frequency once-per-instance
2019-05-18 15:40:04,492 - util.py[DEBUG]: Writing to /var/lib/cloud/instances/i-0ca59a4b9f642f204/sem/config_disk_setup - wb: [644] 25 bytes
2019-05-18 15:40:04,493 - helpers.py[DEBUG]: Running config-disk_setup using lock (<FileLock using file '/var/lib/cloud/instances/i-0ca59a4b9f642f204/sem/config_disk_setup'>)
2019-05-18 15:40:04,493 - handlers.py[DEBUG]: finish: init-network/config-disk_setup: SUCCESS: config-disk_setup ran successfully
2019-05-18 15:40:04,493 - stages.py[DEBUG]: Running module mounts (<module 'cloudinit.config.cc_mounts' from '/usr/lib/python3/dist-packages/cloudinit/config/cc_mounts.py'>) with frequency once-per-instance
2019-05-18 15:40:04,493 - handlers.py[DEBUG]: start: init-network/config-mounts: running config-mounts with frequency once-per-instance
2019-05-18 15:40:04,494 - util.py[DEBUG]: Writing to /var/lib/cloud/instances/i-0ca59a4b9f642f204/sem/config_mounts - wb: [644] 25 bytes
2019-05-18 15:40:04,494 - helpers.py[DEBUG]: Running config-mounts using lock (<FileLock using file '/var/lib/cloud/instances/i-0ca59a4b9f642f204/sem/config_mounts'>)
2019-05-18 15:40:04,494 - cc_mounts.py[DEBUG]: mounts configuration is []
2019-05-18 15:40:04,494 - util.py[DEBUG]: Reading from /etc/fstab (quiet=False)
2019-05-18 15:40:04,494 - util.py[DEBUG]: Read 51 bytes from /etc/fstab
2019-05-18 15:40:04,494 - cc_mounts.py[DEBUG]: Attempting to determine the real name of ephemeral0
2019-05-18 15:40:04,495 - cc_mounts.py[DEBUG]: changed default device ephemeral0 => None
2019-05-18 15:40:04,495 - cc_mounts.py[DEBUG]: Ignoring nonexistent default named mount ephemeral0
2019-05-18 15:40:04,495 - cc_mounts.py[DEBUG]: Attempting to determine the real name of swap
2019-05-18 15:40:04,495 - DataSourceEc2.py[DEBUG]: Unable to convert swap to a device
2019-05-18 15:40:04,495 - cc_mounts.py[DEBUG]: changed default device swap => None
2019-05-18 15:40:04,495 - cc_mounts.py[DEBUG]: Ignoring nonexistent default named mount swap
2019-05-18 15:40:04,495 - cc_mounts.py[DEBUG]: no need to setup swap
2019-05-18 15:40:04,495 - cc_mounts.py[DEBUG]: No modifications to fstab needed
2019-05-18 15:40:04,495 - handlers.py[DEBUG]: finish: init-network/config-mounts: SUCCESS: config-mounts ran successfully
2019-05-18 15:40:04,495 - stages.py[DEBUG]: Running module set_hostname (<module 'cloudinit.config.cc_set_hostname' from '/usr/lib/python3/dist-packages/cloudinit/config/cc_set_hostname.py'>) with frequency once-per-instance
2019-05-18 15:40:04,495 - handlers.py[DEBUG]: start: init-network/config-set_hostname: running config-set_hostname with frequency once-per-instance
2019-05-18 15:40:04,495 - util.py[DEBUG]: Writing to /var/lib/cloud/instances/i-0ca59a4b9f642f204/sem/config_set_hostname - wb: [644] 24 bytes
2019-05-18 15:40:04,496 - helpers.py[DEBUG]: Running config-set_hostname using lock (<FileLock using file '/var/lib/cloud/instances/i-0ca59a4b9f642f204/sem/config_set_hostname'>)
2019-05-18 15:40:04,496 - util.py[DEBUG]: Reading from /var/lib/cloud/data/set-hostname (quiet=False)
2019-05-18 15:40:04,496 - util.py[DEBUG]: Read 86 bytes from /var/lib/cloud/data/set-hostname
2019-05-18 15:40:04,496 - cc_set_hostname.py[DEBUG]: No hostname changes. Skipping set-hostname
2019-05-18 15:40:04,496 - handlers.py[DEBUG]: finish: init-network/config-set_hostname: SUCCESS: config-set_hostname ran successfully
2019-05-18 15:40:04,496 - stages.py[DEBUG]: Running module update_hostname (<module 'cloudinit.config.cc_update_hostname' from '/usr/lib/python3/dist-packages/cloudinit/config/cc_update_hostname.py'>) with frequency always
2019-05-18 15:40:04,496 - handlers.py[DEBUG]: start: init-network/config-update_hostname: running config-update_hostname with frequency always
2019-05-18 15:40:04,496 - helpers.py[DEBUG]: Running config-update_hostname using lock (<cloudinit.helpers.DummyLock object at 0x7f54bd1c0e10>)
2019-05-18 15:40:04,496 - cc_update_hostname.py[DEBUG]: Updating hostname to ip-10-0-0-175.eu-west-1.compute.internal (ip-10-0-0-175)
2019-05-18 15:40:04,496 - util.py[DEBUG]: Reading from /etc/hostname (quiet=False)
2019-05-18 15:40:04,497 - util.py[DEBUG]: Read 14 bytes from /etc/hostname
2019-05-18 15:40:04,497 - __init__.py[DEBUG]: Attempting to update hostname to ip-10-0-0-175 in 1 files
2019-05-18 15:40:04,497 - util.py[DEBUG]: Reading from /var/lib/cloud/data/previous-hostname (quiet=False)
2019-05-18 15:40:04,497 - util.py[DEBUG]: Writing to /var/lib/cloud/data/previous-hostname - wb: [644] 14 bytes
2019-05-18 15:40:04,497 - handlers.py[DEBUG]: finish: init-network/config-update_hostname: SUCCESS: config-update_hostname ran successfully
2019-05-18 15:40:04,497 - stages.py[DEBUG]: Running module update_etc_hosts (<module 'cloudinit.config.cc_update_etc_hosts' from '/usr/lib/python3/dist-packages/cloudinit/config/cc_update_etc_hosts.py'>) with frequency always
2019-05-18 15:40:04,497 - handlers.py[DEBUG]: start: init-network/config-update_etc_hosts: running config-update_etc_hosts with frequency always
2019-05-18 15:40:04,498 - helpers.py[DEBUG]: Running config-update_etc_hosts using lock (<cloudinit.helpers.DummyLock object at 0x7f54bd1c44a8>)
2019-05-18 15:40:04,498 - cc_update_etc_hosts.py[DEBUG]: Configuration option 'manage_etc_hosts' is not set, not managing /etc/hosts in module update_etc_hosts
2019-05-18 15:40:04,498 - handlers.py[DEBUG]: finish: init-network/config-update_etc_hosts: SUCCESS: config-update_etc_hosts ran successfully
2019-05-18 15:40:04,498 - stages.py[DEBUG]: Running module ca-certs (<module 'cloudinit.config.cc_ca_certs' from '/usr/lib/python3/dist-packages/cloudinit/config/cc_ca_certs.py'>) with frequency once-per-instance
2019-05-18 15:40:04,498 - handlers.py[DEBUG]: start: init-network/config-ca-certs: running config-ca-certs with frequency once-per-instance
2019-05-18 15:40:04,498 - util.py[DEBUG]: Writing to /var/lib/cloud/instances/i-0ca59a4b9f642f204/sem/config_ca_certs - wb: [644] 25 bytes
2019-05-18 15:40:04,498 - helpers.py[DEBUG]: Running config-ca-certs using lock (<FileLock using file '/var/lib/cloud/instances/i-0ca59a4b9f642f204/sem/config_ca_certs'>)
2019-05-18 15:40:04,498 - cc_ca_certs.py[DEBUG]: Skipping module named ca-certs, no 'ca-certs' key in configuration
2019-05-18 15:40:04,498 - handlers.py[DEBUG]: finish: init-network/config-ca-certs: SUCCESS: config-ca-certs ran successfully
2019-05-18 15:40:04,498 - stages.py[DEBUG]: Running module rsyslog (<module 'cloudinit.config.cc_rsyslog' from '/usr/lib/python3/dist-packages/cloudinit/config/cc_rsyslog.py'>) with frequency once-per-instance
2019-05-18 15:40:04,499 - handlers.py[DEBUG]: start: init-network/config-rsyslog: running config-rsyslog with frequency once-per-instance
2019-05-18 15:40:04,499 - util.py[DEBUG]: Writing to /var/lib/cloud/instances/i-0ca59a4b9f642f204/sem/config_rsyslog - wb: [644] 25 bytes
2019-05-18 15:40:04,499 - helpers.py[DEBUG]: Running config-rsyslog using lock (<FileLock using file '/var/lib/cloud/instances/i-0ca59a4b9f642f204/sem/config_rsyslog'>)
2019-05-18 15:40:04,499 - cc_rsyslog.py[DEBUG]: Skipping module named rsyslog, no 'rsyslog' key in configuration
2019-05-18 15:40:04,499 - handlers.py[DEBUG]: finish: init-network/config-rsyslog: SUCCESS: config-rsyslog ran successfully
2019-05-18 15:40:04,499 - stages.py[DEBUG]: Running module users-groups (<module 'cloudinit.config.cc_users_groups' from '/usr/lib/python3/dist-packages/cloudinit/config/cc_users_groups.py'>) with frequency once-per-instance
2019-05-18 15:40:04,499 - handlers.py[DEBUG]: start: init-network/config-users-groups: running config-users-groups with frequency once-per-instance
2019-05-18 15:40:04,500 - util.py[DEBUG]: Writing to /var/lib/cloud/instances/i-0ca59a4b9f642f204/sem/config_users_groups - wb: [644] 25 bytes
2019-05-18 15:40:04,500 - helpers.py[DEBUG]: Running config-users-groups using lock (<FileLock using file '/var/lib/cloud/instances/i-0ca59a4b9f642f204/sem/config_users_groups'>)
2019-05-18 15:40:04,500 - util.py[DEBUG]: Reading from /etc/os-release (quiet=True)
2019-05-18 15:40:04,500 - util.py[DEBUG]: Read 298 bytes from /etc/os-release
2019-05-18 15:40:04,501 - util.py[DEBUG]: Reading from /etc/system-image/channel.ini (quiet=True)
2019-05-18 15:40:04,501 - util.py[DEBUG]: Read 0 bytes from /etc/system-image/channel.ini
2019-05-18 15:40:04,501 - __init__.py[DEBUG]: Adding user ubuntu
2019-05-18 15:40:04,501 - util.py[DEBUG]: Running hidden command to protect sensitive input/output logstring: ['useradd', 'ubuntu', '--comment', 'Ubuntu', '--groups', 'adm,audio,cdrom,dialout,dip,floppy,lxd,netdev,plugdev,sudo,video', '--shell', '/bin/bash', '-m']
2019-05-18 15:40:04,552 - util.py[DEBUG]: Running command ['passwd', '-l', 'ubuntu'] with allowed return codes [0] (shell=False, capture=True)
2019-05-18 15:40:04,577 - util.py[DEBUG]: Reading from /etc/sudoers (quiet=False)
2019-05-18 15:40:04,577 - util.py[DEBUG]: Read 755 bytes from /etc/sudoers
2019-05-18 15:40:04,578 - util.py[DEBUG]: Writing to /etc/sudoers.d/90-cloud-init-users - wb: [440] 151 bytes
2019-05-18 15:40:04,579 - handlers.py[DEBUG]: finish: init-network/config-users-groups: SUCCESS: config-users-groups ran successfully
2019-05-18 15:40:04,579 - stages.py[DEBUG]: Running module ssh (<module 'cloudinit.config.cc_ssh' from '/usr/lib/python3/dist-packages/cloudinit/config/cc_ssh.py'>) with frequency once-per-instance
2019-05-18 15:40:04,579 - handlers.py[DEBUG]: start: init-network/config-ssh: running config-ssh with frequency once-per-instance
2019-05-18 15:40:04,579 - util.py[DEBUG]: Writing to /var/lib/cloud/instances/i-0ca59a4b9f642f204/sem/config_ssh - wb: [644] 25 bytes
2019-05-18 15:40:04,580 - helpers.py[DEBUG]: Running config-ssh using lock (<FileLock using file '/var/lib/cloud/instances/i-0ca59a4b9f642f204/sem/config_ssh'>)
2019-05-18 15:40:04,580 - util.py[DEBUG]: Running command ['ssh-keygen', '-t', 'rsa', '-N', '', '-f', '/etc/ssh/ssh_host_rsa_key'] with allowed return codes [0] (shell=False, capture=True)
2019-05-18 15:40:04,898 - util.py[DEBUG]: Running command ['ssh-keygen', '-t', 'dsa', '-N', '', '-f', '/etc/ssh/ssh_host_dsa_key'] with allowed return codes [0] (shell=False, capture=True)
2019-05-18 15:40:05,021 - util.py[DEBUG]: Running command ['ssh-keygen', '-t', 'ecdsa', '-N', '', '-f', '/etc/ssh/ssh_host_ecdsa_key'] with allowed return codes [0] (shell=False, capture=True)
2019-05-18 15:40:05,024 - util.py[DEBUG]: Running command ['ssh-keygen', '-t', 'ed25519', '-N', '', '-f', '/etc/ssh/ssh_host_ed25519_key'] with allowed return codes [0] (shell=False, capture=True)
2019-05-18 15:40:05,029 - util.py[DEBUG]: Changing the ownership of /home/ubuntu/.ssh to 1000:1000
2019-05-18 15:40:05,029 - util.py[DEBUG]: Reading from /etc/ssh/sshd_config (quiet=False)
2019-05-18 15:40:05,030 - util.py[DEBUG]: Read 2540 bytes from /etc/ssh/sshd_config
2019-05-18 15:40:05,030 - util.py[DEBUG]: Writing to /home/ubuntu/.ssh/authorized_keys - wb: [600] 448 bytes
2019-05-18 15:40:05,031 - util.py[DEBUG]: Changing the ownership of /home/ubuntu/.ssh/authorized_keys to 1000:1000
2019-05-18 15:40:05,031 - util.py[DEBUG]: Changing the ownership of /root/.ssh to 0:0
2019-05-18 15:40:05,031 - util.py[DEBUG]: Reading from /etc/ssh/sshd_config (quiet=False)
2019-05-18 15:40:05,032 - util.py[DEBUG]: Read 2540 bytes from /etc/ssh/sshd_config
2019-05-18 15:40:05,032 - util.py[DEBUG]: Writing to /root/.ssh/authorized_keys - wb: [600] 603 bytes
2019-05-18 15:40:05,032 - util.py[DEBUG]: Changing the ownership of /root/.ssh/authorized_keys to 0:0
2019-05-18 15:40:05,032 - handlers.py[DEBUG]: finish: init-network/config-ssh: SUCCESS: config-ssh ran successfully
2019-05-18 15:40:05,033 - main.py[DEBUG]: Ran 15 modules with 0 failures
2019-05-18 15:40:05,033 - util.py[DEBUG]: Reading from /proc/uptime (quiet=False)
2019-05-18 15:40:05,033 - util.py[DEBUG]: Read 12 bytes from /proc/uptime
2019-05-18 15:40:05,033 - util.py[DEBUG]: cloud-init mode 'init' took 0.845 seconds (0.85)
2019-05-18 15:40:05,033 - handlers.py[DEBUG]: finish: init-network: SUCCESS: searching for network datasources
2019-05-18 15:40:11,165 - util.py[DEBUG]: Cloud-init v. 18.3-9-g2e62cb8a-0ubuntu1~16.04.2 running 'modules:config' at Sat, 18 May 2019 15:40:11 +0000. Up 14.41 seconds.
2019-05-18 15:40:11,206 - stages.py[DEBUG]: Using distro class <class 'cloudinit.distros.ubuntu.Distro'>
2019-05-18 15:40:11,207 - stages.py[DEBUG]: Running module emit_upstart (<module 'cloudinit.config.cc_emit_upstart' from '/usr/lib/python3/dist-packages/cloudinit/config/cc_emit_upstart.py'>) with frequency always
2019-05-18 15:40:11,207 - handlers.py[DEBUG]: start: modules-config/config-emit_upstart: running config-emit_upstart with frequency always
2019-05-18 15:40:11,207 - helpers.py[DEBUG]: Running config-emit_upstart using lock (<cloudinit.helpers.DummyLock object at 0x7f03998bde80>)
2019-05-18 15:40:11,207 - cc_emit_upstart.py[DEBUG]: no /sbin/initctl located
2019-05-18 15:40:11,207 - cc_emit_upstart.py[DEBUG]: not upstart system, 'emit_upstart' disabled
2019-05-18 15:40:11,208 - handlers.py[DEBUG]: finish: modules-config/config-emit_upstart: SUCCESS: config-emit_upstart ran successfully
2019-05-18 15:40:11,208 - stages.py[DEBUG]: Running module snap (<module 'cloudinit.config.cc_snap' from '/usr/lib/python3/dist-packages/cloudinit/config/cc_snap.py'>) with frequency once-per-instance
2019-05-18 15:40:11,208 - handlers.py[DEBUG]: start: modules-config/config-snap: running config-snap with frequency once-per-instance
2019-05-18 15:40:11,208 - util.py[DEBUG]: Writing to /var/lib/cloud/instances/i-0ca59a4b9f642f204/sem/config_snap - wb: [644] 25 bytes
2019-05-18 15:40:11,208 - helpers.py[DEBUG]: Running config-snap using lock (<FileLock using file '/var/lib/cloud/instances/i-0ca59a4b9f642f204/sem/config_snap'>)
2019-05-18 15:40:11,208 - cc_snap.py[DEBUG]: Skipping module named snap, no 'snap' key in configuration
2019-05-18 15:40:11,209 - handlers.py[DEBUG]: finish: modules-config/config-snap: SUCCESS: config-snap ran successfully
2019-05-18 15:40:11,209 - stages.py[DEBUG]: Running module snap_config (<module 'cloudinit.config.cc_snap_config' from '/usr/lib/python3/dist-packages/cloudinit/config/cc_snap_config.py'>) with frequency once-per-instance
2019-05-18 15:40:11,209 - handlers.py[DEBUG]: start: modules-config/config-snap_config: running config-snap_config with frequency once-per-instance
2019-05-18 15:40:11,209 - util.py[DEBUG]: Writing to /var/lib/cloud/instances/i-0ca59a4b9f642f204/sem/config_snap_config - wb: [644] 24 bytes
2019-05-18 15:40:11,209 - helpers.py[DEBUG]: Running config-snap_config using lock (<FileLock using file '/var/lib/cloud/instances/i-0ca59a4b9f642f204/sem/config_snap_config'>)
2019-05-18 15:40:11,209 - cc_snap_config.py[DEBUG]: No snappy config provided, skipping
2019-05-18 15:40:11,209 - handlers.py[DEBUG]: finish: modules-config/config-snap_config: SUCCESS: config-snap_config ran successfully
2019-05-18 15:40:11,209 - stages.py[DEBUG]: Running module ssh-import-id (<module 'cloudinit.config.cc_ssh_import_id' from '/usr/lib/python3/dist-packages/cloudinit/config/cc_ssh_import_id.py'>) with frequency once-per-instance
2019-05-18 15:40:11,210 - handlers.py[DEBUG]: start: modules-config/config-ssh-import-id: running config-ssh-import-id with frequency once-per-instance
2019-05-18 15:40:11,210 - util.py[DEBUG]: Writing to /var/lib/cloud/instances/i-0ca59a4b9f642f204/sem/config_ssh_import_id - wb: [644] 25 bytes
2019-05-18 15:40:11,210 - helpers.py[DEBUG]: Running config-ssh-import-id using lock (<FileLock using file '/var/lib/cloud/instances/i-0ca59a4b9f642f204/sem/config_ssh_import_id'>)
2019-05-18 15:40:11,210 - handlers.py[DEBUG]: finish: modules-config/config-ssh-import-id: SUCCESS: config-ssh-import-id ran successfully
2019-05-18 15:40:11,210 - stages.py[DEBUG]: Running module locale (<module 'cloudinit.config.cc_locale' from '/usr/lib/python3/dist-packages/cloudinit/config/cc_locale.py'>) with frequency once-per-instance
2019-05-18 15:40:11,211 - handlers.py[DEBUG]: start: modules-config/config-locale: running config-locale with frequency once-per-instance
2019-05-18 15:40:11,211 - util.py[DEBUG]: Writing to /var/lib/cloud/instances/i-0ca59a4b9f642f204/sem/config_locale - wb: [644] 25 bytes
2019-05-18 15:40:11,211 - helpers.py[DEBUG]: Running config-locale using lock (<FileLock using file '/var/lib/cloud/instances/i-0ca59a4b9f642f204/sem/config_locale'>)
2019-05-18 15:40:11,211 - util.py[DEBUG]: Reading from /etc/default/locale (quiet=False)
2019-05-18 15:40:11,211 - util.py[DEBUG]: Read 35 bytes from /etc/default/locale
2019-05-18 15:40:11,211 - cc_locale.py[DEBUG]: Setting locale to en_US.UTF-8
2019-05-18 15:40:11,211 - util.py[DEBUG]: Reading from /etc/default/locale (quiet=False)
2019-05-18 15:40:11,212 - util.py[DEBUG]: Read 35 bytes from /etc/default/locale
2019-05-18 15:40:11,212 - debian.py[DEBUG]: Generating locales for en_US.UTF-8
2019-05-18 15:40:11,212 - util.py[DEBUG]: Running command ['locale-gen', 'en_US.UTF-8'] with allowed return codes [0] (shell=False, capture=False)
2019-05-18 15:40:11,825 - debian.py[DEBUG]: Updating /etc/default/locale with locale setting LANG=en_US.UTF-8
2019-05-18 15:40:11,825 - util.py[DEBUG]: Running command ['update-locale', '--locale-file=/etc/default/locale', 'LANG=en_US.UTF-8'] with allowed return codes [0] (shell=False, capture=False)
2019-05-18 15:40:11,861 - handlers.py[DEBUG]: finish: modules-config/config-locale: SUCCESS: config-locale ran successfully
2019-05-18 15:40:11,861 - stages.py[DEBUG]: Running module set-passwords (<module 'cloudinit.config.cc_set_passwords' from '/usr/lib/python3/dist-packages/cloudinit/config/cc_set_passwords.py'>) with frequency once-per-instance
2019-05-18 15:40:11,861 - handlers.py[DEBUG]: start: modules-config/config-set-passwords: running config-set-passwords with frequency once-per-instance
2019-05-18 15:40:11,861 - util.py[DEBUG]: Writing to /var/lib/cloud/instances/i-0ca59a4b9f642f204/sem/config_set_passwords - wb: [644] 25 bytes
2019-05-18 15:40:11,862 - helpers.py[DEBUG]: Running config-set-passwords using lock (<FileLock using file '/var/lib/cloud/instances/i-0ca59a4b9f642f204/sem/config_set_passwords'>)
2019-05-18 15:40:11,862 - cc_set_passwords.py[DEBUG]: Leaving ssh config 'PasswordAuthentication' unchanged. ssh_pwauth=None
2019-05-18 15:40:11,862 - handlers.py[DEBUG]: finish: modules-config/config-set-passwords: SUCCESS: config-set-passwords ran successfully
2019-05-18 15:40:11,862 - stages.py[DEBUG]: Running module grub-dpkg (<module 'cloudinit.config.cc_grub_dpkg' from '/usr/lib/python3/dist-packages/cloudinit/config/cc_grub_dpkg.py'>) with frequency once-per-instance
2019-05-18 15:40:11,862 - handlers.py[DEBUG]: start: modules-config/config-grub-dpkg: running config-grub-dpkg with frequency once-per-instance
2019-05-18 15:40:11,862 - util.py[DEBUG]: Writing to /var/lib/cloud/instances/i-0ca59a4b9f642f204/sem/config_grub_dpkg - wb: [644] 25 bytes
2019-05-18 15:40:11,863 - helpers.py[DEBUG]: Running config-grub-dpkg using lock (<FileLock using file '/var/lib/cloud/instances/i-0ca59a4b9f642f204/sem/config_grub_dpkg'>)
2019-05-18 15:40:11,863 - cc_grub_dpkg.py[DEBUG]: Setting grub debconf-set-selections with '/dev/xvda','false'
2019-05-18 15:40:11,863 - util.py[DEBUG]: Running command ['debconf-set-selections'] with allowed return codes [0] (shell=False, capture=True)
2019-05-18 15:40:11,997 - handlers.py[DEBUG]: finish: modules-config/config-grub-dpkg: SUCCESS: config-grub-dpkg ran successfully
2019-05-18 15:40:11,998 - stages.py[DEBUG]: Running module apt-pipelining (<module 'cloudinit.config.cc_apt_pipelining' from '/usr/lib/python3/dist-packages/cloudinit/config/cc_apt_pipelining.py'>) with frequency once-per-instance
2019-05-18 15:40:11,998 - handlers.py[DEBUG]: start: modules-config/config-apt-pipelining: running config-apt-pipelining with frequency once-per-instance
2019-05-18 15:40:11,998 - util.py[DEBUG]: Writing to /var/lib/cloud/instances/i-0ca59a4b9f642f204/sem/config_apt_pipelining - wb: [644] 25 bytes
2019-05-18 15:40:11,998 - helpers.py[DEBUG]: Running config-apt-pipelining using lock (<FileLock using file '/var/lib/cloud/instances/i-0ca59a4b9f642f204/sem/config_apt_pipelining'>)
2019-05-18 15:40:11,999 - util.py[DEBUG]: Writing to /etc/apt/apt.conf.d/90cloud-init-pipelining - wb: [644] 80 bytes
2019-05-18 15:40:12,000 - cc_apt_pipelining.py[DEBUG]: Wrote /etc/apt/apt.conf.d/90cloud-init-pipelining with apt pipeline depth setting 0
2019-05-18 15:40:12,000 - handlers.py[DEBUG]: finish: modules-config/config-apt-pipelining: SUCCESS: config-apt-pipelining ran successfully
2019-05-18 15:40:12,000 - stages.py[DEBUG]: Running module apt-configure (<module 'cloudinit.config.cc_apt_configure' from '/usr/lib/python3/dist-packages/cloudinit/config/cc_apt_configure.py'>) with frequency once-per-instance
2019-05-18 15:40:12,000 - handlers.py[DEBUG]: start: modules-config/config-apt-configure: running config-apt-configure with frequency once-per-instance
2019-05-18 15:40:12,000 - util.py[DEBUG]: Writing to /var/lib/cloud/instances/i-0ca59a4b9f642f204/sem/config_apt_configure - wb: [644] 25 bytes
2019-05-18 15:40:12,001 - helpers.py[DEBUG]: Running config-apt-configure using lock (<FileLock using file '/var/lib/cloud/instances/i-0ca59a4b9f642f204/sem/config_apt_configure'>)
2019-05-18 15:40:12,001 - cc_apt_configure.py[DEBUG]: debconf_selections was not set in config
2019-05-18 15:40:12,001 - util.py[DEBUG]: Reading from /etc/os-release (quiet=True)
2019-05-18 15:40:12,001 - util.py[DEBUG]: Read 298 bytes from /etc/os-release
2019-05-18 15:40:12,001 - util.py[DEBUG]: Reading from /etc/system-image/channel.ini (quiet=True)
2019-05-18 15:40:12,001 - util.py[DEBUG]: Read 0 bytes from /etc/system-image/channel.ini
2019-05-18 15:40:12,002 - cc_apt_configure.py[DEBUG]: handling apt config: {}
2019-05-18 15:40:12,002 - util.py[DEBUG]: Running command ['lsb_release', '--all'] with allowed return codes [0] (shell=False, capture=True)
2019-05-18 15:40:12,051 - util.py[DEBUG]: Running command ['dpkg', '--print-architecture'] with allowed return codes [0] (shell=False, capture=True)
2019-05-18 15:40:12,054 - cc_apt_configure.py[DEBUG]: got primary mirror: None
2019-05-18 15:40:12,054 - cc_apt_configure.py[DEBUG]: got security mirror: None
2019-05-18 15:40:12,054 - util.py[DEBUG]: Running command ['dpkg', '--print-architecture'] with allowed return codes [0] (shell=False, capture=True)
2019-05-18 15:40:12,100 - util.py[DEBUG]: Resolving URL: http://eu-west-1.ec2.archive.ubuntu.com/ubuntu/ took 0.043 seconds
2019-05-18 15:40:12,100 - __init__.py[DEBUG]: filtered distro mirror info: {'primary': 'http://eu-west-1.ec2.archive.ubuntu.com/ubuntu/', 'security': 'http://security.ubuntu.com/ubuntu'}
2019-05-18 15:40:12,100 - cc_apt_configure.py[DEBUG]: Apt Mirror info: {'primary': 'http://eu-west-1.ec2.archive.ubuntu.com/ubuntu/', 'security': 'http://security.ubuntu.com/ubuntu', 'SECURITY': 'http://security.ubuntu.com/ubuntu', 'PRIMARY': 'http://eu-west-1.ec2.archive.ubuntu.com/ubuntu/', 'MIRROR': 'http://eu-west-1.ec2.archive.ubuntu.com/ubuntu/'}
2019-05-18 15:40:12,100 - cc_apt_configure.py[INFO]: No custom template provided, fall back to builtin
2019-05-18 15:40:12,103 - util.py[DEBUG]: Reading from /etc/cloud/templates/sources.list.ubuntu.tmpl (quiet=False)
2019-05-18 15:40:12,103 - util.py[DEBUG]: Read 2841 bytes from /etc/cloud/templates/sources.list.ubuntu.tmpl
2019-05-18 15:40:12,110 - util.py[DEBUG]: Writing to /etc/apt/sources.list - wb: [644] 3335 bytes
2019-05-18 15:40:12,110 - util.py[DEBUG]: Running command ['dpkg', '--print-architecture'] with allowed return codes [0] (shell=False, capture=True)
2019-05-18 15:40:12,114 - cc_apt_configure.py[DEBUG]: Renaming apt list /var/lib/apt/lists/archive.ubuntu.com_ubuntu_dists_xenial-updates_main_i18n_Translation-en to /var/lib/apt/lists/eu-west-1.ec2.archive.ubuntu.com_ubuntu_dists_xenial-updates_main_i18n_Translation-en
2019-05-18 15:40:12,114 - cc_apt_configure.py[DEBUG]: Renaming apt list /var/lib/apt/lists/archive.ubuntu.com_ubuntu_dists_xenial-updates_main_binary-amd64_Packages to /var/lib/apt/lists/eu-west-1.ec2.archive.ubuntu.com_ubuntu_dists_xenial-updates_main_binary-amd64_Packages
2019-05-18 15:40:12,115 - cc_apt_configure.py[DEBUG]: Renaming apt list /var/lib/apt/lists/archive.ubuntu.com_ubuntu_dists_xenial-updates_restricted_binary-amd64_Packages to /var/lib/apt/lists/eu-west-1.ec2.archive.ubuntu.com_ubuntu_dists_xenial-updates_restricted_binary-amd64_Packages
2019-05-18 15:40:12,115 - cc_apt_configure.py[DEBUG]: Renaming apt list /var/lib/apt/lists/archive.ubuntu.com_ubuntu_dists_xenial_main_i18n_Translation-en to /var/lib/apt/lists/eu-west-1.ec2.archive.ubuntu.com_ubuntu_dists_xenial_main_i18n_Translation-en
2019-05-18 15:40:12,115 - cc_apt_configure.py[DEBUG]: Renaming apt list /var/lib/apt/lists/archive.ubuntu.com_ubuntu_dists_xenial-updates_restricted_i18n_Translation-en to /var/lib/apt/lists/eu-west-1.ec2.archive.ubuntu.com_ubuntu_dists_xenial-updates_restricted_i18n_Translation-en
2019-05-18 15:40:12,115 - cc_apt_configure.py[DEBUG]: Renaming apt list /var/lib/apt/lists/archive.ubuntu.com_ubuntu_dists_xenial-updates_InRelease to /var/lib/apt/lists/eu-west-1.ec2.archive.ubuntu.com_ubuntu_dists_xenial-updates_InRelease
2019-05-18 15:40:12,115 - cc_apt_configure.py[DEBUG]: Renaming apt list /var/lib/apt/lists/archive.ubuntu.com_ubuntu_dists_xenial_InRelease to /var/lib/apt/lists/eu-west-1.ec2.archive.ubuntu.com_ubuntu_dists_xenial_InRelease
2019-05-18 15:40:12,115 - cc_apt_configure.py[DEBUG]: Renaming apt list /var/lib/apt/lists/archive.ubuntu.com_ubuntu_dists_xenial_restricted_i18n_Translation-en to /var/lib/apt/lists/eu-west-1.ec2.archive.ubuntu.com_ubuntu_dists_xenial_restricted_i18n_Translation-en
2019-05-18 15:40:12,115 - cc_apt_configure.py[DEBUG]: Renaming apt list /var/lib/apt/lists/archive.ubuntu.com_ubuntu_dists_xenial_restricted_binary-amd64_Packages to /var/lib/apt/lists/eu-west-1.ec2.archive.ubuntu.com_ubuntu_dists_xenial_restricted_binary-amd64_Packages
2019-05-18 15:40:12,115 - cc_apt_configure.py[DEBUG]: Renaming apt list /var/lib/apt/lists/archive.ubuntu.com_ubuntu_dists_xenial_main_binary-amd64_Packages to /var/lib/apt/lists/eu-west-1.ec2.archive.ubuntu.com_ubuntu_dists_xenial_main_binary-amd64_Packages
2019-05-18 15:40:12,115 - handlers.py[DEBUG]: finish: modules-config/config-apt-configure: SUCCESS: config-apt-configure ran successfully
2019-05-18 15:40:12,115 - stages.py[DEBUG]: Running module ubuntu-advantage (<module 'cloudinit.config.cc_ubuntu_advantage' from '/usr/lib/python3/dist-packages/cloudinit/config/cc_ubuntu_advantage.py'>) with frequency once-per-instance
2019-05-18 15:40:12,115 - handlers.py[DEBUG]: start: modules-config/config-ubuntu-advantage: running config-ubuntu-advantage with frequency once-per-instance
2019-05-18 15:40:12,116 - util.py[DEBUG]: Writing to /var/lib/cloud/instances/i-0ca59a4b9f642f204/sem/config_ubuntu_advantage - wb: [644] 25 bytes
2019-05-18 15:40:12,116 - helpers.py[DEBUG]: Running config-ubuntu-advantage using lock (<FileLock using file '/var/lib/cloud/instances/i-0ca59a4b9f642f204/sem/config_ubuntu_advantage'>)
2019-05-18 15:40:12,116 - cc_ubuntu_advantage.py[DEBUG]: Skipping module named ubuntu-advantage, no 'ubuntu-advantage' key in configuration
2019-05-18 15:40:12,116 - handlers.py[DEBUG]: finish: modules-config/config-ubuntu-advantage: SUCCESS: config-ubuntu-advantage ran successfully
2019-05-18 15:40:12,116 - stages.py[DEBUG]: Running module ntp (<module 'cloudinit.config.cc_ntp' from '/usr/lib/python3/dist-packages/cloudinit/config/cc_ntp.py'>) with frequency once-per-instance
2019-05-18 15:40:12,116 - handlers.py[DEBUG]: start: modules-config/config-ntp: running config-ntp with frequency once-per-instance
2019-05-18 15:40:12,116 - util.py[DEBUG]: Writing to /var/lib/cloud/instances/i-0ca59a4b9f642f204/sem/config_ntp - wb: [644] 25 bytes
2019-05-18 15:40:12,117 - helpers.py[DEBUG]: Running config-ntp using lock (<FileLock using file '/var/lib/cloud/instances/i-0ca59a4b9f642f204/sem/config_ntp'>)
2019-05-18 15:40:12,117 - cc_ntp.py[DEBUG]: Skipping module named ntp, not present or disabled by cfg
2019-05-18 15:40:12,117 - handlers.py[DEBUG]: finish: modules-config/config-ntp: SUCCESS: config-ntp ran successfully
2019-05-18 15:40:12,117 - stages.py[DEBUG]: Running module timezone (<module 'cloudinit.config.cc_timezone' from '/usr/lib/python3/dist-packages/cloudinit/config/cc_timezone.py'>) with frequency once-per-instance
2019-05-18 15:40:12,117 - handlers.py[DEBUG]: start: modules-config/config-timezone: running config-timezone with frequency once-per-instance
2019-05-18 15:40:12,117 - util.py[DEBUG]: Writing to /var/lib/cloud/instances/i-0ca59a4b9f642f204/sem/config_timezone - wb: [644] 24 bytes
2019-05-18 15:40:12,118 - helpers.py[DEBUG]: Running config-timezone using lock (<FileLock using file '/var/lib/cloud/instances/i-0ca59a4b9f642f204/sem/config_timezone'>)
2019-05-18 15:40:12,118 - cc_timezone.py[DEBUG]: Skipping module named timezone, no 'timezone' specified
2019-05-18 15:40:12,118 - handlers.py[DEBUG]: finish: modules-config/config-timezone: SUCCESS: config-timezone ran successfully
2019-05-18 15:40:12,118 - stages.py[DEBUG]: Running module disable-ec2-metadata (<module 'cloudinit.config.cc_disable_ec2_metadata' from '/usr/lib/python3/dist-packages/cloudinit/config/cc_disable_ec2_metadata.py'>) with frequency always
2019-05-18 15:40:12,118 - handlers.py[DEBUG]: start: modules-config/config-disable-ec2-metadata: running config-disable-ec2-metadata with frequency always
2019-05-18 15:40:12,118 - helpers.py[DEBUG]: Running config-disable-ec2-metadata using lock (<cloudinit.helpers.DummyLock object at 0x7f03990b8fd0>)
2019-05-18 15:40:12,118 - cc_disable_ec2_metadata.py[DEBUG]: Skipping module named disable-ec2-metadata, disabling the ec2 route not enabled
2019-05-18 15:40:12,118 - handlers.py[DEBUG]: finish: modules-config/config-disable-ec2-metadata: SUCCESS: config-disable-ec2-metadata ran successfully
2019-05-18 15:40:12,118 - stages.py[DEBUG]: Running module runcmd (<module 'cloudinit.config.cc_runcmd' from '/usr/lib/python3/dist-packages/cloudinit/config/cc_runcmd.py'>) with frequency once-per-instance
2019-05-18 15:40:12,118 - handlers.py[DEBUG]: start: modules-config/config-runcmd: running config-runcmd with frequency once-per-instance
2019-05-18 15:40:12,118 - util.py[DEBUG]: Writing to /var/lib/cloud/instances/i-0ca59a4b9f642f204/sem/config_runcmd - wb: [644] 25 bytes
2019-05-18 15:40:12,119 - helpers.py[DEBUG]: Running config-runcmd using lock (<FileLock using file '/var/lib/cloud/instances/i-0ca59a4b9f642f204/sem/config_runcmd'>)
2019-05-18 15:40:12,119 - cc_runcmd.py[DEBUG]: Skipping module named runcmd, no 'runcmd' key in configuration
2019-05-18 15:40:12,119 - handlers.py[DEBUG]: finish: modules-config/config-runcmd: SUCCESS: config-runcmd ran successfully
2019-05-18 15:40:12,119 - stages.py[DEBUG]: Running module byobu (<module 'cloudinit.config.cc_byobu' from '/usr/lib/python3/dist-packages/cloudinit/config/cc_byobu.py'>) with frequency once-per-instance
2019-05-18 15:40:12,119 - handlers.py[DEBUG]: start: modules-config/config-byobu: running config-byobu with frequency once-per-instance
2019-05-18 15:40:12,119 - util.py[DEBUG]: Writing to /var/lib/cloud/instances/i-0ca59a4b9f642f204/sem/config_byobu - wb: [644] 25 bytes
2019-05-18 15:40:12,120 - helpers.py[DEBUG]: Running config-byobu using lock (<FileLock using file '/var/lib/cloud/instances/i-0ca59a4b9f642f204/sem/config_byobu'>)
2019-05-18 15:40:12,120 - cc_byobu.py[DEBUG]: Skipping module named byobu, no 'byobu' values found
2019-05-18 15:40:12,120 - handlers.py[DEBUG]: finish: modules-config/config-byobu: SUCCESS: config-byobu ran successfully
2019-05-18 15:40:12,120 - main.py[DEBUG]: Ran 15 modules with 0 failures
2019-05-18 15:40:12,120 - util.py[DEBUG]: Reading from /proc/uptime (quiet=False)
2019-05-18 15:40:12,120 - util.py[DEBUG]: Read 13 bytes from /proc/uptime
2019-05-18 15:40:12,121 - util.py[DEBUG]: cloud-init mode 'modules' took 1.001 seconds (1.00)
2019-05-18 15:40:12,121 - handlers.py[DEBUG]: finish: modules-config: SUCCESS: running modules for config
2019-05-18 15:40:12,412 - util.py[DEBUG]: Cloud-init v. 18.3-9-g2e62cb8a-0ubuntu1~16.04.2 running 'modules:final' at Sat, 18 May 2019 15:40:12 +0000. Up 15.66 seconds.
2019-05-18 15:40:12,448 - stages.py[DEBUG]: Using distro class <class 'cloudinit.distros.ubuntu.Distro'>
2019-05-18 15:40:12,449 - stages.py[DEBUG]: Running module snappy (<module 'cloudinit.config.cc_snappy' from '/usr/lib/python3/dist-packages/cloudinit/config/cc_snappy.py'>) with frequency once-per-instance
2019-05-18 15:40:12,449 - handlers.py[DEBUG]: start: modules-final/config-snappy: running config-snappy with frequency once-per-instance
2019-05-18 15:40:12,449 - util.py[DEBUG]: Writing to /var/lib/cloud/instances/i-0ca59a4b9f642f204/sem/config_snappy - wb: [644] 25 bytes
2019-05-18 15:40:12,450 - helpers.py[DEBUG]: Running config-snappy using lock (<FileLock using file '/var/lib/cloud/instances/i-0ca59a4b9f642f204/sem/config_snappy'>)
2019-05-18 15:40:12,450 - util.py[DEBUG]: Reading from /etc/os-release (quiet=True)
2019-05-18 15:40:12,450 - util.py[DEBUG]: Read 298 bytes from /etc/os-release
2019-05-18 15:40:12,450 - util.py[DEBUG]: Reading from /etc/system-image/channel.ini (quiet=True)
2019-05-18 15:40:12,450 - util.py[DEBUG]: Read 0 bytes from /etc/system-image/channel.ini
2019-05-18 15:40:12,451 - cc_snappy.py[DEBUG]: snappy: 'auto' mode, and system not snappy
2019-05-18 15:40:12,451 - handlers.py[DEBUG]: finish: modules-final/config-snappy: SUCCESS: config-snappy ran successfully
2019-05-18 15:40:12,451 - stages.py[DEBUG]: Running module package-update-upgrade-install (<module 'cloudinit.config.cc_package_update_upgrade_install' from '/usr/lib/python3/dist-packages/cloudinit/config/cc_package_update_upgrade_install.py'>) with frequency once-per-instance
2019-05-18 15:40:12,451 - handlers.py[DEBUG]: start: modules-final/config-package-update-upgrade-install: running config-package-update-upgrade-install with frequency once-per-instance
2019-05-18 15:40:12,451 - util.py[DEBUG]: Writing to /var/lib/cloud/instances/i-0ca59a4b9f642f204/sem/config_package_update_upgrade_install - wb: [644] 25 bytes
2019-05-18 15:40:12,452 - helpers.py[DEBUG]: Running config-package-update-upgrade-install using lock (<FileLock using file '/var/lib/cloud/instances/i-0ca59a4b9f642f204/sem/config_package_update_upgrade_install'>)
2019-05-18 15:40:12,452 - handlers.py[DEBUG]: finish: modules-final/config-package-update-upgrade-install: SUCCESS: config-package-update-upgrade-install ran successfully
2019-05-18 15:40:12,452 - stages.py[DEBUG]: Running module fan (<module 'cloudinit.config.cc_fan' from '/usr/lib/python3/dist-packages/cloudinit/config/cc_fan.py'>) with frequency once-per-instance
2019-05-18 15:40:12,452 - handlers.py[DEBUG]: start: modules-final/config-fan: running config-fan with frequency once-per-instance
2019-05-18 15:40:12,452 - util.py[DEBUG]: Writing to /var/lib/cloud/instances/i-0ca59a4b9f642f204/sem/config_fan - wb: [644] 25 bytes
2019-05-18 15:40:12,452 - helpers.py[DEBUG]: Running config-fan using lock (<FileLock using file '/var/lib/cloud/instances/i-0ca59a4b9f642f204/sem/config_fan'>)
2019-05-18 15:40:12,453 - cc_fan.py[DEBUG]: fan: no 'fan' config entry. disabling
2019-05-18 15:40:12,453 - handlers.py[DEBUG]: finish: modules-final/config-fan: SUCCESS: config-fan ran successfully
2019-05-18 15:40:12,453 - stages.py[DEBUG]: Running module landscape (<module 'cloudinit.config.cc_landscape' from '/usr/lib/python3/dist-packages/cloudinit/config/cc_landscape.py'>) with frequency once-per-instance
2019-05-18 15:40:12,453 - handlers.py[DEBUG]: start: modules-final/config-landscape: running config-landscape with frequency once-per-instance
2019-05-18 15:40:12,453 - util.py[DEBUG]: Writing to /var/lib/cloud/instances/i-0ca59a4b9f642f204/sem/config_landscape - wb: [644] 25 bytes
2019-05-18 15:40:12,453 - helpers.py[DEBUG]: Running config-landscape using lock (<FileLock using file '/var/lib/cloud/instances/i-0ca59a4b9f642f204/sem/config_landscape'>)
2019-05-18 15:40:12,454 - handlers.py[DEBUG]: finish: modules-final/config-landscape: SUCCESS: config-landscape ran successfully
2019-05-18 15:40:12,454 - stages.py[DEBUG]: Running module lxd (<module 'cloudinit.config.cc_lxd' from '/usr/lib/python3/dist-packages/cloudinit/config/cc_lxd.py'>) with frequency once-per-instance
2019-05-18 15:40:12,454 - handlers.py[DEBUG]: start: modules-final/config-lxd: running config-lxd with frequency once-per-instance
2019-05-18 15:40:12,454 - util.py[DEBUG]: Writing to /var/lib/cloud/instances/i-0ca59a4b9f642f204/sem/config_lxd - wb: [644] 25 bytes
2019-05-18 15:40:12,454 - helpers.py[DEBUG]: Running config-lxd using lock (<FileLock using file '/var/lib/cloud/instances/i-0ca59a4b9f642f204/sem/config_lxd'>)
2019-05-18 15:40:12,454 - cc_lxd.py[DEBUG]: Skipping module named lxd, not present or disabled by cfg
2019-05-18 15:40:12,454 - handlers.py[DEBUG]: finish: modules-final/config-lxd: SUCCESS: config-lxd ran successfully
2019-05-18 15:40:12,455 - stages.py[DEBUG]: Running module puppet (<module 'cloudinit.config.cc_puppet' from '/usr/lib/python3/dist-packages/cloudinit/config/cc_puppet.py'>) with frequency once-per-instance
2019-05-18 15:40:12,455 - handlers.py[DEBUG]: start: modules-final/config-puppet: running config-puppet with frequency once-per-instance
2019-05-18 15:40:12,455 - util.py[DEBUG]: Writing to /var/lib/cloud/instances/i-0ca59a4b9f642f204/sem/config_puppet - wb: [644] 25 bytes
2019-05-18 15:40:12,455 - helpers.py[DEBUG]: Running config-puppet using lock (<FileLock using file '/var/lib/cloud/instances/i-0ca59a4b9f642f204/sem/config_puppet'>)
2019-05-18 15:40:12,455 - cc_puppet.py[DEBUG]: Skipping module named puppet, no 'puppet' configuration found
2019-05-18 15:40:12,455 - handlers.py[DEBUG]: finish: modules-final/config-puppet: SUCCESS: config-puppet ran successfully
2019-05-18 15:40:12,455 - stages.py[DEBUG]: Running module chef (<module 'cloudinit.config.cc_chef' from '/usr/lib/python3/dist-packages/cloudinit/config/cc_chef.py'>) with frequency once-per-instance
2019-05-18 15:40:12,456 - handlers.py[DEBUG]: start: modules-final/config-chef: running config-chef with frequency once-per-instance
2019-05-18 15:40:12,456 - util.py[DEBUG]: Writing to /var/lib/cloud/instances/i-0ca59a4b9f642f204/sem/config_chef - wb: [644] 25 bytes
2019-05-18 15:40:12,456 - helpers.py[DEBUG]: Running config-chef using lock (<FileLock using file '/var/lib/cloud/instances/i-0ca59a4b9f642f204/sem/config_chef'>)
2019-05-18 15:40:12,456 - cc_chef.py[DEBUG]: Skipping module named chef, no 'chef' key in configuration
2019-05-18 15:40:12,456 - handlers.py[DEBUG]: finish: modules-final/config-chef: SUCCESS: config-chef ran successfully
2019-05-18 15:40:12,456 - stages.py[DEBUG]: Running module mcollective (<module 'cloudinit.config.cc_mcollective' from '/usr/lib/python3/dist-packages/cloudinit/config/cc_mcollective.py'>) with frequency once-per-instance
2019-05-18 15:40:12,457 - handlers.py[DEBUG]: start: modules-final/config-mcollective: running config-mcollective with frequency once-per-instance
2019-05-18 15:40:12,457 - util.py[DEBUG]: Writing to /var/lib/cloud/instances/i-0ca59a4b9f642f204/sem/config_mcollective - wb: [644] 25 bytes
2019-05-18 15:40:12,457 - helpers.py[DEBUG]: Running config-mcollective using lock (<FileLock using file '/var/lib/cloud/instances/i-0ca59a4b9f642f204/sem/config_mcollective'>)
2019-05-18 15:40:12,457 - cc_mcollective.py[DEBUG]: Skipping module named mcollective, no 'mcollective' key in configuration
2019-05-18 15:40:12,457 - handlers.py[DEBUG]: finish: modules-final/config-mcollective: SUCCESS: config-mcollective ran successfully
2019-05-18 15:40:12,457 - stages.py[DEBUG]: Running module salt-minion (<module 'cloudinit.config.cc_salt_minion' from '/usr/lib/python3/dist-packages/cloudinit/config/cc_salt_minion.py'>) with frequency once-per-instance
2019-05-18 15:40:12,457 - handlers.py[DEBUG]: start: modules-final/config-salt-minion: running config-salt-minion with frequency once-per-instance
2019-05-18 15:40:12,458 - util.py[DEBUG]: Writing to /var/lib/cloud/instances/i-0ca59a4b9f642f204/sem/config_salt_minion - wb: [644] 25 bytes
2019-05-18 15:40:12,458 - helpers.py[DEBUG]: Running config-salt-minion using lock (<FileLock using file '/var/lib/cloud/instances/i-0ca59a4b9f642f204/sem/config_salt_minion'>)
2019-05-18 15:40:12,458 - cc_salt_minion.py[DEBUG]: Skipping module named salt-minion, no 'salt_minion' key in configuration
2019-05-18 15:40:12,458 - handlers.py[DEBUG]: finish: modules-final/config-salt-minion: SUCCESS: config-salt-minion ran successfully
2019-05-18 15:40:12,458 - stages.py[DEBUG]: Running module rightscale_userdata (<module 'cloudinit.config.cc_rightscale_userdata' from '/usr/lib/python3/dist-packages/cloudinit/config/cc_rightscale_userdata.py'>) with frequency once-per-instance
2019-05-18 15:40:12,458 - handlers.py[DEBUG]: start: modules-final/config-rightscale_userdata: running config-rightscale_userdata with frequency once-per-instance
2019-05-18 15:40:12,458 - util.py[DEBUG]: Writing to /var/lib/cloud/instances/i-0ca59a4b9f642f204/sem/config_rightscale_userdata - wb: [644] 25 bytes
2019-05-18 15:40:12,459 - helpers.py[DEBUG]: Running config-rightscale_userdata using lock (<FileLock using file '/var/lib/cloud/instances/i-0ca59a4b9f642f204/sem/config_rightscale_userdata'>)
2019-05-18 15:40:12,459 - cc_rightscale_userdata.py[DEBUG]: Failed to get raw userdata in module rightscale_userdata
2019-05-18 15:40:12,459 - handlers.py[DEBUG]: finish: modules-final/config-rightscale_userdata: SUCCESS: config-rightscale_userdata ran successfully
2019-05-18 15:40:12,459 - stages.py[DEBUG]: Running module scripts-vendor (<module 'cloudinit.config.cc_scripts_vendor' from '/usr/lib/python3/dist-packages/cloudinit/config/cc_scripts_vendor.py'>) with frequency once-per-instance
2019-05-18 15:40:12,459 - handlers.py[DEBUG]: start: modules-final/config-scripts-vendor: running config-scripts-vendor with frequency once-per-instance
2019-05-18 15:40:12,459 - util.py[DEBUG]: Writing to /var/lib/cloud/instances/i-0ca59a4b9f642f204/sem/config_scripts_vendor - wb: [644] 24 bytes
2019-05-18 15:40:12,460 - helpers.py[DEBUG]: Running config-scripts-vendor using lock (<FileLock using file '/var/lib/cloud/instances/i-0ca59a4b9f642f204/sem/config_scripts_vendor'>)
2019-05-18 15:40:12,460 - handlers.py[DEBUG]: finish: modules-final/config-scripts-vendor: SUCCESS: config-scripts-vendor ran successfully
2019-05-18 15:40:12,460 - stages.py[DEBUG]: Running module scripts-per-once (<module 'cloudinit.config.cc_scripts_per_once' from '/usr/lib/python3/dist-packages/cloudinit/config/cc_scripts_per_once.py'>) with frequency once
2019-05-18 15:40:12,460 - handlers.py[DEBUG]: start: modules-final/config-scripts-per-once: running config-scripts-per-once with frequency once
2019-05-18 15:40:12,460 - util.py[DEBUG]: Writing to /var/lib/cloud/sem/config_scripts_per_once.once - wb: [644] 25 bytes
2019-05-18 15:40:12,460 - helpers.py[DEBUG]: Running config-scripts-per-once using lock (<FileLock using file '/var/lib/cloud/sem/config_scripts_per_once.once'>)
2019-05-18 15:40:12,461 - handlers.py[DEBUG]: finish: modules-final/config-scripts-per-once: SUCCESS: config-scripts-per-once ran successfully
2019-05-18 15:40:12,461 - stages.py[DEBUG]: Running module scripts-per-boot (<module 'cloudinit.config.cc_scripts_per_boot' from '/usr/lib/python3/dist-packages/cloudinit/config/cc_scripts_per_boot.py'>) with frequency always
2019-05-18 15:40:12,461 - handlers.py[DEBUG]: start: modules-final/config-scripts-per-boot: running config-scripts-per-boot with frequency always
2019-05-18 15:40:12,461 - helpers.py[DEBUG]: Running config-scripts-per-boot using lock (<cloudinit.helpers.DummyLock object at 0x7f38a655b4a8>)
2019-05-18 15:40:12,461 - handlers.py[DEBUG]: finish: modules-final/config-scripts-per-boot: SUCCESS: config-scripts-per-boot ran successfully
2019-05-18 15:40:12,461 - stages.py[DEBUG]: Running module scripts-per-instance (<module 'cloudinit.config.cc_scripts_per_instance' from '/usr/lib/python3/dist-packages/cloudinit/config/cc_scripts_per_instance.py'>) with frequency once-per-instance
2019-05-18 15:40:12,461 - handlers.py[DEBUG]: start: modules-final/config-scripts-per-instance: running config-scripts-per-instance with frequency once-per-instance
2019-05-18 15:40:12,461 - util.py[DEBUG]: Writing to /var/lib/cloud/instances/i-0ca59a4b9f642f204/sem/config_scripts_per_instance - wb: [644] 24 bytes
2019-05-18 15:40:12,462 - helpers.py[DEBUG]: Running config-scripts-per-instance using lock (<FileLock using file '/var/lib/cloud/instances/i-0ca59a4b9f642f204/sem/config_scripts_per_instance'>)
2019-05-18 15:40:12,462 - handlers.py[DEBUG]: finish: modules-final/config-scripts-per-instance: SUCCESS: config-scripts-per-instance ran successfully
2019-05-18 15:40:12,462 - stages.py[DEBUG]: Running module scripts-user (<module 'cloudinit.config.cc_scripts_user' from '/usr/lib/python3/dist-packages/cloudinit/config/cc_scripts_user.py'>) with frequency once-per-instance
2019-05-18 15:40:12,462 - handlers.py[DEBUG]: start: modules-final/config-scripts-user: running config-scripts-user with frequency once-per-instance
2019-05-18 15:40:12,462 - util.py[DEBUG]: Writing to /var/lib/cloud/instances/i-0ca59a4b9f642f204/sem/config_scripts_user - wb: [644] 24 bytes
2019-05-18 15:40:12,462 - helpers.py[DEBUG]: Running config-scripts-user using lock (<FileLock using file '/var/lib/cloud/instances/i-0ca59a4b9f642f204/sem/config_scripts_user'>)
2019-05-18 15:40:12,463 - handlers.py[DEBUG]: finish: modules-final/config-scripts-user: SUCCESS: config-scripts-user ran successfully
2019-05-18 15:40:12,463 - stages.py[DEBUG]: Running module ssh-authkey-fingerprints (<module 'cloudinit.config.cc_ssh_authkey_fingerprints' from '/usr/lib/python3/dist-packages/cloudinit/config/cc_ssh_authkey_fingerprints.py'>) with frequency once-per-instance
2019-05-18 15:40:12,463 - handlers.py[DEBUG]: start: modules-final/config-ssh-authkey-fingerprints: running config-ssh-authkey-fingerprints with frequency once-per-instance
2019-05-18 15:40:12,463 - util.py[DEBUG]: Writing to /var/lib/cloud/instances/i-0ca59a4b9f642f204/sem/config_ssh_authkey_fingerprints - wb: [644] 25 bytes
2019-05-18 15:40:12,463 - helpers.py[DEBUG]: Running config-ssh-authkey-fingerprints using lock (<FileLock using file '/var/lib/cloud/instances/i-0ca59a4b9f642f204/sem/config_ssh_authkey_fingerprints'>)
2019-05-18 15:40:12,464 - util.py[DEBUG]: Reading from /etc/ssh/sshd_config (quiet=False)
2019-05-18 15:40:12,464 - util.py[DEBUG]: Read 2540 bytes from /etc/ssh/sshd_config
2019-05-18 15:40:12,464 - util.py[DEBUG]: Reading from /home/ubuntu/.ssh/authorized_keys (quiet=False)
2019-05-18 15:40:12,464 - util.py[DEBUG]: Read 448 bytes from /home/ubuntu/.ssh/authorized_keys
2019-05-18 15:40:12,507 - handlers.py[DEBUG]: finish: modules-final/config-ssh-authkey-fingerprints: SUCCESS: config-ssh-authkey-fingerprints ran successfully
2019-05-18 15:40:12,507 - stages.py[DEBUG]: Running module keys-to-console (<module 'cloudinit.config.cc_keys_to_console' from '/usr/lib/python3/dist-packages/cloudinit/config/cc_keys_to_console.py'>) with frequency once-per-instance
2019-05-18 15:40:12,507 - handlers.py[DEBUG]: start: modules-final/config-keys-to-console: running config-keys-to-console with frequency once-per-instance
2019-05-18 15:40:12,507 - util.py[DEBUG]: Writing to /var/lib/cloud/instances/i-0ca59a4b9f642f204/sem/config_keys_to_console - wb: [644] 25 bytes
2019-05-18 15:40:12,508 - helpers.py[DEBUG]: Running config-keys-to-console using lock (<FileLock using file '/var/lib/cloud/instances/i-0ca59a4b9f642f204/sem/config_keys_to_console'>)
2019-05-18 15:40:12,508 - util.py[DEBUG]: Running command ['/usr/lib/cloud-init/write-ssh-key-fingerprints', '', 'ssh-dss'] with allowed return codes [0] (shell=False, capture=True)
2019-05-18 15:40:12,522 - handlers.py[DEBUG]: finish: modules-final/config-keys-to-console: SUCCESS: config-keys-to-console ran successfully
2019-05-18 15:40:12,522 - stages.py[DEBUG]: Running module phone-home (<module 'cloudinit.config.cc_phone_home' from '/usr/lib/python3/dist-packages/cloudinit/config/cc_phone_home.py'>) with frequency once-per-instance
2019-05-18 15:40:12,522 - handlers.py[DEBUG]: start: modules-final/config-phone-home: running config-phone-home with frequency once-per-instance
2019-05-18 15:40:12,522 - util.py[DEBUG]: Writing to /var/lib/cloud/instances/i-0ca59a4b9f642f204/sem/config_phone_home - wb: [644] 25 bytes
2019-05-18 15:40:12,523 - helpers.py[DEBUG]: Running config-phone-home using lock (<FileLock using file '/var/lib/cloud/instances/i-0ca59a4b9f642f204/sem/config_phone_home'>)
2019-05-18 15:40:12,523 - cc_phone_home.py[DEBUG]: Skipping module named phone-home, no 'phone_home' configuration found
2019-05-18 15:40:12,523 - handlers.py[DEBUG]: finish: modules-final/config-phone-home: SUCCESS: config-phone-home ran successfully
2019-05-18 15:40:12,523 - stages.py[DEBUG]: Running module final-message (<module 'cloudinit.config.cc_final_message' from '/usr/lib/python3/dist-packages/cloudinit/config/cc_final_message.py'>) with frequency always
2019-05-18 15:40:12,523 - handlers.py[DEBUG]: start: modules-final/config-final-message: running config-final-message with frequency always
2019-05-18 15:40:12,523 - helpers.py[DEBUG]: Running config-final-message using lock (<cloudinit.helpers.DummyLock object at 0x7f38a5dde198>)
2019-05-18 15:40:12,523 - util.py[DEBUG]: Reading from /proc/uptime (quiet=False)
2019-05-18 15:40:12,523 - util.py[DEBUG]: Read 13 bytes from /proc/uptime
2019-05-18 15:40:12,526 - util.py[DEBUG]: Cloud-init v. 18.3-9-g2e62cb8a-0ubuntu1~16.04.2 finished at Sat, 18 May 2019 15:40:12 +0000. Datasource DataSourceEc2Local.  Up 15.82 seconds
2019-05-18 15:40:12,526 - util.py[DEBUG]: Writing to /var/lib/cloud/instance/boot-finished - wb: [644] 79 bytes
2019-05-18 15:40:12,527 - handlers.py[DEBUG]: finish: modules-final/config-final-message: SUCCESS: config-final-message ran successfully
2019-05-18 15:40:12,527 - stages.py[DEBUG]: Running module power-state-change (<module 'cloudinit.config.cc_power_state_change' from '/usr/lib/python3/dist-packages/cloudinit/config/cc_power_state_change.py'>) with frequency once-per-instance
2019-05-18 15:40:12,527 - handlers.py[DEBUG]: start: modules-final/config-power-state-change: running config-power-state-change with frequency once-per-instance
2019-05-18 15:40:12,527 - util.py[DEBUG]: Writing to /var/lib/cloud/instances/i-0ca59a4b9f642f204/sem/config_power_state_change - wb: [644] 24 bytes
2019-05-18 15:40:12,527 - helpers.py[DEBUG]: Running config-power-state-change using lock (<FileLock using file '/var/lib/cloud/instances/i-0ca59a4b9f642f204/sem/config_power_state_change'>)
2019-05-18 15:40:12,527 - cc_power_state_change.py[DEBUG]: no power_state provided. doing nothing
2019-05-18 15:40:12,527 - handlers.py[DEBUG]: finish: modules-final/config-power-state-change: SUCCESS: config-power-state-change ran successfully
2019-05-18 15:40:12,528 - main.py[DEBUG]: Ran 20 modules with 0 failures
2019-05-18 15:40:12,528 - util.py[DEBUG]: Creating symbolic link from '/run/cloud-init/result.json' => '../../var/lib/cloud/data/result.json'
2019-05-18 15:40:12,528 - util.py[DEBUG]: Reading from /proc/uptime (quiet=False)
2019-05-18 15:40:12,528 - util.py[DEBUG]: Read 13 bytes from /proc/uptime
2019-05-18 15:40:12,528 - util.py[DEBUG]: cloud-init mode 'modules' took 0.161 seconds (0.16)
2019-05-18 15:40:12,529 - handlers.py[DEBUG]: finish: modules-final: SUCCESS: running modules for final
