2019-05-18 15:40:05,010 - util.py[DEBUG]: Cloud-init v. 18.3-9-g2e62cb8a-0ubuntu1~16.04.2 running 'init-local' at Sat, 18 May 2019 15:40:04 +0000. Up 6.52 seconds.
2019-05-18 15:40:05,010 - main.py[DEBUG]: No kernel command line url found.
2019-05-18 15:40:05,010 - main.py[DEBUG]: Closing stdin.
2019-05-18 15:40:05,013 - util.py[DEBUG]: Writing to /var/log/cloud-init.log - ab: [644] 0 bytes
2019-05-18 15:40:05,014 - util.py[DEBUG]: Changing the ownership of /var/log/cloud-init.log to 104:4
2019-05-18 15:40:05,014 - util.py[DEBUG]: Attempting to remove /var/lib/cloud/instance/boot-finished
2019-05-18 15:40:05,014 - util.py[DEBUG]: Attempting to remove /var/lib/cloud/data/no-net
2019-05-18 15:40:05,014 - handlers.py[DEBUG]: start: init-local/check-cache: attempting to read from cache [check]
2019-05-18 15:40:05,015 - util.py[DEBUG]: Reading from /var/lib/cloud/instance/obj.pkl (quiet=False)
2019-05-18 15:40:05,015 - stages.py[DEBUG]: no cache found
2019-05-18 15:40:05,015 - handlers.py[DEBUG]: finish: init-local/check-cache: SUCCESS: no cache found
2019-05-18 15:40:05,015 - util.py[DEBUG]: Attempting to remove /var/lib/cloud/instance
2019-05-18 15:40:05,020 - stages.py[DEBUG]: Using distro class <class 'cloudinit.distros.ubuntu.Distro'>
2019-05-18 15:40:05,020 - __init__.py[DEBUG]: Looking for data source in: ['NoCloud', 'ConfigDrive', 'OpenNebula', 'DigitalOcean', 'Azure', 'AltCloud', 'OVF', 'MAAS', 'GCE', 'OpenStack', 'CloudSigma', 'SmartOS', 'Bigstep', 'Scaleway', 'AliYun', 'Ec2', 'CloudStack', 'None'], via packages ['', 'cloudinit.sources'] that matches dependencies ['FILESYSTEM']
2019-05-18 15:40:05,054 - util.py[DEBUG]: Reading from /etc/os-release (quiet=False)
2019-05-18 15:40:05,054 - util.py[DEBUG]: Read 298 bytes from /etc/os-release
2019-05-18 15:40:05,077 - __init__.py[DEBUG]: Searching for local data source in: ['DataSourceNoCloud', 'DataSourceConfigDrive', 'DataSourceOpenNebula', 'DataSourceDigitalOcean', 'DataSourceAzure', 'DataSourceOVF', 'DataSourceOpenStackLocal', 'DataSourceCloudSigma', 'DataSourceSmartOS', 'DataSourceEc2Local']
2019-05-18 15:40:05,077 - handlers.py[DEBUG]: start: init-local/search-NoCloud: searching for local data from DataSourceNoCloud
2019-05-18 15:40:05,077 - __init__.py[DEBUG]: Seeing if we can get any data from <class 'cloudinit.sources.DataSourceNoCloud.DataSourceNoCloud'>
2019-05-18 15:40:05,077 - __init__.py[DEBUG]: Update datasource metadata and network config due to events: New instance first boot
2019-05-18 15:40:05,077 - util.py[DEBUG]: Running command ['systemd-detect-virt', '--quiet', '--container'] with allowed return codes [0] (shell=False, capture=True)
2019-05-18 15:40:05,079 - util.py[DEBUG]: Running command ['running-in-container'] with allowed return codes [0] (shell=False, capture=True)
2019-05-18 15:40:05,080 - util.py[DEBUG]: Running command ['lxc-is-container'] with allowed return codes [0] (shell=False, capture=True)
2019-05-18 15:40:05,081 - util.py[DEBUG]: Reading from /proc/1/environ (quiet=False)
2019-05-18 15:40:05,082 - util.py[DEBUG]: Read 150 bytes from /proc/1/environ
2019-05-18 15:40:05,082 - util.py[DEBUG]: Reading from /proc/self/status (quiet=False)
2019-05-18 15:40:05,082 - util.py[DEBUG]: Read 966 bytes from /proc/self/status
2019-05-18 15:40:05,082 - util.py[DEBUG]: querying dmi data /sys/class/dmi/id/product_serial
2019-05-18 15:40:05,082 - util.py[DEBUG]: Reading from /sys/class/dmi/id/product_serial (quiet=False)
2019-05-18 15:40:05,082 - util.py[DEBUG]: Read 37 bytes from /sys/class/dmi/id/product_serial
2019-05-18 15:40:05,082 - util.py[DEBUG]: dmi data /sys/class/dmi/id/product_serial returned ec20d0ba-a647-189c-879b-92942dfd5cef
2019-05-18 15:40:05,082 - util.py[DEBUG]: Reading from /var/lib/cloud/seed/nocloud/user-data (quiet=False)
2019-05-18 15:40:05,082 - util.py[DEBUG]: Reading from /var/lib/cloud/seed/nocloud/meta-data (quiet=False)
2019-05-18 15:40:05,082 - util.py[DEBUG]: Reading from /var/lib/cloud/seed/nocloud/vendor-data (quiet=False)
2019-05-18 15:40:05,082 - util.py[DEBUG]: Reading from /var/lib/cloud/seed/nocloud/network-config (quiet=False)
2019-05-18 15:40:05,082 - util.py[DEBUG]: Reading from /var/lib/cloud/seed/nocloud-net/user-data (quiet=False)
2019-05-18 15:40:05,082 - util.py[DEBUG]: Reading from /var/lib/cloud/seed/nocloud-net/meta-data (quiet=False)
2019-05-18 15:40:05,082 - util.py[DEBUG]: Reading from /var/lib/cloud/seed/nocloud-net/vendor-data (quiet=False)
2019-05-18 15:40:05,082 - util.py[DEBUG]: Reading from /var/lib/cloud/seed/nocloud-net/network-config (quiet=False)
2019-05-18 15:40:05,083 - util.py[DEBUG]: Running command ['blkid', '-odevice', '/dev/sr0'] with allowed return codes [0, 2] (shell=False, capture=True)
2019-05-18 15:40:05,084 - util.py[DEBUG]: Running command ['blkid', '-odevice', '/dev/sr1'] with allowed return codes [0, 2] (shell=False, capture=True)
2019-05-18 15:40:05,085 - util.py[DEBUG]: Running command ['blkid', '-tTYPE=vfat', '-odevice'] with allowed return codes [0, 2] (shell=False, capture=True)
2019-05-18 15:40:05,098 - util.py[DEBUG]: Running command ['blkid', '-tTYPE=iso9660', '-odevice'] with allowed return codes [0, 2] (shell=False, capture=True)
2019-05-18 15:40:05,110 - util.py[DEBUG]: Running command ['blkid', '-tLABEL=cidata', '-odevice'] with allowed return codes [0, 2] (shell=False, capture=True)
2019-05-18 15:40:05,122 - handlers.py[DEBUG]: finish: init-local/search-NoCloud: SUCCESS: no local data found from DataSourceNoCloud
2019-05-18 15:40:05,122 - handlers.py[DEBUG]: start: init-local/search-ConfigDrive: searching for local data from DataSourceConfigDrive
2019-05-18 15:40:05,122 - __init__.py[DEBUG]: Seeing if we can get any data from <class 'cloudinit.sources.DataSourceConfigDrive.DataSourceConfigDrive'>
2019-05-18 15:40:05,122 - __init__.py[DEBUG]: Update datasource metadata and network config due to events: New instance first boot
2019-05-18 15:40:05,122 - util.py[DEBUG]: Running command ['blkid', '-odevice', '/dev/sr0'] with allowed return codes [0, 2] (shell=False, capture=True)
2019-05-18 15:40:05,124 - util.py[DEBUG]: Running command ['blkid', '-odevice', '/dev/sr1'] with allowed return codes [0, 2] (shell=False, capture=True)
2019-05-18 15:40:05,125 - util.py[DEBUG]: Running command ['blkid', '-odevice', '/dev/cd0'] with allowed return codes [0, 2] (shell=False, capture=True)
2019-05-18 15:40:05,127 - util.py[DEBUG]: Running command ['blkid', '-odevice', '/dev/cd1'] with allowed return codes [0, 2] (shell=False, capture=True)
2019-05-18 15:40:05,128 - util.py[DEBUG]: Running command ['blkid', '-tTYPE=vfat', '-odevice'] with allowed return codes [0, 2] (shell=False, capture=True)
2019-05-18 15:40:05,140 - util.py[DEBUG]: Running command ['blkid', '-tTYPE=iso9660', '-odevice'] with allowed return codes [0, 2] (shell=False, capture=True)
2019-05-18 15:40:05,151 - util.py[DEBUG]: Running command ['blkid', '-tLABEL=config-2', '-odevice'] with allowed return codes [0, 2] (shell=False, capture=True)
2019-05-18 15:40:05,164 - util.py[DEBUG]: Running command ['blkid', '-tLABEL=CONFIG-2', '-odevice'] with allowed return codes [0, 2] (shell=False, capture=True)
2019-05-18 15:40:05,176 - DataSourceConfigDrive.py[DEBUG]: devices=[] dslist=['NoCloud', 'ConfigDrive', 'OpenNebula', 'DigitalOcean', 'Azure', 'AltCloud', 'OVF', 'MAAS', 'GCE', 'OpenStack', 'CloudSigma', 'SmartOS', 'Bigstep', 'Scaleway', 'AliYun', 'Ec2', 'CloudStack', 'None']
2019-05-18 15:40:05,176 - handlers.py[DEBUG]: finish: init-local/search-ConfigDrive: SUCCESS: no local data found from DataSourceConfigDrive
2019-05-18 15:40:05,176 - handlers.py[DEBUG]: start: init-local/search-OpenNebula: searching for local data from DataSourceOpenNebula
2019-05-18 15:40:05,176 - __init__.py[DEBUG]: Seeing if we can get any data from <class 'cloudinit.sources.DataSourceOpenNebula.DataSourceOpenNebula'>
2019-05-18 15:40:05,176 - __init__.py[DEBUG]: Update datasource metadata and network config due to events: New instance first boot
2019-05-18 15:40:05,176 - util.py[DEBUG]: Running command ['blkid', '-tLABEL=CONTEXT', '-odevice'] with allowed return codes [0, 2] (shell=False, capture=True)
2019-05-18 15:40:05,188 - util.py[DEBUG]: Running command ['blkid', '-tLABEL=CDROM', '-odevice'] with allowed return codes [0, 2] (shell=False, capture=True)
2019-05-18 15:40:05,201 - util.py[DEBUG]: Running command ['blkid', '-tTYPE=iso9660', '-odevice'] with allowed return codes [0, 2] (shell=False, capture=True)
2019-05-18 15:40:05,213 - handlers.py[DEBUG]: finish: init-local/search-OpenNebula: SUCCESS: no local data found from DataSourceOpenNebula
2019-05-18 15:40:05,213 - handlers.py[DEBUG]: start: init-local/search-DigitalOcean: searching for local data from DataSourceDigitalOcean
2019-05-18 15:40:05,213 - __init__.py[DEBUG]: Seeing if we can get any data from <class 'cloudinit.sources.DataSourceDigitalOcean.DataSourceDigitalOcean'>
2019-05-18 15:40:05,213 - __init__.py[DEBUG]: Update datasource metadata and network config due to events: New instance first boot
2019-05-18 15:40:05,213 - util.py[DEBUG]: Running command ['systemd-detect-virt', '--quiet', '--container'] with allowed return codes [0] (shell=False, capture=True)
2019-05-18 15:40:05,215 - util.py[DEBUG]: Running command ['running-in-container'] with allowed return codes [0] (shell=False, capture=True)
2019-05-18 15:40:05,216 - util.py[DEBUG]: Running command ['lxc-is-container'] with allowed return codes [0] (shell=False, capture=True)
2019-05-18 15:40:05,218 - util.py[DEBUG]: Reading from /proc/1/environ (quiet=False)
2019-05-18 15:40:05,218 - util.py[DEBUG]: Read 150 bytes from /proc/1/environ
2019-05-18 15:40:05,218 - util.py[DEBUG]: Reading from /proc/self/status (quiet=False)
2019-05-18 15:40:05,218 - util.py[DEBUG]: Read 966 bytes from /proc/self/status
2019-05-18 15:40:05,218 - util.py[DEBUG]: querying dmi data /sys/class/dmi/id/sys_vendor
2019-05-18 15:40:05,218 - util.py[DEBUG]: Reading from /sys/class/dmi/id/sys_vendor (quiet=False)
2019-05-18 15:40:05,218 - util.py[DEBUG]: Read 4 bytes from /sys/class/dmi/id/sys_vendor
2019-05-18 15:40:05,218 - util.py[DEBUG]: dmi data /sys/class/dmi/id/sys_vendor returned Xen
2019-05-18 15:40:05,219 - handlers.py[DEBUG]: finish: init-local/search-DigitalOcean: SUCCESS: no local data found from DataSourceDigitalOcean
2019-05-18 15:40:05,219 - handlers.py[DEBUG]: start: init-local/search-Azure: searching for local data from DataSourceAzure
2019-05-18 15:40:05,219 - __init__.py[DEBUG]: Seeing if we can get any data from <class 'cloudinit.sources.DataSourceAzure.DataSourceAzure'>
2019-05-18 15:40:05,219 - __init__.py[DEBUG]: Update datasource metadata and network config due to events: New instance first boot
2019-05-18 15:40:05,219 - util.py[DEBUG]: Running command ['systemd-detect-virt', '--quiet', '--container'] with allowed return codes [0] (shell=False, capture=True)
2019-05-18 15:40:05,221 - util.py[DEBUG]: Running command ['running-in-container'] with allowed return codes [0] (shell=False, capture=True)
2019-05-18 15:40:05,222 - util.py[DEBUG]: Running command ['lxc-is-container'] with allowed return codes [0] (shell=False, capture=True)
2019-05-18 15:40:05,224 - util.py[DEBUG]: Reading from /proc/1/environ (quiet=False)
2019-05-18 15:40:05,224 - util.py[DEBUG]: Read 150 bytes from /proc/1/environ
2019-05-18 15:40:05,224 - util.py[DEBUG]: Reading from /proc/self/status (quiet=False)
2019-05-18 15:40:05,224 - util.py[DEBUG]: Read 966 bytes from /proc/self/status
2019-05-18 15:40:05,224 - util.py[DEBUG]: querying dmi data /sys/class/dmi/id/chassis_asset_tag
2019-05-18 15:40:05,224 - util.py[DEBUG]: Reading from /sys/class/dmi/id/chassis_asset_tag (quiet=False)
2019-05-18 15:40:05,224 - util.py[DEBUG]: Read 1 bytes from /sys/class/dmi/id/chassis_asset_tag
2019-05-18 15:40:05,225 - util.py[DEBUG]: dmi data /sys/class/dmi/id/chassis_asset_tag returned 
2019-05-18 15:40:05,225 - DataSourceAzure.py[DEBUG]: Non-Azure DMI asset tag '' discovered.
2019-05-18 15:40:05,225 - handlers.py[DEBUG]: finish: init-local/search-Azure: SUCCESS: no local data found from DataSourceAzure
2019-05-18 15:40:05,225 - handlers.py[DEBUG]: start: init-local/search-OVF: searching for local data from DataSourceOVF
2019-05-18 15:40:05,225 - __init__.py[DEBUG]: Seeing if we can get any data from <class 'cloudinit.sources.DataSourceOVF.DataSourceOVF'>
2019-05-18 15:40:05,225 - __init__.py[DEBUG]: Update datasource metadata and network config due to events: New instance first boot
2019-05-18 15:40:05,225 - util.py[DEBUG]: Running command ['systemd-detect-virt', '--quiet', '--container'] with allowed return codes [0] (shell=False, capture=True)
2019-05-18 15:40:05,227 - util.py[DEBUG]: Running command ['running-in-container'] with allowed return codes [0] (shell=False, capture=True)
2019-05-18 15:40:05,228 - util.py[DEBUG]: Running command ['lxc-is-container'] with allowed return codes [0] (shell=False, capture=True)
2019-05-18 15:40:05,230 - util.py[DEBUG]: Reading from /proc/1/environ (quiet=False)
2019-05-18 15:40:05,230 - util.py[DEBUG]: Read 150 bytes from /proc/1/environ
2019-05-18 15:40:05,230 - util.py[DEBUG]: Reading from /proc/self/status (quiet=False)
2019-05-18 15:40:05,230 - util.py[DEBUG]: Read 966 bytes from /proc/self/status
2019-05-18 15:40:05,230 - util.py[DEBUG]: querying dmi data /sys/class/dmi/id/product_name
2019-05-18 15:40:05,230 - util.py[DEBUG]: Reading from /sys/class/dmi/id/product_name (quiet=False)
2019-05-18 15:40:05,231 - util.py[DEBUG]: Read 9 bytes from /sys/class/dmi/id/product_name
2019-05-18 15:40:05,231 - util.py[DEBUG]: dmi data /sys/class/dmi/id/product_name returned HVM domU
2019-05-18 15:40:05,231 - util.py[DEBUG]: Reading from /proc/mounts (quiet=False)
2019-05-18 15:40:05,231 - util.py[DEBUG]: Read 1991 bytes from /proc/mounts
2019-05-18 15:40:05,231 - util.py[DEBUG]: Fetched {'proc': {'fstype': 'proc', 'mountpoint': '/proc', 'opts': 'rw,nosuid,nodev,noexec,relatime'}, 'hugetlbfs': {'fstype': 'hugetlbfs', 'mountpoint': '/dev/hugepages', 'opts': 'rw,relatime'}, 'fusectl': {'fstype': 'fusectl', 'mountpoint': '/sys/fs/fuse/connections', 'opts': 'rw,relatime'}, 'debugfs': {'fstype': 'debugfs', 'mountpoint': '/sys/kernel/debug', 'opts': 'rw,relatime'}, 'cgroup': {'fstype': 'cgroup', 'mountpoint': '/sys/fs/cgroup/freezer', 'opts': 'rw,nosuid,nodev,noexec,relatime,freezer'}, 'tmpfs': {'fstype': 'tmpfs', 'mountpoint': '/sys/fs/cgroup', 'opts': 'ro,nosuid,nodev,noexec,mode=755'}, 'sysfs': {'fstype': 'sysfs', 'mountpoint': '/sys', 'opts': 'rw,nosuid,nodev,noexec,relatime'}, 'pstore': {'fstype': 'pstore', 'mountpoint': '/sys/fs/pstore', 'opts': 'rw,nosuid,nodev,noexec,relatime'}, 'udev': {'fstype': 'devtmpfs', 'mountpoint': '/dev', 'opts': 'rw,nosuid,relatime,size=30907648k,nr_inodes=7726912,mode=755'}, 'systemd-1': {'fstype': 'autofs', 'mountpoint': '/proc/sys/fs/binfmt_misc', 'opts': 'rw,relatime,fd=35,pgrp=1,timeout=0,minproto=5,maxproto=5,direct'}, 'devpts': {'fstype': 'devpts', 'mountpoint': '/dev/pts', 'opts': 'rw,nosuid,noexec,relatime,gid=5,mode=620,ptmxmode=000'}, '/dev/xvda1': {'fstype': 'ext4', 'mountpoint': '/', 'opts': 'rw,relatime,discard,data=ordered'}, 'securityfs': {'fstype': 'securityfs', 'mountpoint': '/sys/kernel/security', 'opts': 'rw,nosuid,nodev,noexec,relatime'}, 'mqueue': {'fstype': 'mqueue', 'mountpoint': '/dev/mqueue', 'opts': 'rw,relatime'}} mounts from proc
2019-05-18 15:40:05,231 - util.py[DEBUG]: Running command ['blkid', '-tTYPE=iso9660', '-odevice'] with allowed return codes [0, 2] (shell=False, capture=True)
2019-05-18 15:40:05,243 - handlers.py[DEBUG]: finish: init-local/search-OVF: SUCCESS: no local data found from DataSourceOVF
2019-05-18 15:40:05,243 - handlers.py[DEBUG]: start: init-local/search-OpenStackLocal: searching for local data from DataSourceOpenStackLocal
2019-05-18 15:40:05,243 - __init__.py[DEBUG]: Seeing if we can get any data from <class 'cloudinit.sources.DataSourceOpenStack.DataSourceOpenStackLocal'>
2019-05-18 15:40:05,244 - __init__.py[DEBUG]: Update datasource metadata and network config due to events: New instance first boot
2019-05-18 15:40:05,244 - util.py[DEBUG]: Running command ['systemd-detect-virt', '--quiet', '--container'] with allowed return codes [0] (shell=False, capture=True)
2019-05-18 15:40:05,245 - util.py[DEBUG]: Running command ['running-in-container'] with allowed return codes [0] (shell=False, capture=True)
2019-05-18 15:40:05,247 - util.py[DEBUG]: Running command ['lxc-is-container'] with allowed return codes [0] (shell=False, capture=True)
2019-05-18 15:40:05,249 - util.py[DEBUG]: Reading from /proc/1/environ (quiet=False)
2019-05-18 15:40:05,249 - util.py[DEBUG]: Read 150 bytes from /proc/1/environ
2019-05-18 15:40:05,249 - util.py[DEBUG]: Reading from /proc/self/status (quiet=False)
2019-05-18 15:40:05,249 - util.py[DEBUG]: Read 966 bytes from /proc/self/status
2019-05-18 15:40:05,249 - util.py[DEBUG]: querying dmi data /sys/class/dmi/id/product_name
2019-05-18 15:40:05,249 - util.py[DEBUG]: Reading from /sys/class/dmi/id/product_name (quiet=False)
2019-05-18 15:40:05,249 - util.py[DEBUG]: Read 9 bytes from /sys/class/dmi/id/product_name
2019-05-18 15:40:05,249 - util.py[DEBUG]: dmi data /sys/class/dmi/id/product_name returned HVM domU
2019-05-18 15:40:05,249 - util.py[DEBUG]: Running command ['systemd-detect-virt', '--quiet', '--container'] with allowed return codes [0] (shell=False, capture=True)
2019-05-18 15:40:05,251 - util.py[DEBUG]: Running command ['running-in-container'] with allowed return codes [0] (shell=False, capture=True)
2019-05-18 15:40:05,252 - util.py[DEBUG]: Running command ['lxc-is-container'] with allowed return codes [0] (shell=False, capture=True)
2019-05-18 15:40:05,254 - util.py[DEBUG]: Reading from /proc/1/environ (quiet=False)
2019-05-18 15:40:05,254 - util.py[DEBUG]: Read 150 bytes from /proc/1/environ
2019-05-18 15:40:05,254 - util.py[DEBUG]: Reading from /proc/self/status (quiet=False)
2019-05-18 15:40:05,254 - util.py[DEBUG]: Read 966 bytes from /proc/self/status
2019-05-18 15:40:05,254 - util.py[DEBUG]: querying dmi data /sys/class/dmi/id/chassis_asset_tag
2019-05-18 15:40:05,254 - util.py[DEBUG]: Reading from /sys/class/dmi/id/chassis_asset_tag (quiet=False)
2019-05-18 15:40:05,254 - util.py[DEBUG]: Read 1 bytes from /sys/class/dmi/id/chassis_asset_tag
2019-05-18 15:40:05,254 - util.py[DEBUG]: dmi data /sys/class/dmi/id/chassis_asset_tag returned 
2019-05-18 15:40:05,254 - util.py[DEBUG]: Reading from /proc/1/environ (quiet=False)
2019-05-18 15:40:05,255 - util.py[DEBUG]: Read 150 bytes from /proc/1/environ
2019-05-18 15:40:05,255 - handlers.py[DEBUG]: finish: init-local/search-OpenStackLocal: SUCCESS: no local data found from DataSourceOpenStackLocal
2019-05-18 15:40:05,255 - handlers.py[DEBUG]: start: init-local/search-CloudSigma: searching for local data from DataSourceCloudSigma
2019-05-18 15:40:05,255 - __init__.py[DEBUG]: Seeing if we can get any data from <class 'cloudinit.sources.DataSourceCloudSigma.DataSourceCloudSigma'>
2019-05-18 15:40:05,255 - __init__.py[DEBUG]: Update datasource metadata and network config due to events: New instance first boot
2019-05-18 15:40:05,255 - DataSourceCloudSigma.py[DEBUG]: determining hypervisor product name via dmi data
2019-05-18 15:40:05,255 - util.py[DEBUG]: Running command ['systemd-detect-virt', '--quiet', '--container'] with allowed return codes [0] (shell=False, capture=True)
2019-05-18 15:40:05,257 - util.py[DEBUG]: Running command ['running-in-container'] with allowed return codes [0] (shell=False, capture=True)
2019-05-18 15:40:05,258 - util.py[DEBUG]: Running command ['lxc-is-container'] with allowed return codes [0] (shell=False, capture=True)
2019-05-18 15:40:05,260 - util.py[DEBUG]: Reading from /proc/1/environ (quiet=False)
2019-05-18 15:40:05,260 - util.py[DEBUG]: Read 150 bytes from /proc/1/environ
2019-05-18 15:40:05,260 - util.py[DEBUG]: Reading from /proc/self/status (quiet=False)
2019-05-18 15:40:05,260 - util.py[DEBUG]: Read 966 bytes from /proc/self/status
2019-05-18 15:40:05,260 - util.py[DEBUG]: querying dmi data /sys/class/dmi/id/product_name
2019-05-18 15:40:05,260 - util.py[DEBUG]: Reading from /sys/class/dmi/id/product_name (quiet=False)
2019-05-18 15:40:05,260 - util.py[DEBUG]: Read 9 bytes from /sys/class/dmi/id/product_name
2019-05-18 15:40:05,260 - util.py[DEBUG]: dmi data /sys/class/dmi/id/product_name returned HVM domU
2019-05-18 15:40:05,261 - DataSourceCloudSigma.py[DEBUG]: detected hypervisor as HVM domU
2019-05-18 15:40:05,261 - handlers.py[DEBUG]: finish: init-local/search-CloudSigma: SUCCESS: no local data found from DataSourceCloudSigma
2019-05-18 15:40:05,261 - handlers.py[DEBUG]: start: init-local/search-SmartOS: searching for local data from DataSourceSmartOS
2019-05-18 15:40:05,261 - __init__.py[DEBUG]: Seeing if we can get any data from <class 'cloudinit.sources.DataSourceSmartOS.DataSourceSmartOS'>
2019-05-18 15:40:05,261 - util.py[DEBUG]: Running command ['systemd-detect-virt', '--quiet', '--container'] with allowed return codes [0] (shell=False, capture=True)
2019-05-18 15:40:05,263 - util.py[DEBUG]: Running command ['running-in-container'] with allowed return codes [0] (shell=False, capture=True)
2019-05-18 15:40:05,264 - util.py[DEBUG]: Running command ['lxc-is-container'] with allowed return codes [0] (shell=False, capture=True)
2019-05-18 15:40:05,266 - util.py[DEBUG]: Reading from /proc/1/environ (quiet=False)
2019-05-18 15:40:05,266 - util.py[DEBUG]: Read 150 bytes from /proc/1/environ
2019-05-18 15:40:05,266 - util.py[DEBUG]: Reading from /proc/self/status (quiet=False)
2019-05-18 15:40:05,266 - util.py[DEBUG]: Read 966 bytes from /proc/self/status
2019-05-18 15:40:05,266 - util.py[DEBUG]: querying dmi data /sys/class/dmi/id/product_name
2019-05-18 15:40:05,266 - util.py[DEBUG]: Reading from /sys/class/dmi/id/product_name (quiet=False)
2019-05-18 15:40:05,266 - util.py[DEBUG]: Read 9 bytes from /sys/class/dmi/id/product_name
2019-05-18 15:40:05,266 - util.py[DEBUG]: dmi data /sys/class/dmi/id/product_name returned HVM domU
2019-05-18 15:40:05,266 - __init__.py[DEBUG]: Update datasource metadata and network config due to events: New instance first boot
2019-05-18 15:40:05,267 - DataSourceSmartOS.py[DEBUG]: Not running on smartos
2019-05-18 15:40:05,267 - handlers.py[DEBUG]: finish: init-local/search-SmartOS: SUCCESS: no local data found from DataSourceSmartOS
2019-05-18 15:40:05,267 - handlers.py[DEBUG]: start: init-local/search-Ec2Local: searching for local data from DataSourceEc2Local
2019-05-18 15:40:05,267 - __init__.py[DEBUG]: Seeing if we can get any data from <class 'cloudinit.sources.DataSourceEc2.DataSourceEc2Local'>
2019-05-18 15:40:05,267 - __init__.py[DEBUG]: Update datasource metadata and network config due to events: New instance first boot
2019-05-18 15:40:05,267 - util.py[DEBUG]: Reading from /sys/hypervisor/uuid (quiet=False)
2019-05-18 15:40:05,267 - util.py[DEBUG]: Read 37 bytes from /sys/hypervisor/uuid
2019-05-18 15:40:05,267 - util.py[DEBUG]: Running command ['systemd-detect-virt', '--quiet', '--container'] with allowed return codes [0] (shell=False, capture=True)
2019-05-18 15:40:05,269 - util.py[DEBUG]: Running command ['running-in-container'] with allowed return codes [0] (shell=False, capture=True)
2019-05-18 15:40:05,270 - util.py[DEBUG]: Running command ['lxc-is-container'] with allowed return codes [0] (shell=False, capture=True)
2019-05-18 15:40:05,272 - util.py[DEBUG]: Reading from /proc/1/environ (quiet=False)
2019-05-18 15:40:05,272 - util.py[DEBUG]: Read 150 bytes from /proc/1/environ
2019-05-18 15:40:05,272 - util.py[DEBUG]: Reading from /proc/self/status (quiet=False)
2019-05-18 15:40:05,272 - util.py[DEBUG]: Read 966 bytes from /proc/self/status
2019-05-18 15:40:05,272 - util.py[DEBUG]: querying dmi data /sys/class/dmi/id/product_serial
2019-05-18 15:40:05,272 - util.py[DEBUG]: Reading from /sys/class/dmi/id/product_serial (quiet=False)
2019-05-18 15:40:05,272 - util.py[DEBUG]: Read 37 bytes from /sys/class/dmi/id/product_serial
2019-05-18 15:40:05,272 - util.py[DEBUG]: dmi data /sys/class/dmi/id/product_serial returned ec20d0ba-a647-189c-879b-92942dfd5cef
2019-05-18 15:40:05,273 - DataSourceEc2.py[DEBUG]: strict_mode: warn, cloud_platform=AWS
2019-05-18 15:40:05,273 - util.py[DEBUG]: Reading from /etc/os-release (quiet=False)
2019-05-18 15:40:05,273 - util.py[DEBUG]: Read 298 bytes from /etc/os-release
2019-05-18 15:40:05,273 - util.py[DEBUG]: Reading from /sys/class/net/ens3/name_assign_type (quiet=False)
2019-05-18 15:40:05,273 - util.py[DEBUG]: Read 2 bytes from /sys/class/net/ens3/name_assign_type
2019-05-18 15:40:05,273 - util.py[DEBUG]: Reading from /sys/class/net/ens3/carrier (quiet=False)
2019-05-18 15:40:05,274 - util.py[DEBUG]: Reading from /sys/class/net/ens3/dormant (quiet=False)
2019-05-18 15:40:05,274 - util.py[DEBUG]: Reading from /sys/class/net/ens3/operstate (quiet=False)
2019-05-18 15:40:05,274 - util.py[DEBUG]: Read 5 bytes from /sys/class/net/ens3/operstate
2019-05-18 15:40:05,274 - util.py[DEBUG]: Reading from /sys/class/net/ens3/address (quiet=False)
2019-05-18 15:40:05,274 - util.py[DEBUG]: Read 18 bytes from /sys/class/net/ens3/address
2019-05-18 15:40:05,274 - dhcp.py[DEBUG]: Performing a dhcp discovery on ens3
2019-05-18 15:40:05,274 - util.py[DEBUG]: Copying /sbin/dhclient to /var/tmp/cloud-init/cloud-init-dhcp-e5hut4ea/dhclient
2019-05-18 15:40:05,277 - util.py[DEBUG]: Running command ['ip', 'link', 'set', 'dev', 'ens3', 'up'] with allowed return codes [0] (shell=False, capture=True)
2019-05-18 15:40:05,294 - util.py[DEBUG]: Running command ['/var/tmp/cloud-init/cloud-init-dhcp-e5hut4ea/dhclient', '-1', '-v', '-lf', '/var/tmp/cloud-init/cloud-init-dhcp-e5hut4ea/dhcp.leases', '-pf', '/var/tmp/cloud-init/cloud-init-dhcp-e5hut4ea/dhclient.pid', 'ens3', '-sf', '/bin/true'] with allowed return codes [0] (shell=False, capture=True)
2019-05-18 15:40:05,333 - util.py[DEBUG]: All files appeared after 0 seconds: ['/var/tmp/cloud-init/cloud-init-dhcp-e5hut4ea/dhclient.pid', '/var/tmp/cloud-init/cloud-init-dhcp-e5hut4ea/dhcp.leases']
2019-05-18 15:40:05,334 - util.py[DEBUG]: Reading from /var/tmp/cloud-init/cloud-init-dhcp-e5hut4ea/dhclient.pid (quiet=False)
2019-05-18 15:40:05,334 - util.py[DEBUG]: Read 5 bytes from /var/tmp/cloud-init/cloud-init-dhcp-e5hut4ea/dhclient.pid
2019-05-18 15:40:05,334 - util.py[DEBUG]: Reading from /var/tmp/cloud-init/cloud-init-dhcp-e5hut4ea/dhcp.leases (quiet=False)
2019-05-18 15:40:05,334 - util.py[DEBUG]: Read 511 bytes from /var/tmp/cloud-init/cloud-init-dhcp-e5hut4ea/dhcp.leases
2019-05-18 15:40:05,334 - dhcp.py[DEBUG]: Received dhcp lease on ens3 for 10.0.0.17/255.255.255.0
2019-05-18 15:40:05,335 - __init__.py[DEBUG]: Attempting setup of ephemeral network on ens3 with 10.0.0.17/24 brd 10.0.0.255
2019-05-18 15:40:05,335 - util.py[DEBUG]: Running command ['ip', '-family', 'inet', 'addr', 'add', '10.0.0.17/24', 'broadcast', '10.0.0.255', 'dev', 'ens3'] with allowed return codes [0] (shell=False, capture=True)
2019-05-18 15:40:05,336 - util.py[DEBUG]: Running command ['ip', '-family', 'inet', 'link', 'set', 'dev', 'ens3', 'up'] with allowed return codes [0] (shell=False, capture=True)
2019-05-18 15:40:05,339 - util.py[DEBUG]: Running command ['ip', 'route', 'show', '0.0.0.0/0'] with allowed return codes [0] (shell=False, capture=True)
2019-05-18 15:40:05,341 - util.py[DEBUG]: Running command ['ip', '-4', 'route', 'add', 'default', 'via', '10.0.0.1', 'dev', 'ens3'] with allowed return codes [0] (shell=False, capture=True)
2019-05-18 15:40:05,345 - util.py[DEBUG]: Resolving URL: http://169.254.169.254 took 0.003 seconds
2019-05-18 15:40:05,346 - util.py[DEBUG]: Resolving URL: http://instance-data.:8773 took 0.000 seconds
2019-05-18 15:40:05,346 - DataSourceEc2.py[DEBUG]: Removed the following from metadata urls: ['http://instance-data.:8773']
2019-05-18 15:40:05,346 - url_helper.py[DEBUG]: [0/1] open 'http://169.254.169.254/2009-04-04/meta-data/instance-id' with {'timeout': 50.0, 'method': 'GET', 'url': 'http://169.254.169.254/2009-04-04/meta-data/instance-id', 'headers': {'User-Agent': 'Cloud-Init/18.3-9-g2e62cb8a-0ubuntu1~16.04.2'}, 'allow_redirects': True} configuration
2019-05-18 15:40:05,350 - url_helper.py[DEBUG]: Read from http://169.254.169.254/2009-04-04/meta-data/instance-id (200, 19b) after 1 attempts
2019-05-18 15:40:05,350 - DataSourceEc2.py[DEBUG]: Using metadata source: 'http://169.254.169.254'
2019-05-18 15:40:05,351 - url_helper.py[DEBUG]: [0/1] open 'http://169.254.169.254/2016-09-02/meta-data/instance-id' with {'method': 'GET', 'url': 'http://169.254.169.254/2016-09-02/meta-data/instance-id', 'headers': {'User-Agent': 'Cloud-Init/18.3-9-g2e62cb8a-0ubuntu1~16.04.2'}, 'allow_redirects': True} configuration
2019-05-18 15:40:05,352 - url_helper.py[DEBUG]: Read from http://169.254.169.254/2016-09-02/meta-data/instance-id (200, 19b) after 1 attempts
2019-05-18 15:40:05,352 - DataSourceEc2.py[DEBUG]: Found preferred metadata version 2016-09-02
2019-05-18 15:40:05,352 - url_helper.py[DEBUG]: [0/6] open 'http://169.254.169.254/2016-09-02/user-data' with {'timeout': 5.0, 'method': 'GET', 'url': 'http://169.254.169.254/2016-09-02/user-data', 'headers': {'User-Agent': 'Cloud-Init/18.3-9-g2e62cb8a-0ubuntu1~16.04.2'}, 'allow_redirects': True} configuration
2019-05-18 15:40:05,354 - url_helper.py[DEBUG]: [0/6] open 'http://169.254.169.254/2016-09-02/meta-data/' with {'timeout': 5.0, 'method': 'GET', 'url': 'http://169.254.169.254/2016-09-02/meta-data/', 'headers': {'User-Agent': 'Cloud-Init/18.3-9-g2e62cb8a-0ubuntu1~16.04.2'}, 'allow_redirects': True} configuration
2019-05-18 15:40:05,355 - url_helper.py[DEBUG]: Read from http://169.254.169.254/2016-09-02/meta-data/ (200, 268b) after 1 attempts
2019-05-18 15:40:05,356 - url_helper.py[DEBUG]: [0/6] open 'http://169.254.169.254/2016-09-02/meta-data/block-device-mapping/' with {'timeout': 5.0, 'method': 'GET', 'url': 'http://169.254.169.254/2016-09-02/meta-data/block-device-mapping/', 'headers': {'User-Agent': 'Cloud-Init/18.3-9-g2e62cb8a-0ubuntu1~16.04.2'}, 'allow_redirects': True} configuration
2019-05-18 15:40:05,357 - url_helper.py[DEBUG]: Read from http://169.254.169.254/2016-09-02/meta-data/block-device-mapping/ (200, 30b) after 1 attempts
2019-05-18 15:40:05,357 - url_helper.py[DEBUG]: [0/6] open 'http://169.254.169.254/2016-09-02/meta-data/block-device-mapping/ephemeral0' with {'timeout': 5.0, 'method': 'GET', 'url': 'http://169.254.169.254/2016-09-02/meta-data/block-device-mapping/ephemeral0', 'headers': {'User-Agent': 'Cloud-Init/18.3-9-g2e62cb8a-0ubuntu1~16.04.2'}, 'allow_redirects': True} configuration
2019-05-18 15:40:05,359 - url_helper.py[DEBUG]: Read from http://169.254.169.254/2016-09-02/meta-data/block-device-mapping/ephemeral0 (200, 3b) after 1 attempts
2019-05-18 15:40:05,359 - url_helper.py[DEBUG]: [0/6] open 'http://169.254.169.254/2016-09-02/meta-data/block-device-mapping/ami' with {'timeout': 5.0, 'method': 'GET', 'url': 'http://169.254.169.254/2016-09-02/meta-data/block-device-mapping/ami', 'headers': {'User-Agent': 'Cloud-Init/18.3-9-g2e62cb8a-0ubuntu1~16.04.2'}, 'allow_redirects': True} configuration
2019-05-18 15:40:05,360 - url_helper.py[DEBUG]: Read from http://169.254.169.254/2016-09-02/meta-data/block-device-mapping/ami (200, 9b) after 1 attempts
2019-05-18 15:40:05,361 - url_helper.py[DEBUG]: [0/6] open 'http://169.254.169.254/2016-09-02/meta-data/block-device-mapping/ephemeral1' with {'timeout': 5.0, 'method': 'GET', 'url': 'http://169.254.169.254/2016-09-02/meta-data/block-device-mapping/ephemeral1', 'headers': {'User-Agent': 'Cloud-Init/18.3-9-g2e62cb8a-0ubuntu1~16.04.2'}, 'allow_redirects': True} configuration
2019-05-18 15:40:05,362 - url_helper.py[DEBUG]: Read from http://169.254.169.254/2016-09-02/meta-data/block-device-mapping/ephemeral1 (200, 3b) after 1 attempts
2019-05-18 15:40:05,362 - url_helper.py[DEBUG]: [0/6] open 'http://169.254.169.254/2016-09-02/meta-data/block-device-mapping/root' with {'timeout': 5.0, 'method': 'GET', 'url': 'http://169.254.169.254/2016-09-02/meta-data/block-device-mapping/root', 'headers': {'User-Agent': 'Cloud-Init/18.3-9-g2e62cb8a-0ubuntu1~16.04.2'}, 'allow_redirects': True} configuration
2019-05-18 15:40:05,364 - url_helper.py[DEBUG]: Read from http://169.254.169.254/2016-09-02/meta-data/block-device-mapping/root (200, 9b) after 1 attempts
2019-05-18 15:40:05,364 - url_helper.py[DEBUG]: [0/6] open 'http://169.254.169.254/2016-09-02/meta-data/iam/' with {'timeout': 5.0, 'method': 'GET', 'url': 'http://169.254.169.254/2016-09-02/meta-data/iam/', 'headers': {'User-Agent': 'Cloud-Init/18.3-9-g2e62cb8a-0ubuntu1~16.04.2'}, 'allow_redirects': True} configuration
2019-05-18 15:40:05,365 - url_helper.py[DEBUG]: Read from http://169.254.169.254/2016-09-02/meta-data/iam/ (200, 26b) after 1 attempts
2019-05-18 15:40:05,365 - url_helper.py[DEBUG]: [0/6] open 'http://169.254.169.254/2016-09-02/meta-data/iam/info' with {'timeout': 5.0, 'method': 'GET', 'url': 'http://169.254.169.254/2016-09-02/meta-data/iam/info', 'headers': {'User-Agent': 'Cloud-Init/18.3-9-g2e62cb8a-0ubuntu1~16.04.2'}, 'allow_redirects': True} configuration
2019-05-18 15:40:05,367 - url_helper.py[DEBUG]: Read from http://169.254.169.254/2016-09-02/meta-data/iam/info (200, 246b) after 1 attempts
2019-05-18 15:40:05,367 - url_helper.py[DEBUG]: [0/6] open 'http://169.254.169.254/2016-09-02/meta-data/metrics/' with {'timeout': 5.0, 'method': 'GET', 'url': 'http://169.254.169.254/2016-09-02/meta-data/metrics/', 'headers': {'User-Agent': 'Cloud-Init/18.3-9-g2e62cb8a-0ubuntu1~16.04.2'}, 'allow_redirects': True} configuration
2019-05-18 15:40:05,369 - url_helper.py[DEBUG]: Read from http://169.254.169.254/2016-09-02/meta-data/metrics/ (200, 7b) after 1 attempts
2019-05-18 15:40:05,369 - url_helper.py[DEBUG]: [0/6] open 'http://169.254.169.254/2016-09-02/meta-data/metrics/vhostmd' with {'timeout': 5.0, 'method': 'GET', 'url': 'http://169.254.169.254/2016-09-02/meta-data/metrics/vhostmd', 'headers': {'User-Agent': 'Cloud-Init/18.3-9-g2e62cb8a-0ubuntu1~16.04.2'}, 'allow_redirects': True} configuration
2019-05-18 15:40:05,370 - url_helper.py[DEBUG]: Read from http://169.254.169.254/2016-09-02/meta-data/metrics/vhostmd (200, 38b) after 1 attempts
2019-05-18 15:40:05,370 - url_helper.py[DEBUG]: [0/6] open 'http://169.254.169.254/2016-09-02/meta-data/network/' with {'timeout': 5.0, 'method': 'GET', 'url': 'http://169.254.169.254/2016-09-02/meta-data/network/', 'headers': {'User-Agent': 'Cloud-Init/18.3-9-g2e62cb8a-0ubuntu1~16.04.2'}, 'allow_redirects': True} configuration
2019-05-18 15:40:05,372 - url_helper.py[DEBUG]: Read from http://169.254.169.254/2016-09-02/meta-data/network/ (200, 11b) after 1 attempts
2019-05-18 15:40:05,372 - url_helper.py[DEBUG]: [0/6] open 'http://169.254.169.254/2016-09-02/meta-data/network/interfaces/' with {'timeout': 5.0, 'method': 'GET', 'url': 'http://169.254.169.254/2016-09-02/meta-data/network/interfaces/', 'headers': {'User-Agent': 'Cloud-Init/18.3-9-g2e62cb8a-0ubuntu1~16.04.2'}, 'allow_redirects': True} configuration
2019-05-18 15:40:05,373 - url_helper.py[DEBUG]: Read from http://169.254.169.254/2016-09-02/meta-data/network/interfaces/ (200, 5b) after 1 attempts
2019-05-18 15:40:05,374 - url_helper.py[DEBUG]: [0/6] open 'http://169.254.169.254/2016-09-02/meta-data/network/interfaces/macs/' with {'timeout': 5.0, 'method': 'GET', 'url': 'http://169.254.169.254/2016-09-02/meta-data/network/interfaces/macs/', 'headers': {'User-Agent': 'Cloud-Init/18.3-9-g2e62cb8a-0ubuntu1~16.04.2'}, 'allow_redirects': True} configuration
2019-05-18 15:40:05,375 - url_helper.py[DEBUG]: Read from http://169.254.169.254/2016-09-02/meta-data/network/interfaces/macs/ (200, 18b) after 1 attempts
2019-05-18 15:40:05,375 - url_helper.py[DEBUG]: [0/6] open 'http://169.254.169.254/2016-09-02/meta-data/network/interfaces/macs/02:57:4d:d7:cf:40/' with {'timeout': 5.0, 'method': 'GET', 'url': 'http://169.254.169.254/2016-09-02/meta-data/network/interfaces/macs/02:57:4d:d7:cf:40/', 'headers': {'User-Agent': 'Cloud-Init/18.3-9-g2e62cb8a-0ubuntu1~16.04.2'}, 'allow_redirects': True} configuration
2019-05-18 15:40:05,377 - url_helper.py[DEBUG]: Read from http://169.254.169.254/2016-09-02/meta-data/network/interfaces/macs/02:57:4d:d7:cf:40/ (200, 230b) after 1 attempts
2019-05-18 15:40:05,377 - url_helper.py[DEBUG]: [0/6] open 'http://169.254.169.254/2016-09-02/meta-data/network/interfaces/macs/02:57:4d:d7:cf:40/ipv4-associations/' with {'timeout': 5.0, 'method': 'GET', 'url': 'http://169.254.169.254/2016-09-02/meta-data/network/interfaces/macs/02:57:4d:d7:cf:40/ipv4-associations/', 'headers': {'User-Agent': 'Cloud-Init/18.3-9-g2e62cb8a-0ubuntu1~16.04.2'}, 'allow_redirects': True} configuration
2019-05-18 15:40:05,379 - url_helper.py[DEBUG]: Read from http://169.254.169.254/2016-09-02/meta-data/network/interfaces/macs/02:57:4d:d7:cf:40/ipv4-associations/ (200, 13b) after 1 attempts
2019-05-18 15:40:05,379 - url_helper.py[DEBUG]: [0/6] open 'http://169.254.169.254/2016-09-02/meta-data/network/interfaces/macs/02:57:4d:d7:cf:40/ipv4-associations/54.171.156.22' with {'timeout': 5.0, 'method': 'GET', 'url': 'http://169.254.169.254/2016-09-02/meta-data/network/interfaces/macs/02:57:4d:d7:cf:40/ipv4-associations/54.171.156.22', 'headers': {'User-Agent': 'Cloud-Init/18.3-9-g2e62cb8a-0ubuntu1~16.04.2'}, 'allow_redirects': True} configuration
2019-05-18 15:40:05,380 - url_helper.py[DEBUG]: Read from http://169.254.169.254/2016-09-02/meta-data/network/interfaces/macs/02:57:4d:d7:cf:40/ipv4-associations/54.171.156.22 (200, 9b) after 1 attempts
2019-05-18 15:40:05,380 - url_helper.py[DEBUG]: [0/6] open 'http://169.254.169.254/2016-09-02/meta-data/network/interfaces/macs/02:57:4d:d7:cf:40/local-hostname' with {'timeout': 5.0, 'method': 'GET', 'url': 'http://169.254.169.254/2016-09-02/meta-data/network/interfaces/macs/02:57:4d:d7:cf:40/local-hostname', 'headers': {'User-Agent': 'Cloud-Init/18.3-9-g2e62cb8a-0ubuntu1~16.04.2'}, 'allow_redirects': True} configuration
2019-05-18 15:40:05,382 - url_helper.py[DEBUG]: Read from http://169.254.169.254/2016-09-02/meta-data/network/interfaces/macs/02:57:4d:d7:cf:40/local-hostname (200, 39b) after 1 attempts
2019-05-18 15:40:05,382 - url_helper.py[DEBUG]: [0/6] open 'http://169.254.169.254/2016-09-02/meta-data/network/interfaces/macs/02:57:4d:d7:cf:40/vpc-id' with {'timeout': 5.0, 'method': 'GET', 'url': 'http://169.254.169.254/2016-09-02/meta-data/network/interfaces/macs/02:57:4d:d7:cf:40/vpc-id', 'headers': {'User-Agent': 'Cloud-Init/18.3-9-g2e62cb8a-0ubuntu1~16.04.2'}, 'allow_redirects': True} configuration
2019-05-18 15:40:05,384 - url_helper.py[DEBUG]: Read from http://169.254.169.254/2016-09-02/meta-data/network/interfaces/macs/02:57:4d:d7:cf:40/vpc-id (200, 21b) after 1 attempts
2019-05-18 15:40:05,384 - url_helper.py[DEBUG]: [0/6] open 'http://169.254.169.254/2016-09-02/meta-data/network/interfaces/macs/02:57:4d:d7:cf:40/device-number' with {'timeout': 5.0, 'method': 'GET', 'url': 'http://169.254.169.254/2016-09-02/meta-data/network/interfaces/macs/02:57:4d:d7:cf:40/device-number', 'headers': {'User-Agent': 'Cloud-Init/18.3-9-g2e62cb8a-0ubuntu1~16.04.2'}, 'allow_redirects': True} configuration
2019-05-18 15:40:05,385 - url_helper.py[DEBUG]: Read from http://169.254.169.254/2016-09-02/meta-data/network/interfaces/macs/02:57:4d:d7:cf:40/device-number (200, 1b) after 1 attempts
2019-05-18 15:40:05,386 - url_helper.py[DEBUG]: [0/6] open 'http://169.254.169.254/2016-09-02/meta-data/network/interfaces/macs/02:57:4d:d7:cf:40/subnet-ipv4-cidr-block' with {'timeout': 5.0, 'method': 'GET', 'url': 'http://169.254.169.254/2016-09-02/meta-data/network/interfaces/macs/02:57:4d:d7:cf:40/subnet-ipv4-cidr-block', 'headers': {'User-Agent': 'Cloud-Init/18.3-9-g2e62cb8a-0ubuntu1~16.04.2'}, 'allow_redirects': True} configuration
2019-05-18 15:40:05,387 - url_helper.py[DEBUG]: Read from http://169.254.169.254/2016-09-02/meta-data/network/interfaces/macs/02:57:4d:d7:cf:40/subnet-ipv4-cidr-block (200, 11b) after 1 attempts
2019-05-18 15:40:05,387 - url_helper.py[DEBUG]: [0/6] open 'http://169.254.169.254/2016-09-02/meta-data/network/interfaces/macs/02:57:4d:d7:cf:40/security-group-ids' with {'timeout': 5.0, 'method': 'GET', 'url': 'http://169.254.169.254/2016-09-02/meta-data/network/interfaces/macs/02:57:4d:d7:cf:40/security-group-ids', 'headers': {'User-Agent': 'Cloud-Init/18.3-9-g2e62cb8a-0ubuntu1~16.04.2'}, 'allow_redirects': True} configuration
2019-05-18 15:40:05,389 - url_helper.py[DEBUG]: Read from http://169.254.169.254/2016-09-02/meta-data/network/interfaces/macs/02:57:4d:d7:cf:40/security-group-ids (200, 20b) after 1 attempts
2019-05-18 15:40:05,389 - url_helper.py[DEBUG]: [0/6] open 'http://169.254.169.254/2016-09-02/meta-data/network/interfaces/macs/02:57:4d:d7:cf:40/mac' with {'timeout': 5.0, 'method': 'GET', 'url': 'http://169.254.169.254/2016-09-02/meta-data/network/interfaces/macs/02:57:4d:d7:cf:40/mac', 'headers': {'User-Agent': 'Cloud-Init/18.3-9-g2e62cb8a-0ubuntu1~16.04.2'}, 'allow_redirects': True} configuration
2019-05-18 15:40:05,390 - url_helper.py[DEBUG]: Read from http://169.254.169.254/2016-09-02/meta-data/network/interfaces/macs/02:57:4d:d7:cf:40/mac (200, 17b) after 1 attempts
2019-05-18 15:40:05,391 - url_helper.py[DEBUG]: [0/6] open 'http://169.254.169.254/2016-09-02/meta-data/network/interfaces/macs/02:57:4d:d7:cf:40/owner-id' with {'timeout': 5.0, 'method': 'GET', 'url': 'http://169.254.169.254/2016-09-02/meta-data/network/interfaces/macs/02:57:4d:d7:cf:40/owner-id', 'headers': {'User-Agent': 'Cloud-Init/18.3-9-g2e62cb8a-0ubuntu1~16.04.2'}, 'allow_redirects': True} configuration
2019-05-18 15:40:05,392 - url_helper.py[DEBUG]: Read from http://169.254.169.254/2016-09-02/meta-data/network/interfaces/macs/02:57:4d:d7:cf:40/owner-id (200, 12b) after 1 attempts
2019-05-18 15:40:05,392 - url_helper.py[DEBUG]: [0/6] open 'http://169.254.169.254/2016-09-02/meta-data/network/interfaces/macs/02:57:4d:d7:cf:40/local-ipv4s' with {'timeout': 5.0, 'method': 'GET', 'url': 'http://169.254.169.254/2016-09-02/meta-data/network/interfaces/macs/02:57:4d:d7:cf:40/local-ipv4s', 'headers': {'User-Agent': 'Cloud-Init/18.3-9-g2e62cb8a-0ubuntu1~16.04.2'}, 'allow_redirects': True} configuration
2019-05-18 15:40:05,395 - url_helper.py[DEBUG]: Read from http://169.254.169.254/2016-09-02/meta-data/network/interfaces/macs/02:57:4d:d7:cf:40/local-ipv4s (200, 9b) after 1 attempts
2019-05-18 15:40:05,395 - url_helper.py[DEBUG]: [0/6] open 'http://169.254.169.254/2016-09-02/meta-data/network/interfaces/macs/02:57:4d:d7:cf:40/public-ipv4s' with {'timeout': 5.0, 'method': 'GET', 'url': 'http://169.254.169.254/2016-09-02/meta-data/network/interfaces/macs/02:57:4d:d7:cf:40/public-ipv4s', 'headers': {'User-Agent': 'Cloud-Init/18.3-9-g2e62cb8a-0ubuntu1~16.04.2'}, 'allow_redirects': True} configuration
2019-05-18 15:40:05,396 - url_helper.py[DEBUG]: Read from http://169.254.169.254/2016-09-02/meta-data/network/interfaces/macs/02:57:4d:d7:cf:40/public-ipv4s (200, 13b) after 1 attempts
2019-05-18 15:40:05,397 - url_helper.py[DEBUG]: [0/6] open 'http://169.254.169.254/2016-09-02/meta-data/network/interfaces/macs/02:57:4d:d7:cf:40/interface-id' with {'timeout': 5.0, 'method': 'GET', 'url': 'http://169.254.169.254/2016-09-02/meta-data/network/interfaces/macs/02:57:4d:d7:cf:40/interface-id', 'headers': {'User-Agent': 'Cloud-Init/18.3-9-g2e62cb8a-0ubuntu1~16.04.2'}, 'allow_redirects': True} configuration
2019-05-18 15:40:05,398 - url_helper.py[DEBUG]: Read from http://169.254.169.254/2016-09-02/meta-data/network/interfaces/macs/02:57:4d:d7:cf:40/interface-id (200, 21b) after 1 attempts
2019-05-18 15:40:05,398 - url_helper.py[DEBUG]: [0/6] open 'http://169.254.169.254/2016-09-02/meta-data/network/interfaces/macs/02:57:4d:d7:cf:40/subnet-id' with {'timeout': 5.0, 'method': 'GET', 'url': 'http://169.254.169.254/2016-09-02/meta-data/network/interfaces/macs/02:57:4d:d7:cf:40/subnet-id', 'headers': {'User-Agent': 'Cloud-Init/18.3-9-g2e62cb8a-0ubuntu1~16.04.2'}, 'allow_redirects': True} configuration
2019-05-18 15:40:05,400 - url_helper.py[DEBUG]: Read from http://169.254.169.254/2016-09-02/meta-data/network/interfaces/macs/02:57:4d:d7:cf:40/subnet-id (200, 24b) after 1 attempts
2019-05-18 15:40:05,400 - url_helper.py[DEBUG]: [0/6] open 'http://169.254.169.254/2016-09-02/meta-data/network/interfaces/macs/02:57:4d:d7:cf:40/vpc-ipv4-cidr-blocks' with {'timeout': 5.0, 'method': 'GET', 'url': 'http://169.254.169.254/2016-09-02/meta-data/network/interfaces/macs/02:57:4d:d7:cf:40/vpc-ipv4-cidr-blocks', 'headers': {'User-Agent': 'Cloud-Init/18.3-9-g2e62cb8a-0ubuntu1~16.04.2'}, 'allow_redirects': True} configuration
2019-05-18 15:40:05,401 - url_helper.py[DEBUG]: Read from http://169.254.169.254/2016-09-02/meta-data/network/interfaces/macs/02:57:4d:d7:cf:40/vpc-ipv4-cidr-blocks (200, 11b) after 1 attempts
2019-05-18 15:40:05,401 - url_helper.py[DEBUG]: [0/6] open 'http://169.254.169.254/2016-09-02/meta-data/network/interfaces/macs/02:57:4d:d7:cf:40/public-hostname' with {'timeout': 5.0, 'method': 'GET', 'url': 'http://169.254.169.254/2016-09-02/meta-data/network/interfaces/macs/02:57:4d:d7:cf:40/public-hostname', 'headers': {'User-Agent': 'Cloud-Init/18.3-9-g2e62cb8a-0ubuntu1~16.04.2'}, 'allow_redirects': True} configuration
2019-05-18 15:40:05,403 - url_helper.py[DEBUG]: Read from http://169.254.169.254/2016-09-02/meta-data/network/interfaces/macs/02:57:4d:d7:cf:40/public-hostname (200, 49b) after 1 attempts
2019-05-18 15:40:05,403 - url_helper.py[DEBUG]: [0/6] open 'http://169.254.169.254/2016-09-02/meta-data/network/interfaces/macs/02:57:4d:d7:cf:40/vpc-ipv4-cidr-block' with {'timeout': 5.0, 'method': 'GET', 'url': 'http://169.254.169.254/2016-09-02/meta-data/network/interfaces/macs/02:57:4d:d7:cf:40/vpc-ipv4-cidr-block', 'headers': {'User-Agent': 'Cloud-Init/18.3-9-g2e62cb8a-0ubuntu1~16.04.2'}, 'allow_redirects': True} configuration
2019-05-18 15:40:05,405 - url_helper.py[DEBUG]: Read from http://169.254.169.254/2016-09-02/meta-data/network/interfaces/macs/02:57:4d:d7:cf:40/vpc-ipv4-cidr-block (200, 11b) after 1 attempts
2019-05-18 15:40:05,405 - url_helper.py[DEBUG]: [0/6] open 'http://169.254.169.254/2016-09-02/meta-data/network/interfaces/macs/02:57:4d:d7:cf:40/security-groups' with {'timeout': 5.0, 'method': 'GET', 'url': 'http://169.254.169.254/2016-09-02/meta-data/network/interfaces/macs/02:57:4d:d7:cf:40/security-groups', 'headers': {'User-Agent': 'Cloud-Init/18.3-9-g2e62cb8a-0ubuntu1~16.04.2'}, 'allow_redirects': True} configuration
2019-05-18 15:40:05,406 - url_helper.py[DEBUG]: Read from http://169.254.169.254/2016-09-02/meta-data/network/interfaces/macs/02:57:4d:d7:cf:40/security-groups (200, 80b) after 1 attempts
2019-05-18 15:40:05,406 - url_helper.py[DEBUG]: [0/6] open 'http://169.254.169.254/2016-09-02/meta-data/placement/' with {'timeout': 5.0, 'method': 'GET', 'url': 'http://169.254.169.254/2016-09-02/meta-data/placement/', 'headers': {'User-Agent': 'Cloud-Init/18.3-9-g2e62cb8a-0ubuntu1~16.04.2'}, 'allow_redirects': True} configuration
2019-05-18 15:40:05,408 - url_helper.py[DEBUG]: Read from http://169.254.169.254/2016-09-02/meta-data/placement/ (200, 17b) after 1 attempts
2019-05-18 15:40:05,408 - url_helper.py[DEBUG]: [0/6] open 'http://169.254.169.254/2016-09-02/meta-data/placement/availability-zone' with {'timeout': 5.0, 'method': 'GET', 'url': 'http://169.254.169.254/2016-09-02/meta-data/placement/availability-zone', 'headers': {'User-Agent': 'Cloud-Init/18.3-9-g2e62cb8a-0ubuntu1~16.04.2'}, 'allow_redirects': True} configuration
2019-05-18 15:40:05,410 - url_helper.py[DEBUG]: Read from http://169.254.169.254/2016-09-02/meta-data/placement/availability-zone (200, 10b) after 1 attempts
2019-05-18 15:40:05,410 - url_helper.py[DEBUG]: [0/6] open 'http://169.254.169.254/2016-09-02/meta-data/public-keys/' with {'timeout': 5.0, 'method': 'GET', 'url': 'http://169.254.169.254/2016-09-02/meta-data/public-keys/', 'headers': {'User-Agent': 'Cloud-Init/18.3-9-g2e62cb8a-0ubuntu1~16.04.2'}, 'allow_redirects': True} configuration
2019-05-18 15:40:05,411 - url_helper.py[DEBUG]: Read from http://169.254.169.254/2016-09-02/meta-data/public-keys/ (200, 68b) after 1 attempts
2019-05-18 15:40:05,411 - url_helper.py[DEBUG]: [0/6] open 'http://169.254.169.254/2016-09-02/meta-data/public-keys/0/openssh-key' with {'timeout': 5.0, 'method': 'GET', 'url': 'http://169.254.169.254/2016-09-02/meta-data/public-keys/0/openssh-key', 'headers': {'User-Agent': 'Cloud-Init/18.3-9-g2e62cb8a-0ubuntu1~16.04.2'}, 'allow_redirects': True} configuration
2019-05-18 15:40:05,413 - url_helper.py[DEBUG]: Read from http://169.254.169.254/2016-09-02/meta-data/public-keys/0/openssh-key (200, 448b) after 1 attempts
2019-05-18 15:40:05,413 - url_helper.py[DEBUG]: [0/6] open 'http://169.254.169.254/2016-09-02/meta-data/services/' with {'timeout': 5.0, 'method': 'GET', 'url': 'http://169.254.169.254/2016-09-02/meta-data/services/', 'headers': {'User-Agent': 'Cloud-Init/18.3-9-g2e62cb8a-0ubuntu1~16.04.2'}, 'allow_redirects': True} configuration
2019-05-18 15:40:05,414 - url_helper.py[DEBUG]: Read from http://169.254.169.254/2016-09-02/meta-data/services/ (200, 16b) after 1 attempts
2019-05-18 15:40:05,415 - url_helper.py[DEBUG]: [0/6] open 'http://169.254.169.254/2016-09-02/meta-data/services/partition' with {'timeout': 5.0, 'method': 'GET', 'url': 'http://169.254.169.254/2016-09-02/meta-data/services/partition', 'headers': {'User-Agent': 'Cloud-Init/18.3-9-g2e62cb8a-0ubuntu1~16.04.2'}, 'allow_redirects': True} configuration
2019-05-18 15:40:05,416 - url_helper.py[DEBUG]: Read from http://169.254.169.254/2016-09-02/meta-data/services/partition (200, 3b) after 1 attempts
2019-05-18 15:40:05,416 - url_helper.py[DEBUG]: [0/6] open 'http://169.254.169.254/2016-09-02/meta-data/services/domain' with {'timeout': 5.0, 'method': 'GET', 'url': 'http://169.254.169.254/2016-09-02/meta-data/services/domain', 'headers': {'User-Agent': 'Cloud-Init/18.3-9-g2e62cb8a-0ubuntu1~16.04.2'}, 'allow_redirects': True} configuration
2019-05-18 15:40:05,418 - url_helper.py[DEBUG]: Read from http://169.254.169.254/2016-09-02/meta-data/services/domain (200, 13b) after 1 attempts
2019-05-18 15:40:05,418 - url_helper.py[DEBUG]: [0/6] open 'http://169.254.169.254/2016-09-02/meta-data/local-ipv4' with {'timeout': 5.0, 'method': 'GET', 'url': 'http://169.254.169.254/2016-09-02/meta-data/local-ipv4', 'headers': {'User-Agent': 'Cloud-Init/18.3-9-g2e62cb8a-0ubuntu1~16.04.2'}, 'allow_redirects': True} configuration
2019-05-18 15:40:05,419 - url_helper.py[DEBUG]: Read from http://169.254.169.254/2016-09-02/meta-data/local-ipv4 (200, 9b) after 1 attempts
2019-05-18 15:40:05,419 - url_helper.py[DEBUG]: [0/6] open 'http://169.254.169.254/2016-09-02/meta-data/hostname' with {'timeout': 5.0, 'method': 'GET', 'url': 'http://169.254.169.254/2016-09-02/meta-data/hostname', 'headers': {'User-Agent': 'Cloud-Init/18.3-9-g2e62cb8a-0ubuntu1~16.04.2'}, 'allow_redirects': True} configuration
2019-05-18 15:40:05,421 - url_helper.py[DEBUG]: Read from http://169.254.169.254/2016-09-02/meta-data/hostname (200, 39b) after 1 attempts
2019-05-18 15:40:05,421 - url_helper.py[DEBUG]: [0/6] open 'http://169.254.169.254/2016-09-02/meta-data/instance-action' with {'timeout': 5.0, 'method': 'GET', 'url': 'http://169.254.169.254/2016-09-02/meta-data/instance-action', 'headers': {'User-Agent': 'Cloud-Init/18.3-9-g2e62cb8a-0ubuntu1~16.04.2'}, 'allow_redirects': True} configuration
2019-05-18 15:40:05,423 - url_helper.py[DEBUG]: Read from http://169.254.169.254/2016-09-02/meta-data/instance-action (200, 4b) after 1 attempts
2019-05-18 15:40:05,423 - url_helper.py[DEBUG]: [0/6] open 'http://169.254.169.254/2016-09-02/meta-data/reservation-id' with {'timeout': 5.0, 'method': 'GET', 'url': 'http://169.254.169.254/2016-09-02/meta-data/reservation-id', 'headers': {'User-Agent': 'Cloud-Init/18.3-9-g2e62cb8a-0ubuntu1~16.04.2'}, 'allow_redirects': True} configuration
2019-05-18 15:40:05,424 - url_helper.py[DEBUG]: Read from http://169.254.169.254/2016-09-02/meta-data/reservation-id (200, 19b) after 1 attempts
2019-05-18 15:40:05,424 - url_helper.py[DEBUG]: [0/6] open 'http://169.254.169.254/2016-09-02/meta-data/ami-launch-index' with {'timeout': 5.0, 'method': 'GET', 'url': 'http://169.254.169.254/2016-09-02/meta-data/ami-launch-index', 'headers': {'User-Agent': 'Cloud-Init/18.3-9-g2e62cb8a-0ubuntu1~16.04.2'}, 'allow_redirects': True} configuration
2019-05-18 15:40:05,426 - url_helper.py[DEBUG]: Read from http://169.254.169.254/2016-09-02/meta-data/ami-launch-index (200, 1b) after 1 attempts
2019-05-18 15:40:05,426 - url_helper.py[DEBUG]: [0/6] open 'http://169.254.169.254/2016-09-02/meta-data/local-hostname' with {'timeout': 5.0, 'method': 'GET', 'url': 'http://169.254.169.254/2016-09-02/meta-data/local-hostname', 'headers': {'User-Agent': 'Cloud-Init/18.3-9-g2e62cb8a-0ubuntu1~16.04.2'}, 'allow_redirects': True} configuration
2019-05-18 15:40:05,427 - url_helper.py[DEBUG]: Read from http://169.254.169.254/2016-09-02/meta-data/local-hostname (200, 39b) after 1 attempts
2019-05-18 15:40:05,428 - url_helper.py[DEBUG]: [0/6] open 'http://169.254.169.254/2016-09-02/meta-data/instance-id' with {'timeout': 5.0, 'method': 'GET', 'url': 'http://169.254.169.254/2016-09-02/meta-data/instance-id', 'headers': {'User-Agent': 'Cloud-Init/18.3-9-g2e62cb8a-0ubuntu1~16.04.2'}, 'allow_redirects': True} configuration
2019-05-18 15:40:05,429 - url_helper.py[DEBUG]: Read from http://169.254.169.254/2016-09-02/meta-data/instance-id (200, 19b) after 1 attempts
2019-05-18 15:40:05,429 - url_helper.py[DEBUG]: [0/6] open 'http://169.254.169.254/2016-09-02/meta-data/mac' with {'timeout': 5.0, 'method': 'GET', 'url': 'http://169.254.169.254/2016-09-02/meta-data/mac', 'headers': {'User-Agent': 'Cloud-Init/18.3-9-g2e62cb8a-0ubuntu1~16.04.2'}, 'allow_redirects': True} configuration
2019-05-18 15:40:05,431 - url_helper.py[DEBUG]: Read from http://169.254.169.254/2016-09-02/meta-data/mac (200, 17b) after 1 attempts
2019-05-18 15:40:05,431 - url_helper.py[DEBUG]: [0/6] open 'http://169.254.169.254/2016-09-02/meta-data/public-ipv4' with {'timeout': 5.0, 'method': 'GET', 'url': 'http://169.254.169.254/2016-09-02/meta-data/public-ipv4', 'headers': {'User-Agent': 'Cloud-Init/18.3-9-g2e62cb8a-0ubuntu1~16.04.2'}, 'allow_redirects': True} configuration
2019-05-18 15:40:05,432 - url_helper.py[DEBUG]: Read from http://169.254.169.254/2016-09-02/meta-data/public-ipv4 (200, 13b) after 1 attempts
2019-05-18 15:40:05,432 - url_helper.py[DEBUG]: [0/6] open 'http://169.254.169.254/2016-09-02/meta-data/ami-manifest-path' with {'timeout': 5.0, 'method': 'GET', 'url': 'http://169.254.169.254/2016-09-02/meta-data/ami-manifest-path', 'headers': {'User-Agent': 'Cloud-Init/18.3-9-g2e62cb8a-0ubuntu1~16.04.2'}, 'allow_redirects': True} configuration
2019-05-18 15:40:05,434 - url_helper.py[DEBUG]: Read from http://169.254.169.254/2016-09-02/meta-data/ami-manifest-path (200, 9b) after 1 attempts
2019-05-18 15:40:05,434 - url_helper.py[DEBUG]: [0/6] open 'http://169.254.169.254/2016-09-02/meta-data/ami-id' with {'timeout': 5.0, 'method': 'GET', 'url': 'http://169.254.169.254/2016-09-02/meta-data/ami-id', 'headers': {'User-Agent': 'Cloud-Init/18.3-9-g2e62cb8a-0ubuntu1~16.04.2'}, 'allow_redirects': True} configuration
2019-05-18 15:40:05,436 - url_helper.py[DEBUG]: Read from http://169.254.169.254/2016-09-02/meta-data/ami-id (200, 21b) after 1 attempts
2019-05-18 15:40:05,436 - url_helper.py[DEBUG]: [0/6] open 'http://169.254.169.254/2016-09-02/meta-data/public-hostname' with {'timeout': 5.0, 'method': 'GET', 'url': 'http://169.254.169.254/2016-09-02/meta-data/public-hostname', 'headers': {'User-Agent': 'Cloud-Init/18.3-9-g2e62cb8a-0ubuntu1~16.04.2'}, 'allow_redirects': True} configuration
2019-05-18 15:40:05,437 - url_helper.py[DEBUG]: Read from http://169.254.169.254/2016-09-02/meta-data/public-hostname (200, 49b) after 1 attempts
2019-05-18 15:40:05,437 - url_helper.py[DEBUG]: [0/6] open 'http://169.254.169.254/2016-09-02/meta-data/profile' with {'timeout': 5.0, 'method': 'GET', 'url': 'http://169.254.169.254/2016-09-02/meta-data/profile', 'headers': {'User-Agent': 'Cloud-Init/18.3-9-g2e62cb8a-0ubuntu1~16.04.2'}, 'allow_redirects': True} configuration
2019-05-18 15:40:05,439 - url_helper.py[DEBUG]: Read from http://169.254.169.254/2016-09-02/meta-data/profile (200, 11b) after 1 attempts
2019-05-18 15:40:05,439 - url_helper.py[DEBUG]: [0/6] open 'http://169.254.169.254/2016-09-02/meta-data/security-groups' with {'timeout': 5.0, 'method': 'GET', 'url': 'http://169.254.169.254/2016-09-02/meta-data/security-groups', 'headers': {'User-Agent': 'Cloud-Init/18.3-9-g2e62cb8a-0ubuntu1~16.04.2'}, 'allow_redirects': True} configuration
2019-05-18 15:40:05,440 - url_helper.py[DEBUG]: Read from http://169.254.169.254/2016-09-02/meta-data/security-groups (200, 80b) after 1 attempts
2019-05-18 15:40:05,441 - url_helper.py[DEBUG]: [0/6] open 'http://169.254.169.254/2016-09-02/meta-data/instance-type' with {'timeout': 5.0, 'method': 'GET', 'url': 'http://169.254.169.254/2016-09-02/meta-data/instance-type', 'headers': {'User-Agent': 'Cloud-Init/18.3-9-g2e62cb8a-0ubuntu1~16.04.2'}, 'allow_redirects': True} configuration
2019-05-18 15:40:05,442 - url_helper.py[DEBUG]: Read from http://169.254.169.254/2016-09-02/meta-data/instance-type (200, 10b) after 1 attempts
2019-05-18 15:40:05,442 - url_helper.py[DEBUG]: [0/6] open 'http://169.254.169.254/2016-09-02/dynamic/instance-identity' with {'timeout': 5.0, 'method': 'GET', 'url': 'http://169.254.169.254/2016-09-02/dynamic/instance-identity', 'headers': {'User-Agent': 'Cloud-Init/18.3-9-g2e62cb8a-0ubuntu1~16.04.2'}, 'allow_redirects': True} configuration
2019-05-18 15:40:05,445 - url_helper.py[DEBUG]: Read from http://169.254.169.254/2016-09-02/dynamic/instance-identity (200, 33b) after 1 attempts
2019-05-18 15:40:05,445 - url_helper.py[DEBUG]: [0/6] open 'http://169.254.169.254/2016-09-02/dynamic/instance-identity/document' with {'timeout': 5.0, 'method': 'GET', 'url': 'http://169.254.169.254/2016-09-02/dynamic/instance-identity/document', 'headers': {'User-Agent': 'Cloud-Init/18.3-9-g2e62cb8a-0ubuntu1~16.04.2'}, 'allow_redirects': True} configuration
2019-05-18 15:40:05,446 - url_helper.py[DEBUG]: Read from http://169.254.169.254/2016-09-02/dynamic/instance-identity/document (200, 475b) after 1 attempts
2019-05-18 15:40:05,447 - url_helper.py[DEBUG]: [0/6] open 'http://169.254.169.254/2016-09-02/dynamic/instance-identity/rsa2048' with {'timeout': 5.0, 'method': 'GET', 'url': 'http://169.254.169.254/2016-09-02/dynamic/instance-identity/rsa2048', 'headers': {'User-Agent': 'Cloud-Init/18.3-9-g2e62cb8a-0ubuntu1~16.04.2'}, 'allow_redirects': True} configuration
2019-05-18 15:40:05,448 - url_helper.py[DEBUG]: Read from http://169.254.169.254/2016-09-02/dynamic/instance-identity/rsa2048 (200, 1434b) after 1 attempts
2019-05-18 15:40:05,448 - url_helper.py[DEBUG]: [0/6] open 'http://169.254.169.254/2016-09-02/dynamic/instance-identity/pkcs7' with {'timeout': 5.0, 'method': 'GET', 'url': 'http://169.254.169.254/2016-09-02/dynamic/instance-identity/pkcs7', 'headers': {'User-Agent': 'Cloud-Init/18.3-9-g2e62cb8a-0ubuntu1~16.04.2'}, 'allow_redirects': True} configuration
2019-05-18 15:40:05,450 - url_helper.py[DEBUG]: Read from http://169.254.169.254/2016-09-02/dynamic/instance-identity/pkcs7 (200, 1114b) after 1 attempts
2019-05-18 15:40:05,450 - url_helper.py[DEBUG]: [0/6] open 'http://169.254.169.254/2016-09-02/dynamic/instance-identity/signature' with {'timeout': 5.0, 'method': 'GET', 'url': 'http://169.254.169.254/2016-09-02/dynamic/instance-identity/signature', 'headers': {'User-Agent': 'Cloud-Init/18.3-9-g2e62cb8a-0ubuntu1~16.04.2'}, 'allow_redirects': True} configuration
2019-05-18 15:40:05,451 - url_helper.py[DEBUG]: Read from http://169.254.169.254/2016-09-02/dynamic/instance-identity/signature (200, 174b) after 1 attempts
2019-05-18 15:40:05,451 - util.py[DEBUG]: Crawl of metadata service took 0.109 seconds
2019-05-18 15:40:05,451 - util.py[DEBUG]: Running command ['ip', '-4', 'route', 'del', 'default', 'dev', 'ens3'] with allowed return codes [0] (shell=False, capture=True)
2019-05-18 15:40:05,453 - util.py[DEBUG]: Running command ['ip', '-family', 'inet', 'link', 'set', 'dev', 'ens3', 'down'] with allowed return codes [0] (shell=False, capture=True)
2019-05-18 15:40:05,489 - util.py[DEBUG]: Running command ['ip', '-family', 'inet', 'addr', 'del', '10.0.0.17/24', 'dev', 'ens3'] with allowed return codes [0] (shell=False, capture=True)
2019-05-18 15:40:05,492 - handlers.py[DEBUG]: finish: init-local/search-Ec2Local: SUCCESS: found local data from DataSourceEc2Local
2019-05-18 15:40:05,492 - stages.py[INFO]: Loaded datasource DataSourceEc2Local - DataSourceEc2Local
2019-05-18 15:40:05,493 - util.py[DEBUG]: Reading from /etc/cloud/cloud.cfg (quiet=False)
2019-05-18 15:40:05,493 - util.py[DEBUG]: Read 3169 bytes from /etc/cloud/cloud.cfg
2019-05-18 15:40:05,493 - util.py[DEBUG]: Attempting to load yaml from string of length 3169 with allowed root types (<class 'dict'>,)
2019-05-18 15:40:05,504 - util.py[DEBUG]: Reading from /etc/cloud/cloud.cfg.d/90_dpkg.cfg (quiet=False)
2019-05-18 15:40:05,504 - util.py[DEBUG]: Read 238 bytes from /etc/cloud/cloud.cfg.d/90_dpkg.cfg
2019-05-18 15:40:05,504 - util.py[DEBUG]: Attempting to load yaml from string of length 238 with allowed root types (<class 'dict'>,)
2019-05-18 15:40:05,505 - util.py[DEBUG]: Reading from /etc/cloud/cloud.cfg.d/05_logging.cfg (quiet=False)
2019-05-18 15:40:05,505 - util.py[DEBUG]: Read 2057 bytes from /etc/cloud/cloud.cfg.d/05_logging.cfg
2019-05-18 15:40:05,505 - util.py[DEBUG]: Attempting to load yaml from string of length 2057 with allowed root types (<class 'dict'>,)
2019-05-18 15:40:05,509 - util.py[DEBUG]: Reading from /run/cloud-init/cloud.cfg (quiet=False)
2019-05-18 15:40:05,509 - util.py[DEBUG]: Read 44 bytes from /run/cloud-init/cloud.cfg
2019-05-18 15:40:05,509 - util.py[DEBUG]: Attempting to load yaml from string of length 44 with allowed root types (<class 'dict'>,)
2019-05-18 15:40:05,510 - util.py[DEBUG]: Attempting to load yaml from string of length 0 with allowed root types (<class 'dict'>,)
2019-05-18 15:40:05,510 - util.py[DEBUG]: loaded blob returned None, returning default.
2019-05-18 15:40:05,510 - util.py[DEBUG]: Attempting to remove /var/lib/cloud/instance
2019-05-18 15:40:05,510 - util.py[DEBUG]: Creating symbolic link from '/var/lib/cloud/instance' => '/var/lib/cloud/instances/i-0bb244a52030111dc'
2019-05-18 15:40:05,511 - util.py[DEBUG]: Reading from /var/lib/cloud/instances/i-0bb244a52030111dc/datasource (quiet=False)
2019-05-18 15:40:05,511 - util.py[DEBUG]: Writing to /var/lib/cloud/instances/i-0bb244a52030111dc/datasource - wb: [644] 39 bytes
2019-05-18 15:40:05,512 - util.py[DEBUG]: Writing to /var/lib/cloud/data/previous-datasource - wb: [644] 39 bytes
2019-05-18 15:40:05,512 - util.py[DEBUG]: Reading from /var/lib/cloud/data/instance-id (quiet=False)
2019-05-18 15:40:05,512 - stages.py[DEBUG]: previous iid found to be NO_PREVIOUS_INSTANCE_ID
2019-05-18 15:40:05,512 - util.py[DEBUG]: Writing to /var/lib/cloud/data/instance-id - wb: [644] 20 bytes
2019-05-18 15:40:05,512 - util.py[DEBUG]: Writing to /run/cloud-init/.instance-id - wb: [644] 20 bytes
2019-05-18 15:40:05,513 - util.py[DEBUG]: Writing to /var/lib/cloud/data/previous-instance-id - wb: [644] 24 bytes
2019-05-18 15:40:05,514 - util.py[DEBUG]: Writing to /var/lib/cloud/instance/obj.pkl - wb: [400] 9125 bytes
2019-05-18 15:40:05,514 - main.py[DEBUG]: [local] init will now be targeting instance id: i-0bb244a52030111dc. new=True
2019-05-18 15:40:05,514 - util.py[DEBUG]: Reading from /etc/cloud/cloud.cfg (quiet=False)
2019-05-18 15:40:05,514 - util.py[DEBUG]: Read 3169 bytes from /etc/cloud/cloud.cfg
2019-05-18 15:40:05,514 - util.py[DEBUG]: Attempting to load yaml from string of length 3169 with allowed root types (<class 'dict'>,)
2019-05-18 15:40:05,525 - util.py[DEBUG]: Reading from /etc/cloud/cloud.cfg.d/90_dpkg.cfg (quiet=False)
2019-05-18 15:40:05,525 - util.py[DEBUG]: Read 238 bytes from /etc/cloud/cloud.cfg.d/90_dpkg.cfg
2019-05-18 15:40:05,525 - util.py[DEBUG]: Attempting to load yaml from string of length 238 with allowed root types (<class 'dict'>,)
2019-05-18 15:40:05,526 - util.py[DEBUG]: Reading from /etc/cloud/cloud.cfg.d/05_logging.cfg (quiet=False)
2019-05-18 15:40:05,526 - util.py[DEBUG]: Read 2057 bytes from /etc/cloud/cloud.cfg.d/05_logging.cfg
2019-05-18 15:40:05,526 - util.py[DEBUG]: Attempting to load yaml from string of length 2057 with allowed root types (<class 'dict'>,)
2019-05-18 15:40:05,529 - util.py[DEBUG]: Reading from /run/cloud-init/cloud.cfg (quiet=False)
2019-05-18 15:40:05,530 - util.py[DEBUG]: Read 44 bytes from /run/cloud-init/cloud.cfg
2019-05-18 15:40:05,530 - util.py[DEBUG]: Attempting to load yaml from string of length 44 with allowed root types (<class 'dict'>,)
2019-05-18 15:40:05,530 - util.py[DEBUG]: Attempting to load yaml from string of length 0 with allowed root types (<class 'dict'>,)
2019-05-18 15:40:05,530 - util.py[DEBUG]: loaded blob returned None, returning default.
2019-05-18 15:40:05,531 - stages.py[DEBUG]: Using distro class <class 'cloudinit.distros.ubuntu.Distro'>
2019-05-18 15:40:05,532 - cc_set_hostname.py[DEBUG]: Setting the hostname to ip-10-0-0-17.eu-west-1.compute.internal (ip-10-0-0-17)
2019-05-18 15:40:05,532 - util.py[DEBUG]: Reading from /etc/hostname (quiet=False)
2019-05-18 15:40:05,532 - util.py[DEBUG]: Read 7 bytes from /etc/hostname
2019-05-18 15:40:05,532 - util.py[DEBUG]: Writing to /etc/hostname - wb: [644] 13 bytes
2019-05-18 15:40:05,532 - __init__.py[DEBUG]: Non-persistently setting the system hostname to ip-10-0-0-17
2019-05-18 15:40:05,532 - util.py[DEBUG]: Running command ['hostname', 'ip-10-0-0-17'] with allowed return codes [0] (shell=False, capture=True)
2019-05-18 15:40:05,535 - util.py[DEBUG]: Reading from /sys/class/net/ens3/address (quiet=False)
2019-05-18 15:40:05,535 - util.py[DEBUG]: Read 18 bytes from /sys/class/net/ens3/address
2019-05-18 15:40:05,536 - stages.py[DEBUG]: applying net config names for {'version': 1, 'config': [{'type': 'physical', 'mac_address': '02:57:4d:d7:cf:40', 'subnets': [{'type': 'dhcp4'}], 'name': 'ens3'}]}
2019-05-18 15:40:05,536 - util.py[DEBUG]: Reading from /sys/class/net/ens3/device/device (quiet=False)
2019-05-18 15:40:05,536 - util.py[DEBUG]: Read 7 bytes from /sys/class/net/ens3/device/device
2019-05-18 15:40:05,536 - util.py[DEBUG]: Reading from /sys/class/net/lo/addr_assign_type (quiet=False)
2019-05-18 15:40:05,536 - util.py[DEBUG]: Read 2 bytes from /sys/class/net/lo/addr_assign_type
2019-05-18 15:40:05,536 - util.py[DEBUG]: Reading from /sys/class/net/lo/uevent (quiet=False)
2019-05-18 15:40:05,536 - util.py[DEBUG]: Read 23 bytes from /sys/class/net/lo/uevent
2019-05-18 15:40:05,536 - util.py[DEBUG]: Reading from /sys/class/net/lo/address (quiet=False)
2019-05-18 15:40:05,536 - util.py[DEBUG]: Read 18 bytes from /sys/class/net/lo/address
2019-05-18 15:40:05,536 - util.py[DEBUG]: Reading from /sys/class/net/lo/device/device (quiet=False)
2019-05-18 15:40:05,536 - util.py[DEBUG]: Reading from /sys/class/net/ens3/addr_assign_type (quiet=False)
2019-05-18 15:40:05,537 - util.py[DEBUG]: Read 2 bytes from /sys/class/net/ens3/addr_assign_type
2019-05-18 15:40:05,537 - util.py[DEBUG]: Reading from /sys/class/net/ens3/uevent (quiet=False)
2019-05-18 15:40:05,537 - util.py[DEBUG]: Read 25 bytes from /sys/class/net/ens3/uevent
2019-05-18 15:40:05,537 - util.py[DEBUG]: Reading from /sys/class/net/ens3/address (quiet=False)
2019-05-18 15:40:05,537 - util.py[DEBUG]: Read 18 bytes from /sys/class/net/ens3/address
2019-05-18 15:40:05,537 - util.py[DEBUG]: Reading from /sys/class/net/ens3/device/device (quiet=False)
2019-05-18 15:40:05,537 - util.py[DEBUG]: Read 7 bytes from /sys/class/net/ens3/device/device
2019-05-18 15:40:05,537 - util.py[DEBUG]: Reading from /sys/class/net/lo/operstate (quiet=False)
2019-05-18 15:40:05,537 - util.py[DEBUG]: Read 8 bytes from /sys/class/net/lo/operstate
2019-05-18 15:40:05,537 - util.py[DEBUG]: Reading from /sys/class/net/ens3/operstate (quiet=False)
2019-05-18 15:40:05,537 - util.py[DEBUG]: Read 5 bytes from /sys/class/net/ens3/operstate
2019-05-18 15:40:05,537 - util.py[DEBUG]: Running command ['ip', '-6', 'addr', 'show', 'permanent', 'scope', 'global'] with allowed return codes [0] (shell=False, capture=True)
2019-05-18 15:40:05,540 - util.py[DEBUG]: Running command ['ip', '-4', 'addr', 'show'] with allowed return codes [0] (shell=False, capture=True)
2019-05-18 15:40:05,542 - __init__.py[DEBUG]: no work necessary for renaming of [['02:57:4d:d7:cf:40', 'ens3', 'ixgbevf', '0x10ed']]
2019-05-18 15:40:05,542 - stages.py[INFO]: Applying network configuration from ds bringup=False: {'version': 1, 'config': [{'type': 'physical', 'mac_address': '02:57:4d:d7:cf:40', 'subnets': [{'type': 'dhcp4'}], 'name': 'ens3'}]}
2019-05-18 15:40:05,542 - __init__.py[DEBUG]: Selected renderer 'eni' from priority list: None
2019-05-18 15:40:05,544 - util.py[DEBUG]: Writing to /etc/network/interfaces.d/50-cloud-init.cfg - wb: [644] 367 bytes
2019-05-18 15:40:05,545 - util.py[DEBUG]: Writing to /etc/udev/rules.d/70-persistent-net.rules - wb: [644] 96 bytes
2019-05-18 15:40:05,545 - main.py[DEBUG]: [local] Exiting. datasource DataSourceEc2Local not in local mode.
2019-05-18 15:40:05,546 - util.py[DEBUG]: Reading from /proc/uptime (quiet=False)
2019-05-18 15:40:05,546 - util.py[DEBUG]: Read 12 bytes from /proc/uptime
2019-05-18 15:40:05,546 - util.py[DEBUG]: cloud-init mode 'init' took 0.564 seconds (0.57)
2019-05-18 15:40:05,546 - handlers.py[DEBUG]: finish: init-local: SUCCESS: searching for local datasources
2019-05-18 15:40:06,018 - util.py[DEBUG]: Cloud-init v. 18.3-9-g2e62cb8a-0ubuntu1~16.04.2 running 'init' at Sat, 18 May 2019 15:40:05 +0000. Up 7.53 seconds.
2019-05-18 15:40:06,018 - main.py[DEBUG]: No kernel command line url found.
2019-05-18 15:40:06,018 - main.py[DEBUG]: Closing stdin.
2019-05-18 15:40:06,020 - util.py[DEBUG]: Writing to /var/log/cloud-init.log - ab: [644] 0 bytes
2019-05-18 15:40:06,020 - util.py[DEBUG]: Changing the ownership of /var/log/cloud-init.log to 104:4
2019-05-18 15:40:06,021 - util.py[DEBUG]: Running command ['ip', 'addr', 'show'] with allowed return codes [0] (shell=False, capture=True)
2019-05-18 15:40:06,023 - util.py[DEBUG]: Running command ['ip', '-o', 'route', 'list'] with allowed return codes [0] (shell=False, capture=True)
2019-05-18 15:40:06,025 - util.py[DEBUG]: Running command ['ip', '--oneline', '-6', 'route', 'list', 'table', 'all'] with allowed return codes [0, 1] (shell=False, capture=True)
2019-05-18 15:40:06,034 - main.py[DEBUG]: Checking to see if files that we need already exist from a previous run that would allow us to stop early.
2019-05-18 15:40:06,034 - main.py[DEBUG]: Execution continuing, no previous run detected that would allow us to stop early.
2019-05-18 15:40:06,034 - handlers.py[DEBUG]: start: init-network/check-cache: attempting to read from cache [trust]
2019-05-18 15:40:06,034 - util.py[DEBUG]: Reading from /var/lib/cloud/instance/obj.pkl (quiet=False)
2019-05-18 15:40:06,035 - util.py[DEBUG]: Read 9125 bytes from /var/lib/cloud/instance/obj.pkl
2019-05-18 15:40:06,037 - util.py[DEBUG]: Reading from /run/cloud-init/.instance-id (quiet=False)
2019-05-18 15:40:06,037 - util.py[DEBUG]: Read 20 bytes from /run/cloud-init/.instance-id
2019-05-18 15:40:06,037 - stages.py[DEBUG]: restored from cache with run check: DataSourceEc2Local
2019-05-18 15:40:06,037 - handlers.py[DEBUG]: finish: init-network/check-cache: SUCCESS: restored from cache with run check: DataSourceEc2Local
2019-05-18 15:40:06,037 - util.py[DEBUG]: Reading from /etc/cloud/cloud.cfg (quiet=False)
2019-05-18 15:40:06,038 - util.py[DEBUG]: Read 3169 bytes from /etc/cloud/cloud.cfg
2019-05-18 15:40:06,038 - util.py[DEBUG]: Attempting to load yaml from string of length 3169 with allowed root types (<class 'dict'>,)
2019-05-18 15:40:06,049 - util.py[DEBUG]: Reading from /etc/cloud/cloud.cfg.d/90_dpkg.cfg (quiet=False)
2019-05-18 15:40:06,049 - util.py[DEBUG]: Read 238 bytes from /etc/cloud/cloud.cfg.d/90_dpkg.cfg
2019-05-18 15:40:06,049 - util.py[DEBUG]: Attempting to load yaml from string of length 238 with allowed root types (<class 'dict'>,)
2019-05-18 15:40:06,050 - util.py[DEBUG]: Reading from /etc/cloud/cloud.cfg.d/05_logging.cfg (quiet=False)
2019-05-18 15:40:06,050 - util.py[DEBUG]: Read 2057 bytes from /etc/cloud/cloud.cfg.d/05_logging.cfg
2019-05-18 15:40:06,050 - util.py[DEBUG]: Attempting to load yaml from string of length 2057 with allowed root types (<class 'dict'>,)
2019-05-18 15:40:06,053 - util.py[DEBUG]: Reading from /run/cloud-init/cloud.cfg (quiet=False)
2019-05-18 15:40:06,054 - util.py[DEBUG]: Read 44 bytes from /run/cloud-init/cloud.cfg
2019-05-18 15:40:06,054 - util.py[DEBUG]: Attempting to load yaml from string of length 44 with allowed root types (<class 'dict'>,)
2019-05-18 15:40:06,054 - util.py[DEBUG]: Attempting to load yaml from string of length 0 with allowed root types (<class 'dict'>,)
2019-05-18 15:40:06,054 - util.py[DEBUG]: loaded blob returned None, returning default.
2019-05-18 15:40:06,055 - util.py[DEBUG]: Attempting to remove /var/lib/cloud/instance
2019-05-18 15:40:06,055 - util.py[DEBUG]: Creating symbolic link from '/var/lib/cloud/instance' => '/var/lib/cloud/instances/i-0bb244a52030111dc'
2019-05-18 15:40:06,055 - util.py[DEBUG]: Reading from /var/lib/cloud/instances/i-0bb244a52030111dc/datasource (quiet=False)
2019-05-18 15:40:06,055 - util.py[DEBUG]: Read 39 bytes from /var/lib/cloud/instances/i-0bb244a52030111dc/datasource
2019-05-18 15:40:06,055 - util.py[DEBUG]: Writing to /var/lib/cloud/instances/i-0bb244a52030111dc/datasource - wb: [644] 39 bytes
2019-05-18 15:40:06,056 - util.py[DEBUG]: Writing to /var/lib/cloud/data/previous-datasource - wb: [644] 39 bytes
2019-05-18 15:40:06,056 - util.py[DEBUG]: Reading from /var/lib/cloud/data/instance-id (quiet=False)
2019-05-18 15:40:06,056 - util.py[DEBUG]: Read 20 bytes from /var/lib/cloud/data/instance-id
2019-05-18 15:40:06,056 - stages.py[DEBUG]: previous iid found to be i-0bb244a52030111dc
2019-05-18 15:40:06,056 - util.py[DEBUG]: Writing to /var/lib/cloud/data/instance-id - wb: [644] 20 bytes
2019-05-18 15:40:06,057 - util.py[DEBUG]: Writing to /run/cloud-init/.instance-id - wb: [644] 20 bytes
2019-05-18 15:40:06,057 - util.py[DEBUG]: Writing to /var/lib/cloud/data/previous-instance-id - wb: [644] 20 bytes
2019-05-18 15:40:06,058 - util.py[DEBUG]: Writing to /var/lib/cloud/instance/obj.pkl - wb: [400] 9195 bytes
2019-05-18 15:40:06,058 - main.py[DEBUG]: [net] init will now be targeting instance id: i-0bb244a52030111dc. new=False
2019-05-18 15:40:06,058 - util.py[DEBUG]: Reading from /etc/cloud/cloud.cfg (quiet=False)
2019-05-18 15:40:06,058 - util.py[DEBUG]: Read 3169 bytes from /etc/cloud/cloud.cfg
2019-05-18 15:40:06,058 - util.py[DEBUG]: Attempting to load yaml from string of length 3169 with allowed root types (<class 'dict'>,)
2019-05-18 15:40:06,068 - util.py[DEBUG]: Reading from /etc/cloud/cloud.cfg.d/90_dpkg.cfg (quiet=False)
2019-05-18 15:40:06,068 - util.py[DEBUG]: Read 238 bytes from /etc/cloud/cloud.cfg.d/90_dpkg.cfg
2019-05-18 15:40:06,068 - util.py[DEBUG]: Attempting to load yaml from string of length 238 with allowed root types (<class 'dict'>,)
2019-05-18 15:40:06,070 - util.py[DEBUG]: Reading from /etc/cloud/cloud.cfg.d/05_logging.cfg (quiet=False)
2019-05-18 15:40:06,070 - util.py[DEBUG]: Read 2057 bytes from /etc/cloud/cloud.cfg.d/05_logging.cfg
2019-05-18 15:40:06,070 - util.py[DEBUG]: Attempting to load yaml from string of length 2057 with allowed root types (<class 'dict'>,)
2019-05-18 15:40:06,073 - util.py[DEBUG]: Reading from /run/cloud-init/cloud.cfg (quiet=False)
2019-05-18 15:40:06,073 - util.py[DEBUG]: Read 44 bytes from /run/cloud-init/cloud.cfg
2019-05-18 15:40:06,073 - util.py[DEBUG]: Attempting to load yaml from string of length 44 with allowed root types (<class 'dict'>,)
2019-05-18 15:40:06,074 - util.py[DEBUG]: Attempting to load yaml from string of length 0 with allowed root types (<class 'dict'>,)
2019-05-18 15:40:06,074 - util.py[DEBUG]: loaded blob returned None, returning default.
2019-05-18 15:40:06,075 - util.py[DEBUG]: Reading from /sys/class/net/ens3/address (quiet=False)
2019-05-18 15:40:06,075 - util.py[DEBUG]: Read 18 bytes from /sys/class/net/ens3/address
2019-05-18 15:40:06,075 - stages.py[DEBUG]: applying net config names for {'version': 1, 'config': [{'subnets': [{'type': 'dhcp4'}], 'type': 'physical', 'name': 'ens3', 'mac_address': '02:57:4d:d7:cf:40'}]}
2019-05-18 15:40:06,075 - stages.py[DEBUG]: Using distro class <class 'cloudinit.distros.ubuntu.Distro'>
2019-05-18 15:40:06,076 - util.py[DEBUG]: Reading from /sys/class/net/ens3/device/device (quiet=False)
2019-05-18 15:40:06,076 - util.py[DEBUG]: Read 7 bytes from /sys/class/net/ens3/device/device
2019-05-18 15:40:06,076 - util.py[DEBUG]: Reading from /sys/class/net/lo/addr_assign_type (quiet=False)
2019-05-18 15:40:06,076 - util.py[DEBUG]: Read 2 bytes from /sys/class/net/lo/addr_assign_type
2019-05-18 15:40:06,076 - util.py[DEBUG]: Reading from /sys/class/net/lo/uevent (quiet=False)
2019-05-18 15:40:06,076 - util.py[DEBUG]: Read 23 bytes from /sys/class/net/lo/uevent
2019-05-18 15:40:06,076 - util.py[DEBUG]: Reading from /sys/class/net/lo/address (quiet=False)
2019-05-18 15:40:06,076 - util.py[DEBUG]: Read 18 bytes from /sys/class/net/lo/address
2019-05-18 15:40:06,076 - util.py[DEBUG]: Reading from /sys/class/net/lo/device/device (quiet=False)
2019-05-18 15:40:06,076 - util.py[DEBUG]: Reading from /sys/class/net/ens3/addr_assign_type (quiet=False)
2019-05-18 15:40:06,076 - util.py[DEBUG]: Read 2 bytes from /sys/class/net/ens3/addr_assign_type
2019-05-18 15:40:06,076 - util.py[DEBUG]: Reading from /sys/class/net/ens3/uevent (quiet=False)
2019-05-18 15:40:06,076 - util.py[DEBUG]: Read 25 bytes from /sys/class/net/ens3/uevent
2019-05-18 15:40:06,077 - util.py[DEBUG]: Reading from /sys/class/net/ens3/address (quiet=False)
2019-05-18 15:40:06,077 - util.py[DEBUG]: Read 18 bytes from /sys/class/net/ens3/address
2019-05-18 15:40:06,077 - util.py[DEBUG]: Reading from /sys/class/net/ens3/device/device (quiet=False)
2019-05-18 15:40:06,077 - util.py[DEBUG]: Read 7 bytes from /sys/class/net/ens3/device/device
2019-05-18 15:40:06,077 - util.py[DEBUG]: Reading from /sys/class/net/lo/operstate (quiet=False)
2019-05-18 15:40:06,077 - util.py[DEBUG]: Read 8 bytes from /sys/class/net/lo/operstate
2019-05-18 15:40:06,077 - util.py[DEBUG]: Reading from /sys/class/net/ens3/operstate (quiet=False)
2019-05-18 15:40:06,077 - util.py[DEBUG]: Read 3 bytes from /sys/class/net/ens3/operstate
2019-05-18 15:40:06,077 - util.py[DEBUG]: Running command ['ip', '-6', 'addr', 'show', 'permanent', 'scope', 'global'] with allowed return codes [0] (shell=False, capture=True)
2019-05-18 15:40:06,079 - util.py[DEBUG]: Running command ['ip', '-4', 'addr', 'show'] with allowed return codes [0] (shell=False, capture=True)
2019-05-18 15:40:06,081 - __init__.py[DEBUG]: no work necessary for renaming of [['02:57:4d:d7:cf:40', 'ens3', 'ixgbevf', '0x10ed']]
2019-05-18 15:40:06,081 - stages.py[DEBUG]: No network config applied. Neither a new instance nor datasource network update on 'System boot' event
2019-05-18 15:40:06,082 - handlers.py[DEBUG]: start: init-network/setup-datasource: setting up datasource
2019-05-18 15:40:06,082 - handlers.py[DEBUG]: finish: init-network/setup-datasource: SUCCESS: setting up datasource
2019-05-18 15:40:06,082 - util.py[DEBUG]: Writing to /var/lib/cloud/instances/i-0bb244a52030111dc/user-data.txt - wb: [600] 0 bytes
2019-05-18 15:40:06,084 - util.py[DEBUG]: Writing to /var/lib/cloud/instances/i-0bb244a52030111dc/user-data.txt.i - wb: [600] 308 bytes
2019-05-18 15:40:06,085 - util.py[DEBUG]: Writing to /var/lib/cloud/instances/i-0bb244a52030111dc/vendor-data.txt - wb: [600] 0 bytes
2019-05-18 15:40:06,086 - util.py[DEBUG]: Writing to /var/lib/cloud/instances/i-0bb244a52030111dc/vendor-data.txt.i - wb: [600] 308 bytes
2019-05-18 15:40:06,086 - util.py[DEBUG]: Reading from /var/lib/cloud/data/set-hostname (quiet=False)
2019-05-18 15:40:06,087 - util.py[DEBUG]: Read 84 bytes from /var/lib/cloud/data/set-hostname
2019-05-18 15:40:06,087 - cc_set_hostname.py[DEBUG]: No hostname changes. Skipping set-hostname
2019-05-18 15:40:06,087 - util.py[DEBUG]: Writing to /var/lib/cloud/instances/i-0bb244a52030111dc/sem/consume_data - wb: [644] 25 bytes
2019-05-18 15:40:06,087 - helpers.py[DEBUG]: Running consume_data using lock (<FileLock using file '/var/lib/cloud/instances/i-0bb244a52030111dc/sem/consume_data'>)
2019-05-18 15:40:06,087 - handlers.py[DEBUG]: start: init-network/consume-user-data: reading and applying user-data
2019-05-18 15:40:06,088 - launch_index.py[DEBUG]: Discarding 0 multipart messages which do not match launch index 0
2019-05-18 15:40:06,088 - stages.py[DEBUG]: Added default handler for {'text/cloud-config-jsonp', 'text/cloud-config'} from CloudConfigPartHandler: [['text/cloud-config-jsonp', 'text/cloud-config']]
2019-05-18 15:40:06,088 - stages.py[DEBUG]: Added default handler for {'text/x-shellscript'} from ShellScriptPartHandler: [['text/x-shellscript']]
2019-05-18 15:40:06,088 - stages.py[DEBUG]: Added default handler for {'text/cloud-boothook'} from BootHookPartHandler: [['text/cloud-boothook']]
2019-05-18 15:40:06,088 - stages.py[DEBUG]: Added default handler for {'text/upstart-job'} from UpstartJobPartHandler: [['text/upstart-job']]
2019-05-18 15:40:06,088 - __init__.py[DEBUG]: Calling handler ShellScriptPartHandler: [['text/x-shellscript']] (__begin__, None, 2) with frequency once-per-instance
2019-05-18 15:40:06,088 - __init__.py[DEBUG]: Calling handler CloudConfigPartHandler: [['text/cloud-config-jsonp', 'text/cloud-config']] (__begin__, None, 3) with frequency once-per-instance
2019-05-18 15:40:06,088 - __init__.py[DEBUG]: Calling handler UpstartJobPartHandler: [['text/upstart-job']] (__begin__, None, 2) with frequency once-per-instance
2019-05-18 15:40:06,088 - __init__.py[DEBUG]: Calling handler BootHookPartHandler: [['text/cloud-boothook']] (__begin__, None, 2) with frequency once-per-instance
2019-05-18 15:40:06,089 - __init__.py[DEBUG]: {'MIME-Version': '1.0', 'Content-Type': 'text/x-not-multipart', 'Content-Disposition': 'attachment; filename="part-001"'}
2019-05-18 15:40:06,089 - __init__.py[DEBUG]: Empty payload of type text/x-not-multipart
2019-05-18 15:40:06,089 - __init__.py[DEBUG]: Calling handler ShellScriptPartHandler: [['text/x-shellscript']] (__end__, None, 2) with frequency once-per-instance
2019-05-18 15:40:06,089 - __init__.py[DEBUG]: Calling handler CloudConfigPartHandler: [['text/cloud-config-jsonp', 'text/cloud-config']] (__end__, None, 3) with frequency once-per-instance
2019-05-18 15:40:06,089 - util.py[DEBUG]: Writing to /var/lib/cloud/instances/i-0bb244a52030111dc/cloud-config.txt - wb: [600] 0 bytes
2019-05-18 15:40:06,089 - __init__.py[DEBUG]: Calling handler UpstartJobPartHandler: [['text/upstart-job']] (__end__, None, 2) with frequency once-per-instance
2019-05-18 15:40:06,089 - __init__.py[DEBUG]: Calling handler BootHookPartHandler: [['text/cloud-boothook']] (__end__, None, 2) with frequency once-per-instance
2019-05-18 15:40:06,089 - handlers.py[DEBUG]: finish: init-network/consume-user-data: SUCCESS: reading and applying user-data
2019-05-18 15:40:06,090 - handlers.py[DEBUG]: start: init-network/consume-vendor-data: reading and applying vendor-data
2019-05-18 15:40:06,090 - stages.py[DEBUG]: no vendordata from datasource
2019-05-18 15:40:06,090 - handlers.py[DEBUG]: finish: init-network/consume-vendor-data: SUCCESS: reading and applying vendor-data
2019-05-18 15:40:06,090 - util.py[DEBUG]: Reading from /etc/cloud/cloud.cfg (quiet=False)
2019-05-18 15:40:06,090 - util.py[DEBUG]: Read 3169 bytes from /etc/cloud/cloud.cfg
2019-05-18 15:40:06,090 - util.py[DEBUG]: Attempting to load yaml from string of length 3169 with allowed root types (<class 'dict'>,)
2019-05-18 15:40:06,100 - util.py[DEBUG]: Reading from /etc/cloud/cloud.cfg.d/90_dpkg.cfg (quiet=False)
2019-05-18 15:40:06,100 - util.py[DEBUG]: Read 238 bytes from /etc/cloud/cloud.cfg.d/90_dpkg.cfg
2019-05-18 15:40:06,100 - util.py[DEBUG]: Attempting to load yaml from string of length 238 with allowed root types (<class 'dict'>,)
2019-05-18 15:40:06,102 - util.py[DEBUG]: Reading from /etc/cloud/cloud.cfg.d/05_logging.cfg (quiet=False)
2019-05-18 15:40:06,102 - util.py[DEBUG]: Read 2057 bytes from /etc/cloud/cloud.cfg.d/05_logging.cfg
2019-05-18 15:40:06,102 - util.py[DEBUG]: Attempting to load yaml from string of length 2057 with allowed root types (<class 'dict'>,)
2019-05-18 15:40:06,105 - util.py[DEBUG]: Reading from /run/cloud-init/cloud.cfg (quiet=False)
2019-05-18 15:40:06,105 - util.py[DEBUG]: Read 44 bytes from /run/cloud-init/cloud.cfg
2019-05-18 15:40:06,105 - util.py[DEBUG]: Attempting to load yaml from string of length 44 with allowed root types (<class 'dict'>,)
2019-05-18 15:40:06,106 - util.py[DEBUG]: Attempting to load yaml from string of length 0 with allowed root types (<class 'dict'>,)
2019-05-18 15:40:06,106 - util.py[DEBUG]: loaded blob returned None, returning default.
2019-05-18 15:40:06,106 - util.py[DEBUG]: Reading from /var/lib/cloud/instance/cloud-config.txt (quiet=False)
2019-05-18 15:40:06,106 - util.py[DEBUG]: Read 0 bytes from /var/lib/cloud/instance/cloud-config.txt
2019-05-18 15:40:06,106 - util.py[DEBUG]: Attempting to load yaml from string of length 0 with allowed root types (<class 'dict'>,)
2019-05-18 15:40:06,106 - util.py[DEBUG]: loaded blob returned None, returning default.
2019-05-18 15:40:06,107 - util.py[DEBUG]: Reading from /var/lib/cloud/instance/cloud-config.txt (quiet=False)
2019-05-18 15:40:06,107 - util.py[DEBUG]: Read 0 bytes from /var/lib/cloud/instance/cloud-config.txt
2019-05-18 15:40:06,107 - util.py[DEBUG]: Attempting to load yaml from string of length 0 with allowed root types (<class 'dict'>,)
2019-05-18 15:40:06,107 - util.py[DEBUG]: loaded blob returned None, returning default.
2019-05-18 15:40:06,108 - handlers.py[DEBUG]: start: init-network/activate-datasource: activating datasource
2019-05-18 15:40:06,109 - util.py[DEBUG]: Writing to /var/lib/cloud/instance/obj.pkl - wb: [400] 8517 bytes
2019-05-18 15:40:06,109 - handlers.py[DEBUG]: finish: init-network/activate-datasource: SUCCESS: activating datasource
2019-05-18 15:40:06,110 - main.py[DEBUG]: used datasource 'DataSourceEc2Local' from 'Ec2' was in di_report's list: ['Ec2', 'None']
2019-05-18 15:40:06,162 - stages.py[DEBUG]: Using distro class <class 'cloudinit.distros.ubuntu.Distro'>
2019-05-18 15:40:06,163 - stages.py[DEBUG]: Running module migrator (<module 'cloudinit.config.cc_migrator' from '/usr/lib/python3/dist-packages/cloudinit/config/cc_migrator.py'>) with frequency always
2019-05-18 15:40:06,163 - handlers.py[DEBUG]: start: init-network/config-migrator: running config-migrator with frequency always
2019-05-18 15:40:06,163 - helpers.py[DEBUG]: Running config-migrator using lock (<cloudinit.helpers.DummyLock object at 0x7f1902976400>)
2019-05-18 15:40:06,163 - cc_migrator.py[DEBUG]: Migrated 0 semaphore files to there canonicalized names
2019-05-18 15:40:06,163 - handlers.py[DEBUG]: finish: init-network/config-migrator: SUCCESS: config-migrator ran successfully
2019-05-18 15:40:06,163 - stages.py[DEBUG]: Running module seed_random (<module 'cloudinit.config.cc_seed_random' from '/usr/lib/python3/dist-packages/cloudinit/config/cc_seed_random.py'>) with frequency once-per-instance
2019-05-18 15:40:06,163 - handlers.py[DEBUG]: start: init-network/config-seed_random: running config-seed_random with frequency once-per-instance
2019-05-18 15:40:06,164 - util.py[DEBUG]: Writing to /var/lib/cloud/instances/i-0bb244a52030111dc/sem/config_seed_random - wb: [644] 25 bytes
2019-05-18 15:40:06,164 - helpers.py[DEBUG]: Running config-seed_random using lock (<FileLock using file '/var/lib/cloud/instances/i-0bb244a52030111dc/sem/config_seed_random'>)
2019-05-18 15:40:06,164 - cc_seed_random.py[DEBUG]: no command provided
2019-05-18 15:40:06,164 - handlers.py[DEBUG]: finish: init-network/config-seed_random: SUCCESS: config-seed_random ran successfully
2019-05-18 15:40:06,164 - stages.py[DEBUG]: Running module bootcmd (<module 'cloudinit.config.cc_bootcmd' from '/usr/lib/python3/dist-packages/cloudinit/config/cc_bootcmd.py'>) with frequency always
2019-05-18 15:40:06,164 - handlers.py[DEBUG]: start: init-network/config-bootcmd: running config-bootcmd with frequency always
2019-05-18 15:40:06,164 - helpers.py[DEBUG]: Running config-bootcmd using lock (<cloudinit.helpers.DummyLock object at 0x7f1902976940>)
2019-05-18 15:40:06,165 - cc_bootcmd.py[DEBUG]: Skipping module named bootcmd, no 'bootcmd' key in configuration
2019-05-18 15:40:06,165 - handlers.py[DEBUG]: finish: init-network/config-bootcmd: SUCCESS: config-bootcmd ran successfully
2019-05-18 15:40:06,165 - stages.py[DEBUG]: Running module write-files (<module 'cloudinit.config.cc_write_files' from '/usr/lib/python3/dist-packages/cloudinit/config/cc_write_files.py'>) with frequency once-per-instance
2019-05-18 15:40:06,165 - handlers.py[DEBUG]: start: init-network/config-write-files: running config-write-files with frequency once-per-instance
2019-05-18 15:40:06,165 - util.py[DEBUG]: Writing to /var/lib/cloud/instances/i-0bb244a52030111dc/sem/config_write_files - wb: [644] 25 bytes
2019-05-18 15:40:06,165 - helpers.py[DEBUG]: Running config-write-files using lock (<FileLock using file '/var/lib/cloud/instances/i-0bb244a52030111dc/sem/config_write_files'>)
2019-05-18 15:40:06,166 - cc_write_files.py[DEBUG]: Skipping module named write-files, no/empty 'write_files' key in configuration
2019-05-18 15:40:06,166 - handlers.py[DEBUG]: finish: init-network/config-write-files: SUCCESS: config-write-files ran successfully
2019-05-18 15:40:06,166 - stages.py[DEBUG]: Running module growpart (<module 'cloudinit.config.cc_growpart' from '/usr/lib/python3/dist-packages/cloudinit/config/cc_growpart.py'>) with frequency always
2019-05-18 15:40:06,166 - handlers.py[DEBUG]: start: init-network/config-growpart: running config-growpart with frequency always
2019-05-18 15:40:06,166 - helpers.py[DEBUG]: Running config-growpart using lock (<cloudinit.helpers.DummyLock object at 0x7f190296a278>)
2019-05-18 15:40:06,166 - cc_growpart.py[DEBUG]: No 'growpart' entry in cfg.  Using default: {'ignore_growroot_disabled': False, 'devices': ['/'], 'mode': 'auto'}
2019-05-18 15:40:06,166 - util.py[DEBUG]: Running command ['growpart', '--help'] with allowed return codes [0] (shell=False, capture=True)
2019-05-18 15:40:06,169 - util.py[DEBUG]: Reading from /proc/1314/mountinfo (quiet=False)
2019-05-18 15:40:06,169 - util.py[DEBUG]: Read 2627 bytes from /proc/1314/mountinfo
2019-05-18 15:40:06,169 - util.py[DEBUG]: Running command ['systemd-detect-virt', '--quiet', '--container'] with allowed return codes [0] (shell=False, capture=True)
2019-05-18 15:40:06,171 - util.py[DEBUG]: Running command ['running-in-container'] with allowed return codes [0] (shell=False, capture=True)
2019-05-18 15:40:06,173 - util.py[DEBUG]: Running command ['lxc-is-container'] with allowed return codes [0] (shell=False, capture=True)
2019-05-18 15:40:06,175 - util.py[DEBUG]: Reading from /proc/1/environ (quiet=False)
2019-05-18 15:40:06,175 - util.py[DEBUG]: Read 150 bytes from /proc/1/environ
2019-05-18 15:40:06,175 - util.py[DEBUG]: Reading from /proc/self/status (quiet=False)
2019-05-18 15:40:06,175 - util.py[DEBUG]: Read 971 bytes from /proc/self/status
2019-05-18 15:40:06,177 - util.py[DEBUG]: Reading from /etc/os-release (quiet=False)
2019-05-18 15:40:06,177 - util.py[DEBUG]: Read 298 bytes from /etc/os-release
2019-05-18 15:40:06,178 - util.py[DEBUG]: Reading from /sys/class/block/xvda1/partition (quiet=False)
2019-05-18 15:40:06,178 - util.py[DEBUG]: Read 2 bytes from /sys/class/block/xvda1/partition
2019-05-18 15:40:06,178 - util.py[DEBUG]: Reading from /sys/devices/vbd-768/block/xvda/dev (quiet=False)
2019-05-18 15:40:06,178 - util.py[DEBUG]: Read 6 bytes from /sys/devices/vbd-768/block/xvda/dev
2019-05-18 15:40:06,178 - util.py[DEBUG]: Running command ['growpart', '--dry-run', '/dev/xvda', '1'] with allowed return codes [0] (shell=False, capture=True)
2019-05-18 15:40:06,210 - util.py[DEBUG]: Running command ['growpart', '/dev/xvda', '1'] with allowed return codes [0] (shell=False, capture=True)
2019-05-18 15:40:06,268 - util.py[DEBUG]: resize_devices took 0.099 seconds
2019-05-18 15:40:06,268 - cc_growpart.py[INFO]: '/' resized: changed (/dev/xvda, 1) from 8588869120 to 32211189248
2019-05-18 15:40:06,268 - handlers.py[DEBUG]: finish: init-network/config-growpart: SUCCESS: config-growpart ran successfully
2019-05-18 15:40:06,268 - stages.py[DEBUG]: Running module resizefs (<module 'cloudinit.config.cc_resizefs' from '/usr/lib/python3/dist-packages/cloudinit/config/cc_resizefs.py'>) with frequency always
2019-05-18 15:40:06,268 - handlers.py[DEBUG]: start: init-network/config-resizefs: running config-resizefs with frequency always
2019-05-18 15:40:06,269 - helpers.py[DEBUG]: Running config-resizefs using lock (<cloudinit.helpers.DummyLock object at 0x7f19029c1780>)
2019-05-18 15:40:06,269 - schema.py[DEBUG]: Ignoring schema validation. python-jsonschema is not present
2019-05-18 15:40:06,269 - util.py[DEBUG]: Reading from /proc/1314/mountinfo (quiet=False)
2019-05-18 15:40:06,269 - util.py[DEBUG]: Read 2627 bytes from /proc/1314/mountinfo
2019-05-18 15:40:06,269 - cc_resizefs.py[DEBUG]: resize_info: dev=/dev/xvda1 mnt_point=/ path=/
2019-05-18 15:40:06,269 - util.py[DEBUG]: Running command ['systemd-detect-virt', '--quiet', '--container'] with allowed return codes [0] (shell=False, capture=True)
2019-05-18 15:40:06,272 - util.py[DEBUG]: Running command ['running-in-container'] with allowed return codes [0] (shell=False, capture=True)
2019-05-18 15:40:06,273 - util.py[DEBUG]: Running command ['lxc-is-container'] with allowed return codes [0] (shell=False, capture=True)
2019-05-18 15:40:06,275 - util.py[DEBUG]: Reading from /proc/1/environ (quiet=False)
2019-05-18 15:40:06,276 - util.py[DEBUG]: Read 150 bytes from /proc/1/environ
2019-05-18 15:40:06,276 - util.py[DEBUG]: Reading from /proc/self/status (quiet=False)
2019-05-18 15:40:06,276 - util.py[DEBUG]: Read 972 bytes from /proc/self/status
2019-05-18 15:40:06,276 - cc_resizefs.py[DEBUG]: Resizing / (ext4) using resize2fs /dev/xvda1
2019-05-18 15:40:06,276 - util.py[DEBUG]: Running command ('resize2fs', '/dev/xvda1') with allowed return codes [0] (shell=False, capture=True)
2019-05-18 15:40:06,320 - util.py[DEBUG]: Resizing took 0.044 seconds
2019-05-18 15:40:06,320 - cc_resizefs.py[DEBUG]: Resized root filesystem (type=ext4, val=True)
2019-05-18 15:40:06,320 - handlers.py[DEBUG]: finish: init-network/config-resizefs: SUCCESS: config-resizefs ran successfully
2019-05-18 15:40:06,320 - stages.py[DEBUG]: Running module disk_setup (<module 'cloudinit.config.cc_disk_setup' from '/usr/lib/python3/dist-packages/cloudinit/config/cc_disk_setup.py'>) with frequency once-per-instance
2019-05-18 15:40:06,321 - handlers.py[DEBUG]: start: init-network/config-disk_setup: running config-disk_setup with frequency once-per-instance
2019-05-18 15:40:06,321 - util.py[DEBUG]: Writing to /var/lib/cloud/instances/i-0bb244a52030111dc/sem/config_disk_setup - wb: [644] 25 bytes
2019-05-18 15:40:06,321 - helpers.py[DEBUG]: Running config-disk_setup using lock (<FileLock using file '/var/lib/cloud/instances/i-0bb244a52030111dc/sem/config_disk_setup'>)
2019-05-18 15:40:06,322 - handlers.py[DEBUG]: finish: init-network/config-disk_setup: SUCCESS: config-disk_setup ran successfully
2019-05-18 15:40:06,322 - stages.py[DEBUG]: Running module mounts (<module 'cloudinit.config.cc_mounts' from '/usr/lib/python3/dist-packages/cloudinit/config/cc_mounts.py'>) with frequency once-per-instance
2019-05-18 15:40:06,322 - handlers.py[DEBUG]: start: init-network/config-mounts: running config-mounts with frequency once-per-instance
2019-05-18 15:40:06,322 - util.py[DEBUG]: Writing to /var/lib/cloud/instances/i-0bb244a52030111dc/sem/config_mounts - wb: [644] 24 bytes
2019-05-18 15:40:06,322 - helpers.py[DEBUG]: Running config-mounts using lock (<FileLock using file '/var/lib/cloud/instances/i-0bb244a52030111dc/sem/config_mounts'>)
2019-05-18 15:40:06,322 - cc_mounts.py[DEBUG]: mounts configuration is []
2019-05-18 15:40:06,323 - util.py[DEBUG]: Reading from /etc/fstab (quiet=False)
2019-05-18 15:40:06,323 - util.py[DEBUG]: Read 51 bytes from /etc/fstab
2019-05-18 15:40:06,323 - cc_mounts.py[DEBUG]: Attempting to determine the real name of ephemeral0
2019-05-18 15:40:06,323 - cc_mounts.py[DEBUG]: changed default device ephemeral0 => None
2019-05-18 15:40:06,323 - cc_mounts.py[DEBUG]: Ignoring nonexistent default named mount ephemeral0
2019-05-18 15:40:06,323 - cc_mounts.py[DEBUG]: Attempting to determine the real name of swap
2019-05-18 15:40:06,323 - DataSourceEc2.py[DEBUG]: Unable to convert swap to a device
2019-05-18 15:40:06,323 - cc_mounts.py[DEBUG]: changed default device swap => None
2019-05-18 15:40:06,323 - cc_mounts.py[DEBUG]: Ignoring nonexistent default named mount swap
2019-05-18 15:40:06,323 - cc_mounts.py[DEBUG]: no need to setup swap
2019-05-18 15:40:06,323 - cc_mounts.py[DEBUG]: No modifications to fstab needed
2019-05-18 15:40:06,323 - handlers.py[DEBUG]: finish: init-network/config-mounts: SUCCESS: config-mounts ran successfully
2019-05-18 15:40:06,323 - stages.py[DEBUG]: Running module set_hostname (<module 'cloudinit.config.cc_set_hostname' from '/usr/lib/python3/dist-packages/cloudinit/config/cc_set_hostname.py'>) with frequency once-per-instance
2019-05-18 15:40:06,324 - handlers.py[DEBUG]: start: init-network/config-set_hostname: running config-set_hostname with frequency once-per-instance
2019-05-18 15:40:06,324 - util.py[DEBUG]: Writing to /var/lib/cloud/instances/i-0bb244a52030111dc/sem/config_set_hostname - wb: [644] 25 bytes
2019-05-18 15:40:06,324 - helpers.py[DEBUG]: Running config-set_hostname using lock (<FileLock using file '/var/lib/cloud/instances/i-0bb244a52030111dc/sem/config_set_hostname'>)
2019-05-18 15:40:06,324 - util.py[DEBUG]: Reading from /var/lib/cloud/data/set-hostname (quiet=False)
2019-05-18 15:40:06,324 - util.py[DEBUG]: Read 84 bytes from /var/lib/cloud/data/set-hostname
2019-05-18 15:40:06,324 - cc_set_hostname.py[DEBUG]: No hostname changes. Skipping set-hostname
2019-05-18 15:40:06,324 - handlers.py[DEBUG]: finish: init-network/config-set_hostname: SUCCESS: config-set_hostname ran successfully
2019-05-18 15:40:06,324 - stages.py[DEBUG]: Running module update_hostname (<module 'cloudinit.config.cc_update_hostname' from '/usr/lib/python3/dist-packages/cloudinit/config/cc_update_hostname.py'>) with frequency always
2019-05-18 15:40:06,325 - handlers.py[DEBUG]: start: init-network/config-update_hostname: running config-update_hostname with frequency always
2019-05-18 15:40:06,325 - helpers.py[DEBUG]: Running config-update_hostname using lock (<cloudinit.helpers.DummyLock object at 0x7f190296e898>)
2019-05-18 15:40:06,325 - cc_update_hostname.py[DEBUG]: Updating hostname to ip-10-0-0-17.eu-west-1.compute.internal (ip-10-0-0-17)
2019-05-18 15:40:06,325 - util.py[DEBUG]: Reading from /etc/hostname (quiet=False)
2019-05-18 15:40:06,325 - util.py[DEBUG]: Read 13 bytes from /etc/hostname
2019-05-18 15:40:06,325 - __init__.py[DEBUG]: Attempting to update hostname to ip-10-0-0-17 in 1 files
2019-05-18 15:40:06,325 - util.py[DEBUG]: Reading from /var/lib/cloud/data/previous-hostname (quiet=False)
2019-05-18 15:40:06,325 - util.py[DEBUG]: Writing to /var/lib/cloud/data/previous-hostname - wb: [644] 13 bytes
2019-05-18 15:40:06,326 - handlers.py[DEBUG]: finish: init-network/config-update_hostname: SUCCESS: config-update_hostname ran successfully
2019-05-18 15:40:06,326 - stages.py[DEBUG]: Running module update_etc_hosts (<module 'cloudinit.config.cc_update_etc_hosts' from '/usr/lib/python3/dist-packages/cloudinit/config/cc_update_etc_hosts.py'>) with frequency always
2019-05-18 15:40:06,326 - handlers.py[DEBUG]: start: init-network/config-update_etc_hosts: running config-update_etc_hosts with frequency always
2019-05-18 15:40:06,326 - helpers.py[DEBUG]: Running config-update_etc_hosts using lock (<cloudinit.helpers.DummyLock object at 0x7f190296eb00>)
2019-05-18 15:40:06,326 - cc_update_etc_hosts.py[DEBUG]: Configuration option 'manage_etc_hosts' is not set, not managing /etc/hosts in module update_etc_hosts
2019-05-18 15:40:06,326 - handlers.py[DEBUG]: finish: init-network/config-update_etc_hosts: SUCCESS: config-update_etc_hosts ran successfully
2019-05-18 15:40:06,326 - stages.py[DEBUG]: Running module ca-certs (<module 'cloudinit.config.cc_ca_certs' from '/usr/lib/python3/dist-packages/cloudinit/config/cc_ca_certs.py'>) with frequency once-per-instance
2019-05-18 15:40:06,326 - handlers.py[DEBUG]: start: init-network/config-ca-certs: running config-ca-certs with frequency once-per-instance
2019-05-18 15:40:06,326 - util.py[DEBUG]: Writing to /var/lib/cloud/instances/i-0bb244a52030111dc/sem/config_ca_certs - wb: [644] 24 bytes
2019-05-18 15:40:06,327 - helpers.py[DEBUG]: Running config-ca-certs using lock (<FileLock using file '/var/lib/cloud/instances/i-0bb244a52030111dc/sem/config_ca_certs'>)
2019-05-18 15:40:06,327 - cc_ca_certs.py[DEBUG]: Skipping module named ca-certs, no 'ca-certs' key in configuration
2019-05-18 15:40:06,327 - handlers.py[DEBUG]: finish: init-network/config-ca-certs: SUCCESS: config-ca-certs ran successfully
2019-05-18 15:40:06,327 - stages.py[DEBUG]: Running module rsyslog (<module 'cloudinit.config.cc_rsyslog' from '/usr/lib/python3/dist-packages/cloudinit/config/cc_rsyslog.py'>) with frequency once-per-instance
2019-05-18 15:40:06,327 - handlers.py[DEBUG]: start: init-network/config-rsyslog: running config-rsyslog with frequency once-per-instance
2019-05-18 15:40:06,327 - util.py[DEBUG]: Writing to /var/lib/cloud/instances/i-0bb244a52030111dc/sem/config_rsyslog - wb: [644] 24 bytes
2019-05-18 15:40:06,327 - helpers.py[DEBUG]: Running config-rsyslog using lock (<FileLock using file '/var/lib/cloud/instances/i-0bb244a52030111dc/sem/config_rsyslog'>)
2019-05-18 15:40:06,328 - cc_rsyslog.py[DEBUG]: Skipping module named rsyslog, no 'rsyslog' key in configuration
2019-05-18 15:40:06,328 - handlers.py[DEBUG]: finish: init-network/config-rsyslog: SUCCESS: config-rsyslog ran successfully
2019-05-18 15:40:06,328 - stages.py[DEBUG]: Running module users-groups (<module 'cloudinit.config.cc_users_groups' from '/usr/lib/python3/dist-packages/cloudinit/config/cc_users_groups.py'>) with frequency once-per-instance
2019-05-18 15:40:06,328 - handlers.py[DEBUG]: start: init-network/config-users-groups: running config-users-groups with frequency once-per-instance
2019-05-18 15:40:06,328 - util.py[DEBUG]: Writing to /var/lib/cloud/instances/i-0bb244a52030111dc/sem/config_users_groups - wb: [644] 25 bytes
2019-05-18 15:40:06,328 - helpers.py[DEBUG]: Running config-users-groups using lock (<FileLock using file '/var/lib/cloud/instances/i-0bb244a52030111dc/sem/config_users_groups'>)
2019-05-18 15:40:06,329 - util.py[DEBUG]: Reading from /etc/os-release (quiet=True)
2019-05-18 15:40:06,329 - util.py[DEBUG]: Read 298 bytes from /etc/os-release
2019-05-18 15:40:06,329 - util.py[DEBUG]: Reading from /etc/system-image/channel.ini (quiet=True)
2019-05-18 15:40:06,329 - util.py[DEBUG]: Read 0 bytes from /etc/system-image/channel.ini
2019-05-18 15:40:06,329 - __init__.py[DEBUG]: Adding user ubuntu
2019-05-18 15:40:06,329 - util.py[DEBUG]: Running hidden command to protect sensitive input/output logstring: ['useradd', 'ubuntu', '--comment', 'Ubuntu', '--groups', 'adm,audio,cdrom,dialout,dip,floppy,lxd,netdev,plugdev,sudo,video', '--shell', '/bin/bash', '-m']
2019-05-18 15:40:06,374 - util.py[DEBUG]: Running command ['passwd', '-l', 'ubuntu'] with allowed return codes [0] (shell=False, capture=True)
2019-05-18 15:40:06,385 - util.py[DEBUG]: Reading from /etc/sudoers (quiet=False)
2019-05-18 15:40:06,385 - util.py[DEBUG]: Read 755 bytes from /etc/sudoers
2019-05-18 15:40:06,386 - util.py[DEBUG]: Writing to /etc/sudoers.d/90-cloud-init-users - wb: [440] 151 bytes
2019-05-18 15:40:06,386 - handlers.py[DEBUG]: finish: init-network/config-users-groups: SUCCESS: config-users-groups ran successfully
2019-05-18 15:40:06,386 - stages.py[DEBUG]: Running module ssh (<module 'cloudinit.config.cc_ssh' from '/usr/lib/python3/dist-packages/cloudinit/config/cc_ssh.py'>) with frequency once-per-instance
2019-05-18 15:40:06,387 - handlers.py[DEBUG]: start: init-network/config-ssh: running config-ssh with frequency once-per-instance
2019-05-18 15:40:06,387 - util.py[DEBUG]: Writing to /var/lib/cloud/instances/i-0bb244a52030111dc/sem/config_ssh - wb: [644] 25 bytes
2019-05-18 15:40:06,387 - helpers.py[DEBUG]: Running config-ssh using lock (<FileLock using file '/var/lib/cloud/instances/i-0bb244a52030111dc/sem/config_ssh'>)
2019-05-18 15:40:06,388 - util.py[DEBUG]: Running command ['ssh-keygen', '-t', 'rsa', '-N', '', '-f', '/etc/ssh/ssh_host_rsa_key'] with allowed return codes [0] (shell=False, capture=True)
2019-05-18 15:40:06,686 - util.py[DEBUG]: Running command ['ssh-keygen', '-t', 'dsa', '-N', '', '-f', '/etc/ssh/ssh_host_dsa_key'] with allowed return codes [0] (shell=False, capture=True)
2019-05-18 15:40:06,773 - util.py[DEBUG]: Running command ['ssh-keygen', '-t', 'ecdsa', '-N', '', '-f', '/etc/ssh/ssh_host_ecdsa_key'] with allowed return codes [0] (shell=False, capture=True)
2019-05-18 15:40:06,776 - util.py[DEBUG]: Running command ['ssh-keygen', '-t', 'ed25519', '-N', '', '-f', '/etc/ssh/ssh_host_ed25519_key'] with allowed return codes [0] (shell=False, capture=True)
2019-05-18 15:40:06,781 - util.py[DEBUG]: Changing the ownership of /home/ubuntu/.ssh to 1000:1000
2019-05-18 15:40:06,781 - util.py[DEBUG]: Reading from /etc/ssh/sshd_config (quiet=False)
2019-05-18 15:40:06,782 - util.py[DEBUG]: Read 2540 bytes from /etc/ssh/sshd_config
2019-05-18 15:40:06,782 - util.py[DEBUG]: Writing to /home/ubuntu/.ssh/authorized_keys - wb: [600] 448 bytes
2019-05-18 15:40:06,783 - util.py[DEBUG]: Changing the ownership of /home/ubuntu/.ssh/authorized_keys to 1000:1000
2019-05-18 15:40:06,783 - util.py[DEBUG]: Changing the ownership of /root/.ssh to 0:0
2019-05-18 15:40:06,783 - util.py[DEBUG]: Reading from /etc/ssh/sshd_config (quiet=False)
2019-05-18 15:40:06,784 - util.py[DEBUG]: Read 2540 bytes from /etc/ssh/sshd_config
2019-05-18 15:40:06,784 - util.py[DEBUG]: Writing to /root/.ssh/authorized_keys - wb: [600] 603 bytes
2019-05-18 15:40:06,784 - util.py[DEBUG]: Changing the ownership of /root/.ssh/authorized_keys to 0:0
2019-05-18 15:40:06,785 - handlers.py[DEBUG]: finish: init-network/config-ssh: SUCCESS: config-ssh ran successfully
2019-05-18 15:40:06,785 - main.py[DEBUG]: Ran 15 modules with 0 failures
2019-05-18 15:40:06,785 - util.py[DEBUG]: Reading from /proc/uptime (quiet=False)
2019-05-18 15:40:06,785 - util.py[DEBUG]: Read 12 bytes from /proc/uptime
2019-05-18 15:40:06,785 - util.py[DEBUG]: cloud-init mode 'init' took 0.795 seconds (0.80)
2019-05-18 15:40:06,785 - handlers.py[DEBUG]: finish: init-network: SUCCESS: searching for network datasources
2019-05-18 15:40:13,257 - util.py[DEBUG]: Cloud-init v. 18.3-9-g2e62cb8a-0ubuntu1~16.04.2 running 'modules:config' at Sat, 18 May 2019 15:40:13 +0000. Up 14.74 seconds.
2019-05-18 15:40:13,292 - stages.py[DEBUG]: Using distro class <class 'cloudinit.distros.ubuntu.Distro'>
2019-05-18 15:40:13,292 - stages.py[DEBUG]: Running module emit_upstart (<module 'cloudinit.config.cc_emit_upstart' from '/usr/lib/python3/dist-packages/cloudinit/config/cc_emit_upstart.py'>) with frequency always
2019-05-18 15:40:13,293 - handlers.py[DEBUG]: start: modules-config/config-emit_upstart: running config-emit_upstart with frequency always
2019-05-18 15:40:13,293 - helpers.py[DEBUG]: Running config-emit_upstart using lock (<cloudinit.helpers.DummyLock object at 0x7f43feea9d68>)
2019-05-18 15:40:13,293 - cc_emit_upstart.py[DEBUG]: no /sbin/initctl located
2019-05-18 15:40:13,293 - cc_emit_upstart.py[DEBUG]: not upstart system, 'emit_upstart' disabled
2019-05-18 15:40:13,293 - handlers.py[DEBUG]: finish: modules-config/config-emit_upstart: SUCCESS: config-emit_upstart ran successfully
2019-05-18 15:40:13,293 - stages.py[DEBUG]: Running module snap (<module 'cloudinit.config.cc_snap' from '/usr/lib/python3/dist-packages/cloudinit/config/cc_snap.py'>) with frequency once-per-instance
2019-05-18 15:40:13,293 - handlers.py[DEBUG]: start: modules-config/config-snap: running config-snap with frequency once-per-instance
2019-05-18 15:40:13,294 - util.py[DEBUG]: Writing to /var/lib/cloud/instances/i-0bb244a52030111dc/sem/config_snap - wb: [644] 25 bytes
2019-05-18 15:40:13,294 - helpers.py[DEBUG]: Running config-snap using lock (<FileLock using file '/var/lib/cloud/instances/i-0bb244a52030111dc/sem/config_snap'>)
2019-05-18 15:40:13,294 - cc_snap.py[DEBUG]: Skipping module named snap, no 'snap' key in configuration
2019-05-18 15:40:13,294 - handlers.py[DEBUG]: finish: modules-config/config-snap: SUCCESS: config-snap ran successfully
2019-05-18 15:40:13,294 - stages.py[DEBUG]: Running module snap_config (<module 'cloudinit.config.cc_snap_config' from '/usr/lib/python3/dist-packages/cloudinit/config/cc_snap_config.py'>) with frequency once-per-instance
2019-05-18 15:40:13,294 - handlers.py[DEBUG]: start: modules-config/config-snap_config: running config-snap_config with frequency once-per-instance
2019-05-18 15:40:13,294 - util.py[DEBUG]: Writing to /var/lib/cloud/instances/i-0bb244a52030111dc/sem/config_snap_config - wb: [644] 25 bytes
2019-05-18 15:40:13,295 - helpers.py[DEBUG]: Running config-snap_config using lock (<FileLock using file '/var/lib/cloud/instances/i-0bb244a52030111dc/sem/config_snap_config'>)
2019-05-18 15:40:13,295 - cc_snap_config.py[DEBUG]: No snappy config provided, skipping
2019-05-18 15:40:13,295 - handlers.py[DEBUG]: finish: modules-config/config-snap_config: SUCCESS: config-snap_config ran successfully
2019-05-18 15:40:13,295 - stages.py[DEBUG]: Running module ssh-import-id (<module 'cloudinit.config.cc_ssh_import_id' from '/usr/lib/python3/dist-packages/cloudinit/config/cc_ssh_import_id.py'>) with frequency once-per-instance
2019-05-18 15:40:13,295 - handlers.py[DEBUG]: start: modules-config/config-ssh-import-id: running config-ssh-import-id with frequency once-per-instance
2019-05-18 15:40:13,295 - util.py[DEBUG]: Writing to /var/lib/cloud/instances/i-0bb244a52030111dc/sem/config_ssh_import_id - wb: [644] 25 bytes
2019-05-18 15:40:13,296 - helpers.py[DEBUG]: Running config-ssh-import-id using lock (<FileLock using file '/var/lib/cloud/instances/i-0bb244a52030111dc/sem/config_ssh_import_id'>)
2019-05-18 15:40:13,296 - handlers.py[DEBUG]: finish: modules-config/config-ssh-import-id: SUCCESS: config-ssh-import-id ran successfully
2019-05-18 15:40:13,296 - stages.py[DEBUG]: Running module locale (<module 'cloudinit.config.cc_locale' from '/usr/lib/python3/dist-packages/cloudinit/config/cc_locale.py'>) with frequency once-per-instance
2019-05-18 15:40:13,296 - handlers.py[DEBUG]: start: modules-config/config-locale: running config-locale with frequency once-per-instance
2019-05-18 15:40:13,296 - util.py[DEBUG]: Writing to /var/lib/cloud/instances/i-0bb244a52030111dc/sem/config_locale - wb: [644] 24 bytes
2019-05-18 15:40:13,297 - helpers.py[DEBUG]: Running config-locale using lock (<FileLock using file '/var/lib/cloud/instances/i-0bb244a52030111dc/sem/config_locale'>)
2019-05-18 15:40:13,297 - util.py[DEBUG]: Reading from /etc/default/locale (quiet=False)
2019-05-18 15:40:13,297 - util.py[DEBUG]: Read 35 bytes from /etc/default/locale
2019-05-18 15:40:13,297 - cc_locale.py[DEBUG]: Setting locale to en_US.UTF-8
2019-05-18 15:40:13,297 - util.py[DEBUG]: Reading from /etc/default/locale (quiet=False)
2019-05-18 15:40:13,297 - util.py[DEBUG]: Read 35 bytes from /etc/default/locale
2019-05-18 15:40:13,297 - debian.py[DEBUG]: Generating locales for en_US.UTF-8
2019-05-18 15:40:13,297 - util.py[DEBUG]: Running command ['locale-gen', 'en_US.UTF-8'] with allowed return codes [0] (shell=False, capture=False)
2019-05-18 15:40:13,888 - debian.py[DEBUG]: Updating /etc/default/locale with locale setting LANG=en_US.UTF-8
2019-05-18 15:40:13,888 - util.py[DEBUG]: Running command ['update-locale', '--locale-file=/etc/default/locale', 'LANG=en_US.UTF-8'] with allowed return codes [0] (shell=False, capture=False)
2019-05-18 15:40:14,002 - handlers.py[DEBUG]: finish: modules-config/config-locale: SUCCESS: config-locale ran successfully
2019-05-18 15:40:14,002 - stages.py[DEBUG]: Running module set-passwords (<module 'cloudinit.config.cc_set_passwords' from '/usr/lib/python3/dist-packages/cloudinit/config/cc_set_passwords.py'>) with frequency once-per-instance
2019-05-18 15:40:14,002 - handlers.py[DEBUG]: start: modules-config/config-set-passwords: running config-set-passwords with frequency once-per-instance
2019-05-18 15:40:14,003 - util.py[DEBUG]: Writing to /var/lib/cloud/instances/i-0bb244a52030111dc/sem/config_set_passwords - wb: [644] 25 bytes
2019-05-18 15:40:14,003 - helpers.py[DEBUG]: Running config-set-passwords using lock (<FileLock using file '/var/lib/cloud/instances/i-0bb244a52030111dc/sem/config_set_passwords'>)
2019-05-18 15:40:14,003 - cc_set_passwords.py[DEBUG]: Leaving ssh config 'PasswordAuthentication' unchanged. ssh_pwauth=None
2019-05-18 15:40:14,003 - handlers.py[DEBUG]: finish: modules-config/config-set-passwords: SUCCESS: config-set-passwords ran successfully
2019-05-18 15:40:14,003 - stages.py[DEBUG]: Running module grub-dpkg (<module 'cloudinit.config.cc_grub_dpkg' from '/usr/lib/python3/dist-packages/cloudinit/config/cc_grub_dpkg.py'>) with frequency once-per-instance
2019-05-18 15:40:14,004 - handlers.py[DEBUG]: start: modules-config/config-grub-dpkg: running config-grub-dpkg with frequency once-per-instance
2019-05-18 15:40:14,004 - util.py[DEBUG]: Writing to /var/lib/cloud/instances/i-0bb244a52030111dc/sem/config_grub_dpkg - wb: [644] 25 bytes
2019-05-18 15:40:14,004 - helpers.py[DEBUG]: Running config-grub-dpkg using lock (<FileLock using file '/var/lib/cloud/instances/i-0bb244a52030111dc/sem/config_grub_dpkg'>)
2019-05-18 15:40:14,004 - cc_grub_dpkg.py[DEBUG]: Setting grub debconf-set-selections with '/dev/xvda','false'
2019-05-18 15:40:14,004 - util.py[DEBUG]: Running command ['debconf-set-selections'] with allowed return codes [0] (shell=False, capture=True)
2019-05-18 15:40:14,141 - handlers.py[DEBUG]: finish: modules-config/config-grub-dpkg: SUCCESS: config-grub-dpkg ran successfully
2019-05-18 15:40:14,141 - stages.py[DEBUG]: Running module apt-pipelining (<module 'cloudinit.config.cc_apt_pipelining' from '/usr/lib/python3/dist-packages/cloudinit/config/cc_apt_pipelining.py'>) with frequency once-per-instance
2019-05-18 15:40:14,141 - handlers.py[DEBUG]: start: modules-config/config-apt-pipelining: running config-apt-pipelining with frequency once-per-instance
2019-05-18 15:40:14,142 - util.py[DEBUG]: Writing to /var/lib/cloud/instances/i-0bb244a52030111dc/sem/config_apt_pipelining - wb: [644] 25 bytes
2019-05-18 15:40:14,142 - helpers.py[DEBUG]: Running config-apt-pipelining using lock (<FileLock using file '/var/lib/cloud/instances/i-0bb244a52030111dc/sem/config_apt_pipelining'>)
2019-05-18 15:40:14,142 - util.py[DEBUG]: Writing to /etc/apt/apt.conf.d/90cloud-init-pipelining - wb: [644] 80 bytes
2019-05-18 15:40:14,143 - cc_apt_pipelining.py[DEBUG]: Wrote /etc/apt/apt.conf.d/90cloud-init-pipelining with apt pipeline depth setting 0
2019-05-18 15:40:14,143 - handlers.py[DEBUG]: finish: modules-config/config-apt-pipelining: SUCCESS: config-apt-pipelining ran successfully
2019-05-18 15:40:14,143 - stages.py[DEBUG]: Running module apt-configure (<module 'cloudinit.config.cc_apt_configure' from '/usr/lib/python3/dist-packages/cloudinit/config/cc_apt_configure.py'>) with frequency once-per-instance
2019-05-18 15:40:14,143 - handlers.py[DEBUG]: start: modules-config/config-apt-configure: running config-apt-configure with frequency once-per-instance
2019-05-18 15:40:14,143 - util.py[DEBUG]: Writing to /var/lib/cloud/instances/i-0bb244a52030111dc/sem/config_apt_configure - wb: [644] 25 bytes
2019-05-18 15:40:14,144 - helpers.py[DEBUG]: Running config-apt-configure using lock (<FileLock using file '/var/lib/cloud/instances/i-0bb244a52030111dc/sem/config_apt_configure'>)
2019-05-18 15:40:14,144 - cc_apt_configure.py[DEBUG]: debconf_selections was not set in config
2019-05-18 15:40:14,144 - util.py[DEBUG]: Reading from /etc/os-release (quiet=True)
2019-05-18 15:40:14,144 - util.py[DEBUG]: Read 298 bytes from /etc/os-release
2019-05-18 15:40:14,144 - util.py[DEBUG]: Reading from /etc/system-image/channel.ini (quiet=True)
2019-05-18 15:40:14,144 - util.py[DEBUG]: Read 0 bytes from /etc/system-image/channel.ini
2019-05-18 15:40:14,144 - cc_apt_configure.py[DEBUG]: handling apt config: {}
2019-05-18 15:40:14,145 - util.py[DEBUG]: Running command ['lsb_release', '--all'] with allowed return codes [0] (shell=False, capture=True)
2019-05-18 15:40:14,188 - util.py[DEBUG]: Running command ['dpkg', '--print-architecture'] with allowed return codes [0] (shell=False, capture=True)
2019-05-18 15:40:14,191 - cc_apt_configure.py[DEBUG]: got primary mirror: None
2019-05-18 15:40:14,191 - cc_apt_configure.py[DEBUG]: got security mirror: None
2019-05-18 15:40:14,191 - util.py[DEBUG]: Running command ['dpkg', '--print-architecture'] with allowed return codes [0] (shell=False, capture=True)
2019-05-18 15:40:14,213 - util.py[DEBUG]: Resolving URL: http://eu-west-1.ec2.archive.ubuntu.com/ubuntu/ took 0.020 seconds
2019-05-18 15:40:14,213 - __init__.py[DEBUG]: filtered distro mirror info: {'security': 'http://security.ubuntu.com/ubuntu', 'primary': 'http://eu-west-1.ec2.archive.ubuntu.com/ubuntu/'}
2019-05-18 15:40:14,213 - cc_apt_configure.py[DEBUG]: Apt Mirror info: {'security': 'http://security.ubuntu.com/ubuntu', 'primary': 'http://eu-west-1.ec2.archive.ubuntu.com/ubuntu/', 'SECURITY': 'http://security.ubuntu.com/ubuntu', 'PRIMARY': 'http://eu-west-1.ec2.archive.ubuntu.com/ubuntu/', 'MIRROR': 'http://eu-west-1.ec2.archive.ubuntu.com/ubuntu/'}
2019-05-18 15:40:14,214 - cc_apt_configure.py[INFO]: No custom template provided, fall back to builtin
2019-05-18 15:40:14,214 - util.py[DEBUG]: Reading from /etc/cloud/templates/sources.list.ubuntu.tmpl (quiet=False)
2019-05-18 15:40:14,214 - util.py[DEBUG]: Read 2841 bytes from /etc/cloud/templates/sources.list.ubuntu.tmpl
2019-05-18 15:40:14,221 - util.py[DEBUG]: Writing to /etc/apt/sources.list - wb: [644] 3335 bytes
2019-05-18 15:40:14,222 - util.py[DEBUG]: Running command ['dpkg', '--print-architecture'] with allowed return codes [0] (shell=False, capture=True)
2019-05-18 15:40:14,225 - cc_apt_configure.py[DEBUG]: Renaming apt list /var/lib/apt/lists/archive.ubuntu.com_ubuntu_dists_xenial-updates_main_i18n_Translation-en to /var/lib/apt/lists/eu-west-1.ec2.archive.ubuntu.com_ubuntu_dists_xenial-updates_main_i18n_Translation-en
2019-05-18 15:40:14,225 - cc_apt_configure.py[DEBUG]: Renaming apt list /var/lib/apt/lists/archive.ubuntu.com_ubuntu_dists_xenial-updates_universe_i18n_Translation-en to /var/lib/apt/lists/eu-west-1.ec2.archive.ubuntu.com_ubuntu_dists_xenial-updates_universe_i18n_Translation-en
2019-05-18 15:40:14,225 - cc_apt_configure.py[DEBUG]: Renaming apt list /var/lib/apt/lists/archive.ubuntu.com_ubuntu_dists_xenial-updates_universe_binary-amd64_Packages to /var/lib/apt/lists/eu-west-1.ec2.archive.ubuntu.com_ubuntu_dists_xenial-updates_universe_binary-amd64_Packages
2019-05-18 15:40:14,225 - cc_apt_configure.py[DEBUG]: Renaming apt list /var/lib/apt/lists/archive.ubuntu.com_ubuntu_dists_xenial-updates_multiverse_binary-amd64_Packages to /var/lib/apt/lists/eu-west-1.ec2.archive.ubuntu.com_ubuntu_dists_xenial-updates_multiverse_binary-amd64_Packages
2019-05-18 15:40:14,225 - cc_apt_configure.py[DEBUG]: Renaming apt list /var/lib/apt/lists/archive.ubuntu.com_ubuntu_dists_xenial-updates_main_binary-amd64_Packages to /var/lib/apt/lists/eu-west-1.ec2.archive.ubuntu.com_ubuntu_dists_xenial-updates_main_binary-amd64_Packages
2019-05-18 15:40:14,225 - cc_apt_configure.py[DEBUG]: Renaming apt list /var/lib/apt/lists/archive.ubuntu.com_ubuntu_dists_xenial-updates_restricted_binary-amd64_Packages to /var/lib/apt/lists/eu-west-1.ec2.archive.ubuntu.com_ubuntu_dists_xenial-updates_restricted_binary-amd64_Packages
2019-05-18 15:40:14,225 - cc_apt_configure.py[DEBUG]: Renaming apt list /var/lib/apt/lists/archive.ubuntu.com_ubuntu_dists_xenial_main_i18n_Translation-en to /var/lib/apt/lists/eu-west-1.ec2.archive.ubuntu.com_ubuntu_dists_xenial_main_i18n_Translation-en
2019-05-18 15:40:14,225 - cc_apt_configure.py[DEBUG]: Renaming apt list /var/lib/apt/lists/archive.ubuntu.com_ubuntu_dists_xenial-updates_restricted_i18n_Translation-en to /var/lib/apt/lists/eu-west-1.ec2.archive.ubuntu.com_ubuntu_dists_xenial-updates_restricted_i18n_Translation-en
2019-05-18 15:40:14,225 - cc_apt_configure.py[DEBUG]: Renaming apt list /var/lib/apt/lists/archive.ubuntu.com_ubuntu_dists_xenial_universe_binary-amd64_Packages to /var/lib/apt/lists/eu-west-1.ec2.archive.ubuntu.com_ubuntu_dists_xenial_universe_binary-amd64_Packages
2019-05-18 15:40:14,225 - cc_apt_configure.py[DEBUG]: Renaming apt list /var/lib/apt/lists/archive.ubuntu.com_ubuntu_dists_xenial_multiverse_i18n_Translation-en to /var/lib/apt/lists/eu-west-1.ec2.archive.ubuntu.com_ubuntu_dists_xenial_multiverse_i18n_Translation-en
2019-05-18 15:40:14,225 - cc_apt_configure.py[DEBUG]: Renaming apt list /var/lib/apt/lists/archive.ubuntu.com_ubuntu_dists_xenial-updates_InRelease to /var/lib/apt/lists/eu-west-1.ec2.archive.ubuntu.com_ubuntu_dists_xenial-updates_InRelease
2019-05-18 15:40:14,226 - cc_apt_configure.py[DEBUG]: Renaming apt list /var/lib/apt/lists/archive.ubuntu.com_ubuntu_dists_xenial-backports_InRelease to /var/lib/apt/lists/eu-west-1.ec2.archive.ubuntu.com_ubuntu_dists_xenial-backports_InRelease
2019-05-18 15:40:14,226 - cc_apt_configure.py[DEBUG]: Renaming apt list /var/lib/apt/lists/archive.ubuntu.com_ubuntu_dists_xenial_multiverse_binary-amd64_Packages to /var/lib/apt/lists/eu-west-1.ec2.archive.ubuntu.com_ubuntu_dists_xenial_multiverse_binary-amd64_Packages
2019-05-18 15:40:14,226 - cc_apt_configure.py[DEBUG]: Renaming apt list /var/lib/apt/lists/archive.ubuntu.com_ubuntu_dists_xenial_universe_i18n_Translation-en to /var/lib/apt/lists/eu-west-1.ec2.archive.ubuntu.com_ubuntu_dists_xenial_universe_i18n_Translation-en
2019-05-18 15:40:14,226 - cc_apt_configure.py[DEBUG]: Renaming apt list /var/lib/apt/lists/archive.ubuntu.com_ubuntu_dists_xenial-backports_universe_i18n_Translation-en to /var/lib/apt/lists/eu-west-1.ec2.archive.ubuntu.com_ubuntu_dists_xenial-backports_universe_i18n_Translation-en
2019-05-18 15:40:14,226 - cc_apt_configure.py[DEBUG]: Renaming apt list /var/lib/apt/lists/archive.ubuntu.com_ubuntu_dists_xenial_InRelease to /var/lib/apt/lists/eu-west-1.ec2.archive.ubuntu.com_ubuntu_dists_xenial_InRelease
2019-05-18 15:40:14,226 - cc_apt_configure.py[DEBUG]: Renaming apt list /var/lib/apt/lists/archive.ubuntu.com_ubuntu_dists_xenial-backports_main_binary-amd64_Packages to /var/lib/apt/lists/eu-west-1.ec2.archive.ubuntu.com_ubuntu_dists_xenial-backports_main_binary-amd64_Packages
2019-05-18 15:40:14,226 - cc_apt_configure.py[DEBUG]: Renaming apt list /var/lib/apt/lists/archive.ubuntu.com_ubuntu_dists_xenial-updates_multiverse_i18n_Translation-en to /var/lib/apt/lists/eu-west-1.ec2.archive.ubuntu.com_ubuntu_dists_xenial-updates_multiverse_i18n_Translation-en
2019-05-18 15:40:14,226 - cc_apt_configure.py[DEBUG]: Renaming apt list /var/lib/apt/lists/archive.ubuntu.com_ubuntu_dists_xenial_restricted_i18n_Translation-en to /var/lib/apt/lists/eu-west-1.ec2.archive.ubuntu.com_ubuntu_dists_xenial_restricted_i18n_Translation-en
2019-05-18 15:40:14,226 - cc_apt_configure.py[DEBUG]: Renaming apt list /var/lib/apt/lists/archive.ubuntu.com_ubuntu_dists_xenial_restricted_binary-amd64_Packages to /var/lib/apt/lists/eu-west-1.ec2.archive.ubuntu.com_ubuntu_dists_xenial_restricted_binary-amd64_Packages
2019-05-18 15:40:14,226 - cc_apt_configure.py[DEBUG]: Renaming apt list /var/lib/apt/lists/archive.ubuntu.com_ubuntu_dists_xenial-backports_main_i18n_Translation-en to /var/lib/apt/lists/eu-west-1.ec2.archive.ubuntu.com_ubuntu_dists_xenial-backports_main_i18n_Translation-en
2019-05-18 15:40:14,226 - cc_apt_configure.py[DEBUG]: Renaming apt list /var/lib/apt/lists/archive.ubuntu.com_ubuntu_dists_xenial-backports_universe_binary-amd64_Packages to /var/lib/apt/lists/eu-west-1.ec2.archive.ubuntu.com_ubuntu_dists_xenial-backports_universe_binary-amd64_Packages
2019-05-18 15:40:14,226 - cc_apt_configure.py[DEBUG]: Renaming apt list /var/lib/apt/lists/archive.ubuntu.com_ubuntu_dists_xenial_main_binary-amd64_Packages to /var/lib/apt/lists/eu-west-1.ec2.archive.ubuntu.com_ubuntu_dists_xenial_main_binary-amd64_Packages
2019-05-18 15:40:14,226 - handlers.py[DEBUG]: finish: modules-config/config-apt-configure: SUCCESS: config-apt-configure ran successfully
2019-05-18 15:40:14,226 - stages.py[DEBUG]: Running module ubuntu-advantage (<module 'cloudinit.config.cc_ubuntu_advantage' from '/usr/lib/python3/dist-packages/cloudinit/config/cc_ubuntu_advantage.py'>) with frequency once-per-instance
2019-05-18 15:40:14,227 - handlers.py[DEBUG]: start: modules-config/config-ubuntu-advantage: running config-ubuntu-advantage with frequency once-per-instance
2019-05-18 15:40:14,227 - util.py[DEBUG]: Writing to /var/lib/cloud/instances/i-0bb244a52030111dc/sem/config_ubuntu_advantage - wb: [644] 23 bytes
2019-05-18 15:40:14,227 - helpers.py[DEBUG]: Running config-ubuntu-advantage using lock (<FileLock using file '/var/lib/cloud/instances/i-0bb244a52030111dc/sem/config_ubuntu_advantage'>)
2019-05-18 15:40:14,227 - cc_ubuntu_advantage.py[DEBUG]: Skipping module named ubuntu-advantage, no 'ubuntu-advantage' key in configuration
2019-05-18 15:40:14,227 - handlers.py[DEBUG]: finish: modules-config/config-ubuntu-advantage: SUCCESS: config-ubuntu-advantage ran successfully
2019-05-18 15:40:14,227 - stages.py[DEBUG]: Running module ntp (<module 'cloudinit.config.cc_ntp' from '/usr/lib/python3/dist-packages/cloudinit/config/cc_ntp.py'>) with frequency once-per-instance
2019-05-18 15:40:14,227 - handlers.py[DEBUG]: start: modules-config/config-ntp: running config-ntp with frequency once-per-instance
2019-05-18 15:40:14,228 - util.py[DEBUG]: Writing to /var/lib/cloud/instances/i-0bb244a52030111dc/sem/config_ntp - wb: [644] 25 bytes
2019-05-18 15:40:14,228 - helpers.py[DEBUG]: Running config-ntp using lock (<FileLock using file '/var/lib/cloud/instances/i-0bb244a52030111dc/sem/config_ntp'>)
2019-05-18 15:40:14,228 - cc_ntp.py[DEBUG]: Skipping module named ntp, not present or disabled by cfg
2019-05-18 15:40:14,228 - handlers.py[DEBUG]: finish: modules-config/config-ntp: SUCCESS: config-ntp ran successfully
2019-05-18 15:40:14,228 - stages.py[DEBUG]: Running module timezone (<module 'cloudinit.config.cc_timezone' from '/usr/lib/python3/dist-packages/cloudinit/config/cc_timezone.py'>) with frequency once-per-instance
2019-05-18 15:40:14,228 - handlers.py[DEBUG]: start: modules-config/config-timezone: running config-timezone with frequency once-per-instance
2019-05-18 15:40:14,228 - util.py[DEBUG]: Writing to /var/lib/cloud/instances/i-0bb244a52030111dc/sem/config_timezone - wb: [644] 25 bytes
2019-05-18 15:40:14,229 - helpers.py[DEBUG]: Running config-timezone using lock (<FileLock using file '/var/lib/cloud/instances/i-0bb244a52030111dc/sem/config_timezone'>)
2019-05-18 15:40:14,229 - cc_timezone.py[DEBUG]: Skipping module named timezone, no 'timezone' specified
2019-05-18 15:40:14,229 - handlers.py[DEBUG]: finish: modules-config/config-timezone: SUCCESS: config-timezone ran successfully
2019-05-18 15:40:14,229 - stages.py[DEBUG]: Running module disable-ec2-metadata (<module 'cloudinit.config.cc_disable_ec2_metadata' from '/usr/lib/python3/dist-packages/cloudinit/config/cc_disable_ec2_metadata.py'>) with frequency always
2019-05-18 15:40:14,229 - handlers.py[DEBUG]: start: modules-config/config-disable-ec2-metadata: running config-disable-ec2-metadata with frequency always
2019-05-18 15:40:14,229 - helpers.py[DEBUG]: Running config-disable-ec2-metadata using lock (<cloudinit.helpers.DummyLock object at 0x7f43fe6a7fd0>)
2019-05-18 15:40:14,229 - cc_disable_ec2_metadata.py[DEBUG]: Skipping module named disable-ec2-metadata, disabling the ec2 route not enabled
2019-05-18 15:40:14,229 - handlers.py[DEBUG]: finish: modules-config/config-disable-ec2-metadata: SUCCESS: config-disable-ec2-metadata ran successfully
2019-05-18 15:40:14,229 - stages.py[DEBUG]: Running module runcmd (<module 'cloudinit.config.cc_runcmd' from '/usr/lib/python3/dist-packages/cloudinit/config/cc_runcmd.py'>) with frequency once-per-instance
2019-05-18 15:40:14,230 - handlers.py[DEBUG]: start: modules-config/config-runcmd: running config-runcmd with frequency once-per-instance
2019-05-18 15:40:14,230 - util.py[DEBUG]: Writing to /var/lib/cloud/instances/i-0bb244a52030111dc/sem/config_runcmd - wb: [644] 25 bytes
2019-05-18 15:40:14,230 - helpers.py[DEBUG]: Running config-runcmd using lock (<FileLock using file '/var/lib/cloud/instances/i-0bb244a52030111dc/sem/config_runcmd'>)
2019-05-18 15:40:14,230 - cc_runcmd.py[DEBUG]: Skipping module named runcmd, no 'runcmd' key in configuration
2019-05-18 15:40:14,230 - handlers.py[DEBUG]: finish: modules-config/config-runcmd: SUCCESS: config-runcmd ran successfully
2019-05-18 15:40:14,230 - stages.py[DEBUG]: Running module byobu (<module 'cloudinit.config.cc_byobu' from '/usr/lib/python3/dist-packages/cloudinit/config/cc_byobu.py'>) with frequency once-per-instance
2019-05-18 15:40:14,230 - handlers.py[DEBUG]: start: modules-config/config-byobu: running config-byobu with frequency once-per-instance
2019-05-18 15:40:14,231 - util.py[DEBUG]: Writing to /var/lib/cloud/instances/i-0bb244a52030111dc/sem/config_byobu - wb: [644] 24 bytes
2019-05-18 15:40:14,231 - helpers.py[DEBUG]: Running config-byobu using lock (<FileLock using file '/var/lib/cloud/instances/i-0bb244a52030111dc/sem/config_byobu'>)
2019-05-18 15:40:14,231 - cc_byobu.py[DEBUG]: Skipping module named byobu, no 'byobu' values found
2019-05-18 15:40:14,231 - handlers.py[DEBUG]: finish: modules-config/config-byobu: SUCCESS: config-byobu ran successfully
2019-05-18 15:40:14,231 - main.py[DEBUG]: Ran 15 modules with 0 failures
2019-05-18 15:40:14,232 - util.py[DEBUG]: Reading from /proc/uptime (quiet=False)
2019-05-18 15:40:14,232 - util.py[DEBUG]: Read 13 bytes from /proc/uptime
2019-05-18 15:40:14,232 - util.py[DEBUG]: cloud-init mode 'modules' took 1.020 seconds (1.02)
2019-05-18 15:40:14,232 - handlers.py[DEBUG]: finish: modules-config: SUCCESS: running modules for config
2019-05-18 15:40:14,513 - util.py[DEBUG]: Cloud-init v. 18.3-9-g2e62cb8a-0ubuntu1~16.04.2 running 'modules:final' at Sat, 18 May 2019 15:40:14 +0000. Up 16.00 seconds.
2019-05-18 15:40:14,551 - stages.py[DEBUG]: Using distro class <class 'cloudinit.distros.ubuntu.Distro'>
2019-05-18 15:40:14,552 - stages.py[DEBUG]: Running module snappy (<module 'cloudinit.config.cc_snappy' from '/usr/lib/python3/dist-packages/cloudinit/config/cc_snappy.py'>) with frequency once-per-instance
2019-05-18 15:40:14,552 - handlers.py[DEBUG]: start: modules-final/config-snappy: running config-snappy with frequency once-per-instance
2019-05-18 15:40:14,552 - util.py[DEBUG]: Writing to /var/lib/cloud/instances/i-0bb244a52030111dc/sem/config_snappy - wb: [644] 24 bytes
2019-05-18 15:40:14,553 - helpers.py[DEBUG]: Running config-snappy using lock (<FileLock using file '/var/lib/cloud/instances/i-0bb244a52030111dc/sem/config_snappy'>)
2019-05-18 15:40:14,553 - util.py[DEBUG]: Reading from /etc/os-release (quiet=True)
2019-05-18 15:40:14,553 - util.py[DEBUG]: Read 298 bytes from /etc/os-release
2019-05-18 15:40:14,553 - util.py[DEBUG]: Reading from /etc/system-image/channel.ini (quiet=True)
2019-05-18 15:40:14,553 - util.py[DEBUG]: Read 0 bytes from /etc/system-image/channel.ini
2019-05-18 15:40:14,554 - cc_snappy.py[DEBUG]: snappy: 'auto' mode, and system not snappy
2019-05-18 15:40:14,554 - handlers.py[DEBUG]: finish: modules-final/config-snappy: SUCCESS: config-snappy ran successfully
2019-05-18 15:40:14,554 - stages.py[DEBUG]: Running module package-update-upgrade-install (<module 'cloudinit.config.cc_package_update_upgrade_install' from '/usr/lib/python3/dist-packages/cloudinit/config/cc_package_update_upgrade_install.py'>) with frequency once-per-instance
2019-05-18 15:40:14,554 - handlers.py[DEBUG]: start: modules-final/config-package-update-upgrade-install: running config-package-update-upgrade-install with frequency once-per-instance
2019-05-18 15:40:14,554 - util.py[DEBUG]: Writing to /var/lib/cloud/instances/i-0bb244a52030111dc/sem/config_package_update_upgrade_install - wb: [644] 25 bytes
2019-05-18 15:40:14,555 - helpers.py[DEBUG]: Running config-package-update-upgrade-install using lock (<FileLock using file '/var/lib/cloud/instances/i-0bb244a52030111dc/sem/config_package_update_upgrade_install'>)
2019-05-18 15:40:14,555 - handlers.py[DEBUG]: finish: modules-final/config-package-update-upgrade-install: SUCCESS: config-package-update-upgrade-install ran successfully
2019-05-18 15:40:14,555 - stages.py[DEBUG]: Running module fan (<module 'cloudinit.config.cc_fan' from '/usr/lib/python3/dist-packages/cloudinit/config/cc_fan.py'>) with frequency once-per-instance
2019-05-18 15:40:14,555 - handlers.py[DEBUG]: start: modules-final/config-fan: running config-fan with frequency once-per-instance
2019-05-18 15:40:14,555 - util.py[DEBUG]: Writing to /var/lib/cloud/instances/i-0bb244a52030111dc/sem/config_fan - wb: [644] 25 bytes
2019-05-18 15:40:14,555 - helpers.py[DEBUG]: Running config-fan using lock (<FileLock using file '/var/lib/cloud/instances/i-0bb244a52030111dc/sem/config_fan'>)
2019-05-18 15:40:14,556 - cc_fan.py[DEBUG]: fan: no 'fan' config entry. disabling
2019-05-18 15:40:14,556 - handlers.py[DEBUG]: finish: modules-final/config-fan: SUCCESS: config-fan ran successfully
2019-05-18 15:40:14,556 - stages.py[DEBUG]: Running module landscape (<module 'cloudinit.config.cc_landscape' from '/usr/lib/python3/dist-packages/cloudinit/config/cc_landscape.py'>) with frequency once-per-instance
2019-05-18 15:40:14,556 - handlers.py[DEBUG]: start: modules-final/config-landscape: running config-landscape with frequency once-per-instance
2019-05-18 15:40:14,556 - util.py[DEBUG]: Writing to /var/lib/cloud/instances/i-0bb244a52030111dc/sem/config_landscape - wb: [644] 25 bytes
2019-05-18 15:40:14,556 - helpers.py[DEBUG]: Running config-landscape using lock (<FileLock using file '/var/lib/cloud/instances/i-0bb244a52030111dc/sem/config_landscape'>)
2019-05-18 15:40:14,556 - handlers.py[DEBUG]: finish: modules-final/config-landscape: SUCCESS: config-landscape ran successfully
2019-05-18 15:40:14,556 - stages.py[DEBUG]: Running module lxd (<module 'cloudinit.config.cc_lxd' from '/usr/lib/python3/dist-packages/cloudinit/config/cc_lxd.py'>) with frequency once-per-instance
2019-05-18 15:40:14,557 - handlers.py[DEBUG]: start: modules-final/config-lxd: running config-lxd with frequency once-per-instance
2019-05-18 15:40:14,557 - util.py[DEBUG]: Writing to /var/lib/cloud/instances/i-0bb244a52030111dc/sem/config_lxd - wb: [644] 25 bytes
2019-05-18 15:40:14,557 - helpers.py[DEBUG]: Running config-lxd using lock (<FileLock using file '/var/lib/cloud/instances/i-0bb244a52030111dc/sem/config_lxd'>)
2019-05-18 15:40:14,557 - cc_lxd.py[DEBUG]: Skipping module named lxd, not present or disabled by cfg
2019-05-18 15:40:14,557 - handlers.py[DEBUG]: finish: modules-final/config-lxd: SUCCESS: config-lxd ran successfully
2019-05-18 15:40:14,557 - stages.py[DEBUG]: Running module puppet (<module 'cloudinit.config.cc_puppet' from '/usr/lib/python3/dist-packages/cloudinit/config/cc_puppet.py'>) with frequency once-per-instance
2019-05-18 15:40:14,557 - handlers.py[DEBUG]: start: modules-final/config-puppet: running config-puppet with frequency once-per-instance
2019-05-18 15:40:14,558 - util.py[DEBUG]: Writing to /var/lib/cloud/instances/i-0bb244a52030111dc/sem/config_puppet - wb: [644] 24 bytes
2019-05-18 15:40:14,558 - helpers.py[DEBUG]: Running config-puppet using lock (<FileLock using file '/var/lib/cloud/instances/i-0bb244a52030111dc/sem/config_puppet'>)
2019-05-18 15:40:14,558 - cc_puppet.py[DEBUG]: Skipping module named puppet, no 'puppet' configuration found
2019-05-18 15:40:14,558 - handlers.py[DEBUG]: finish: modules-final/config-puppet: SUCCESS: config-puppet ran successfully
2019-05-18 15:40:14,558 - stages.py[DEBUG]: Running module chef (<module 'cloudinit.config.cc_chef' from '/usr/lib/python3/dist-packages/cloudinit/config/cc_chef.py'>) with frequency once-per-instance
2019-05-18 15:40:14,558 - handlers.py[DEBUG]: start: modules-final/config-chef: running config-chef with frequency once-per-instance
2019-05-18 15:40:14,558 - util.py[DEBUG]: Writing to /var/lib/cloud/instances/i-0bb244a52030111dc/sem/config_chef - wb: [644] 25 bytes
2019-05-18 15:40:14,559 - helpers.py[DEBUG]: Running config-chef using lock (<FileLock using file '/var/lib/cloud/instances/i-0bb244a52030111dc/sem/config_chef'>)
2019-05-18 15:40:14,559 - cc_chef.py[DEBUG]: Skipping module named chef, no 'chef' key in configuration
2019-05-18 15:40:14,559 - handlers.py[DEBUG]: finish: modules-final/config-chef: SUCCESS: config-chef ran successfully
2019-05-18 15:40:14,559 - stages.py[DEBUG]: Running module mcollective (<module 'cloudinit.config.cc_mcollective' from '/usr/lib/python3/dist-packages/cloudinit/config/cc_mcollective.py'>) with frequency once-per-instance
2019-05-18 15:40:14,559 - handlers.py[DEBUG]: start: modules-final/config-mcollective: running config-mcollective with frequency once-per-instance
2019-05-18 15:40:14,559 - util.py[DEBUG]: Writing to /var/lib/cloud/instances/i-0bb244a52030111dc/sem/config_mcollective - wb: [644] 24 bytes
2019-05-18 15:40:14,560 - helpers.py[DEBUG]: Running config-mcollective using lock (<FileLock using file '/var/lib/cloud/instances/i-0bb244a52030111dc/sem/config_mcollective'>)
2019-05-18 15:40:14,560 - cc_mcollective.py[DEBUG]: Skipping module named mcollective, no 'mcollective' key in configuration
2019-05-18 15:40:14,560 - handlers.py[DEBUG]: finish: modules-final/config-mcollective: SUCCESS: config-mcollective ran successfully
2019-05-18 15:40:14,560 - stages.py[DEBUG]: Running module salt-minion (<module 'cloudinit.config.cc_salt_minion' from '/usr/lib/python3/dist-packages/cloudinit/config/cc_salt_minion.py'>) with frequency once-per-instance
2019-05-18 15:40:14,560 - handlers.py[DEBUG]: start: modules-final/config-salt-minion: running config-salt-minion with frequency once-per-instance
2019-05-18 15:40:14,560 - util.py[DEBUG]: Writing to /var/lib/cloud/instances/i-0bb244a52030111dc/sem/config_salt_minion - wb: [644] 25 bytes
2019-05-18 15:40:14,560 - helpers.py[DEBUG]: Running config-salt-minion using lock (<FileLock using file '/var/lib/cloud/instances/i-0bb244a52030111dc/sem/config_salt_minion'>)
2019-05-18 15:40:14,561 - cc_salt_minion.py[DEBUG]: Skipping module named salt-minion, no 'salt_minion' key in configuration
2019-05-18 15:40:14,561 - handlers.py[DEBUG]: finish: modules-final/config-salt-minion: SUCCESS: config-salt-minion ran successfully
2019-05-18 15:40:14,561 - stages.py[DEBUG]: Running module rightscale_userdata (<module 'cloudinit.config.cc_rightscale_userdata' from '/usr/lib/python3/dist-packages/cloudinit/config/cc_rightscale_userdata.py'>) with frequency once-per-instance
2019-05-18 15:40:14,561 - handlers.py[DEBUG]: start: modules-final/config-rightscale_userdata: running config-rightscale_userdata with frequency once-per-instance
2019-05-18 15:40:14,561 - util.py[DEBUG]: Writing to /var/lib/cloud/instances/i-0bb244a52030111dc/sem/config_rightscale_userdata - wb: [644] 24 bytes
2019-05-18 15:40:14,561 - helpers.py[DEBUG]: Running config-rightscale_userdata using lock (<FileLock using file '/var/lib/cloud/instances/i-0bb244a52030111dc/sem/config_rightscale_userdata'>)
2019-05-18 15:40:14,561 - cc_rightscale_userdata.py[DEBUG]: Failed to get raw userdata in module rightscale_userdata
2019-05-18 15:40:14,562 - handlers.py[DEBUG]: finish: modules-final/config-rightscale_userdata: SUCCESS: config-rightscale_userdata ran successfully
2019-05-18 15:40:14,562 - stages.py[DEBUG]: Running module scripts-vendor (<module 'cloudinit.config.cc_scripts_vendor' from '/usr/lib/python3/dist-packages/cloudinit/config/cc_scripts_vendor.py'>) with frequency once-per-instance
2019-05-18 15:40:14,562 - handlers.py[DEBUG]: start: modules-final/config-scripts-vendor: running config-scripts-vendor with frequency once-per-instance
2019-05-18 15:40:14,562 - util.py[DEBUG]: Writing to /var/lib/cloud/instances/i-0bb244a52030111dc/sem/config_scripts_vendor - wb: [644] 24 bytes
2019-05-18 15:40:14,562 - helpers.py[DEBUG]: Running config-scripts-vendor using lock (<FileLock using file '/var/lib/cloud/instances/i-0bb244a52030111dc/sem/config_scripts_vendor'>)
2019-05-18 15:40:14,562 - handlers.py[DEBUG]: finish: modules-final/config-scripts-vendor: SUCCESS: config-scripts-vendor ran successfully
2019-05-18 15:40:14,562 - stages.py[DEBUG]: Running module scripts-per-once (<module 'cloudinit.config.cc_scripts_per_once' from '/usr/lib/python3/dist-packages/cloudinit/config/cc_scripts_per_once.py'>) with frequency once
2019-05-18 15:40:14,563 - handlers.py[DEBUG]: start: modules-final/config-scripts-per-once: running config-scripts-per-once with frequency once
2019-05-18 15:40:14,563 - util.py[DEBUG]: Writing to /var/lib/cloud/sem/config_scripts_per_once.once - wb: [644] 24 bytes
2019-05-18 15:40:14,563 - helpers.py[DEBUG]: Running config-scripts-per-once using lock (<FileLock using file '/var/lib/cloud/sem/config_scripts_per_once.once'>)
2019-05-18 15:40:14,563 - handlers.py[DEBUG]: finish: modules-final/config-scripts-per-once: SUCCESS: config-scripts-per-once ran successfully
2019-05-18 15:40:14,563 - stages.py[DEBUG]: Running module scripts-per-boot (<module 'cloudinit.config.cc_scripts_per_boot' from '/usr/lib/python3/dist-packages/cloudinit/config/cc_scripts_per_boot.py'>) with frequency always
2019-05-18 15:40:14,563 - handlers.py[DEBUG]: start: modules-final/config-scripts-per-boot: running config-scripts-per-boot with frequency always
2019-05-18 15:40:14,563 - helpers.py[DEBUG]: Running config-scripts-per-boot using lock (<cloudinit.helpers.DummyLock object at 0x7f1c03ac0278>)
2019-05-18 15:40:14,564 - handlers.py[DEBUG]: finish: modules-final/config-scripts-per-boot: SUCCESS: config-scripts-per-boot ran successfully
2019-05-18 15:40:14,564 - stages.py[DEBUG]: Running module scripts-per-instance (<module 'cloudinit.config.cc_scripts_per_instance' from '/usr/lib/python3/dist-packages/cloudinit/config/cc_scripts_per_instance.py'>) with frequency once-per-instance
2019-05-18 15:40:14,564 - handlers.py[DEBUG]: start: modules-final/config-scripts-per-instance: running config-scripts-per-instance with frequency once-per-instance
2019-05-18 15:40:14,564 - util.py[DEBUG]: Writing to /var/lib/cloud/instances/i-0bb244a52030111dc/sem/config_scripts_per_instance - wb: [644] 23 bytes
2019-05-18 15:40:14,564 - helpers.py[DEBUG]: Running config-scripts-per-instance using lock (<FileLock using file '/var/lib/cloud/instances/i-0bb244a52030111dc/sem/config_scripts_per_instance'>)
2019-05-18 15:40:14,564 - handlers.py[DEBUG]: finish: modules-final/config-scripts-per-instance: SUCCESS: config-scripts-per-instance ran successfully
2019-05-18 15:40:14,564 - stages.py[DEBUG]: Running module scripts-user (<module 'cloudinit.config.cc_scripts_user' from '/usr/lib/python3/dist-packages/cloudinit/config/cc_scripts_user.py'>) with frequency once-per-instance
2019-05-18 15:40:14,565 - handlers.py[DEBUG]: start: modules-final/config-scripts-user: running config-scripts-user with frequency once-per-instance
2019-05-18 15:40:14,565 - util.py[DEBUG]: Writing to /var/lib/cloud/instances/i-0bb244a52030111dc/sem/config_scripts_user - wb: [644] 25 bytes
2019-05-18 15:40:14,565 - helpers.py[DEBUG]: Running config-scripts-user using lock (<FileLock using file '/var/lib/cloud/instances/i-0bb244a52030111dc/sem/config_scripts_user'>)
2019-05-18 15:40:14,565 - handlers.py[DEBUG]: finish: modules-final/config-scripts-user: SUCCESS: config-scripts-user ran successfully
2019-05-18 15:40:14,565 - stages.py[DEBUG]: Running module ssh-authkey-fingerprints (<module 'cloudinit.config.cc_ssh_authkey_fingerprints' from '/usr/lib/python3/dist-packages/cloudinit/config/cc_ssh_authkey_fingerprints.py'>) with frequency once-per-instance
2019-05-18 15:40:14,565 - handlers.py[DEBUG]: start: modules-final/config-ssh-authkey-fingerprints: running config-ssh-authkey-fingerprints with frequency once-per-instance
2019-05-18 15:40:14,565 - util.py[DEBUG]: Writing to /var/lib/cloud/instances/i-0bb244a52030111dc/sem/config_ssh_authkey_fingerprints - wb: [644] 25 bytes
2019-05-18 15:40:14,566 - helpers.py[DEBUG]: Running config-ssh-authkey-fingerprints using lock (<FileLock using file '/var/lib/cloud/instances/i-0bb244a52030111dc/sem/config_ssh_authkey_fingerprints'>)
2019-05-18 15:40:14,566 - util.py[DEBUG]: Reading from /etc/ssh/sshd_config (quiet=False)
2019-05-18 15:40:14,566 - util.py[DEBUG]: Read 2540 bytes from /etc/ssh/sshd_config
2019-05-18 15:40:14,567 - util.py[DEBUG]: Reading from /home/ubuntu/.ssh/authorized_keys (quiet=False)
2019-05-18 15:40:14,567 - util.py[DEBUG]: Read 448 bytes from /home/ubuntu/.ssh/authorized_keys
2019-05-18 15:40:14,619 - handlers.py[DEBUG]: finish: modules-final/config-ssh-authkey-fingerprints: SUCCESS: config-ssh-authkey-fingerprints ran successfully
2019-05-18 15:40:14,619 - stages.py[DEBUG]: Running module keys-to-console (<module 'cloudinit.config.cc_keys_to_console' from '/usr/lib/python3/dist-packages/cloudinit/config/cc_keys_to_console.py'>) with frequency once-per-instance
2019-05-18 15:40:14,619 - handlers.py[DEBUG]: start: modules-final/config-keys-to-console: running config-keys-to-console with frequency once-per-instance
2019-05-18 15:40:14,620 - util.py[DEBUG]: Writing to /var/lib/cloud/instances/i-0bb244a52030111dc/sem/config_keys_to_console - wb: [644] 25 bytes
2019-05-18 15:40:14,620 - helpers.py[DEBUG]: Running config-keys-to-console using lock (<FileLock using file '/var/lib/cloud/instances/i-0bb244a52030111dc/sem/config_keys_to_console'>)
2019-05-18 15:40:14,620 - util.py[DEBUG]: Running command ['/usr/lib/cloud-init/write-ssh-key-fingerprints', '', 'ssh-dss'] with allowed return codes [0] (shell=False, capture=True)
2019-05-18 15:40:14,631 - handlers.py[DEBUG]: finish: modules-final/config-keys-to-console: SUCCESS: config-keys-to-console ran successfully
2019-05-18 15:40:14,631 - stages.py[DEBUG]: Running module phone-home (<module 'cloudinit.config.cc_phone_home' from '/usr/lib/python3/dist-packages/cloudinit/config/cc_phone_home.py'>) with frequency once-per-instance
2019-05-18 15:40:14,631 - handlers.py[DEBUG]: start: modules-final/config-phone-home: running config-phone-home with frequency once-per-instance
2019-05-18 15:40:14,632 - util.py[DEBUG]: Writing to /var/lib/cloud/instances/i-0bb244a52030111dc/sem/config_phone_home - wb: [644] 25 bytes
2019-05-18 15:40:14,632 - helpers.py[DEBUG]: Running config-phone-home using lock (<FileLock using file '/var/lib/cloud/instances/i-0bb244a52030111dc/sem/config_phone_home'>)
2019-05-18 15:40:14,632 - cc_phone_home.py[DEBUG]: Skipping module named phone-home, no 'phone_home' configuration found
2019-05-18 15:40:14,632 - handlers.py[DEBUG]: finish: modules-final/config-phone-home: SUCCESS: config-phone-home ran successfully
2019-05-18 15:40:14,632 - stages.py[DEBUG]: Running module final-message (<module 'cloudinit.config.cc_final_message' from '/usr/lib/python3/dist-packages/cloudinit/config/cc_final_message.py'>) with frequency always
2019-05-18 15:40:14,632 - handlers.py[DEBUG]: start: modules-final/config-final-message: running config-final-message with frequency always
2019-05-18 15:40:14,633 - helpers.py[DEBUG]: Running config-final-message using lock (<cloudinit.helpers.DummyLock object at 0x7f1c0332e6d8>)
2019-05-18 15:40:14,633 - util.py[DEBUG]: Reading from /proc/uptime (quiet=False)
2019-05-18 15:40:14,633 - util.py[DEBUG]: Read 13 bytes from /proc/uptime
2019-05-18 15:40:14,636 - util.py[DEBUG]: Cloud-init v. 18.3-9-g2e62cb8a-0ubuntu1~16.04.2 finished at Sat, 18 May 2019 15:40:14 +0000. Datasource DataSourceEc2Local.  Up 16.16 seconds
2019-05-18 15:40:14,636 - util.py[DEBUG]: Writing to /var/lib/cloud/instance/boot-finished - wb: [644] 79 bytes
2019-05-18 15:40:14,636 - handlers.py[DEBUG]: finish: modules-final/config-final-message: SUCCESS: config-final-message ran successfully
2019-05-18 15:40:14,636 - stages.py[DEBUG]: Running module power-state-change (<module 'cloudinit.config.cc_power_state_change' from '/usr/lib/python3/dist-packages/cloudinit/config/cc_power_state_change.py'>) with frequency once-per-instance
2019-05-18 15:40:14,636 - handlers.py[DEBUG]: start: modules-final/config-power-state-change: running config-power-state-change with frequency once-per-instance
2019-05-18 15:40:14,636 - util.py[DEBUG]: Writing to /var/lib/cloud/instances/i-0bb244a52030111dc/sem/config_power_state_change - wb: [644] 25 bytes
2019-05-18 15:40:14,637 - helpers.py[DEBUG]: Running config-power-state-change using lock (<FileLock using file '/var/lib/cloud/instances/i-0bb244a52030111dc/sem/config_power_state_change'>)
2019-05-18 15:40:14,637 - cc_power_state_change.py[DEBUG]: no power_state provided. doing nothing
2019-05-18 15:40:14,637 - handlers.py[DEBUG]: finish: modules-final/config-power-state-change: SUCCESS: config-power-state-change ran successfully
2019-05-18 15:40:14,637 - main.py[DEBUG]: Ran 20 modules with 0 failures
2019-05-18 15:40:14,638 - util.py[DEBUG]: Creating symbolic link from '/run/cloud-init/result.json' => '../../var/lib/cloud/data/result.json'
2019-05-18 15:40:14,638 - util.py[DEBUG]: Reading from /proc/uptime (quiet=False)
2019-05-18 15:40:14,638 - util.py[DEBUG]: Read 13 bytes from /proc/uptime
2019-05-18 15:40:14,638 - util.py[DEBUG]: cloud-init mode 'modules' took 0.169 seconds (0.17)
2019-05-18 15:40:14,638 - handlers.py[DEBUG]: finish: modules-final: SUCCESS: running modules for final
